Workbook

Sheet HISTORIA
A1: HISTORIA CLÍNICA-NUTRICIONAL | AC1: Masculino
A2: Fecha: | B2: 46027 | AC2: Femenino
A3: 1- DATOS PERSONALES
A4: Nombre y Apellido | G4: Ocupación
A5: Cédula | G5: Nivel de actividad en el trabajo
A6: Fecha de nacimiento | G6: Teléfono
A7: Edad | C7: =(B2-C6)/365 -> 126.10137 | G7: Correo electrónico
A8: Estado civil | G8: Deporte/Actividad | K8: Posición
A9: Dirección | K9: Perfil/Dominio
A10: Sexo | C10: Femenino
A11: Motivo de consulta
A12: Tratamiento médico
A13: 2-ANTECEDENTES PERSONALES
A14: Enfermedad(es) importante(s) diagnosticada(s)
A15: Operación(es) realizada(s)
A16: 3- ANTECEDENTES FAMILIARES
A17: Enfermedad(es) importante(s) diagnosticada(s)
A18: 4- HÁBITOS (PSICOBIOLÓGICO Y FUNCIONALES)
A19: Café | E19: Agua
A20: Alcohol | E20: Apetito/Ansiedad
A21: Tabaco | E21: Ciclo menstrual
A22: Consumo de drogas | E22: Alguna otra información relevante:
A23: Horas de sueño
A24: Evacuaciones
A25: Hábitos miccionales
A26: Acidez/Pirosis/Náuseas
A27: 5- HÁBITOS Y CONDUCTAS ALIMENTARIAS
A28: Horas de mayor apetito | G28: Rechazos alimentarios
A29: Comidas fuera de casa
A30: Alergias alimentarias
A31: Intolerancias alimentarias
A32: 6- DEPORTE/ACTIVIDAD FÍSICA/ENERGÍA DE ACTIVIDAD
A33: Tipo de Actividad | E33: Horas/Día | H33: Coeficiente | K33: Coeficiente x hora
A34: Deporte | H34: 3 | K34: =PRODUCT(E34*H34) -> 0
A35: Tv -Lectura | H35: 1 | K35: =PRODUCT(E35*H35) -> 0
A36: Juegos Pasivos | H36: 1.5 | K36: =PRODUCT(E36*H36) -> 0
A37: Juegos Activos | H37: 2.5 | K37: =PRODUCT(E37*H37) -> 0
A38: Escolar | H38: 1 | K38: =PRODUCT(E38*H38) -> 0
A39: Descanso | H39: 0 | K39: =PRODUCT(E39*H39) -> 0
A40: TOTAL | E40: =SUM(E34:G39) -> 0 | K40: =SUM(K34:M39) -> 0
...

Sheet LABORATORIO
A1: LABORATORIO
A4: ANALISÍS QUÍMICO Y HEMATOLÓGIO
A5: PARÁMETRO | B5: VALOR CONSULTA 1 | C5: VALOR CONSULTA 2 | D5: VALOR CONSULTA 3 | E5: VALOR CONSULTA 4 | F5: VALORES DE REFERENCIA
A6: Hemoglobina | F6: H: 13 – 18 g/dL M: 12 -14 G/dL
A7: Hematocrito | F7: H: 37 – 49 g/dL M: 36 -46 d/dL
A8: Glucosa | F8: 70 – 100 mg/dL
A9: Colesterol total | F9: Hasta 200 mg/dL
A10: Colesterol HDL | F10: H: mayor a 40 mg/dL M: mayor a 50 mg/dL
A12: Colesterol LDL | F12: Menor 130 mg/dL
A13: Triglicéridos | F13: Hasta 150 mg/dL
A14: Urea | F14: 10 – 50 g/dL
A15: Creatinina | F15: 0.8 – 1.2 mg/dL
A16: Ácido úrico | F16: 2.4 – 7.2 mg/dL
A17: BUN | F17: 8 – 20 mg/dL
A18: Proteínas totales | F18: 5.5 – 8 g/dL
... A46: Insulina | F46: <9 µg/mL
A48: Heces
A49: Orina

Sheet ANTROPOMETRÍA DEPORTISTAS
B1: VALORES ANTROPOMÉTRICOS
A5: Número de evaluación | B5: 1
A6: Fecha de evaluación | C6: =HISTORIA!C2 -> 0 | D6: =HISTORIA!D2 -> 0 | E6: =HISTORIA!E2 -> 0 | F6: =HISTORIA!F2 -> 0 | G6: =HISTORIA!G2 -> 0 | H6: =HISTORIA!H2 -> 0 | I6: =HISTORIA!I2 -> 0 | J6: =HISTORIA!J2 -> 0 | ... N6: =HISTORIA!N2 -> 0
A7: Peso actual (kg)
A8: Talla (m)
A9: Talla (cm)
A10: Talla sentada (cm)
A11: Circunferencias(cm)
A12: Brazo relajado (cm)
A13: Brazo Flexionado en Tensón (cm)
A14: Antebrazo máximo (cm)
A15: Tórax (Mesoesternal) (cm)
A16: Cintura mínimo (cm)
A17: Cadera máximo (cm)
A18: Muslo máximo (cm)
... A37: Circunferencias corregidas por pliegues (cm)
A38: Brazo relajado (cm) | B38: =B12-(3.1416*B23)/10 -> 0 | C38: =C12-(3.1416*C23)/10 -> 0 | D38: =D12-(3.1416*D23)/10 -> 0 | E38: =E12-(3.1416*E23)/10 -> 0 | F38: =F12-(3.1416*F23)/10 -> 0
A39: Caja torácica (cm) | B39: =B15-(3.1416*B24)/10 -> 0 | C39: =C15-(3.1416*C24)/10 -> 0 | D39: =D15-(3.1416*D24)/10 -> 0 | E39: =E15-(3.1416*E24)/10 -> 0 | F39: =F15-(3.1416*F24)/10 -> 0
A40: Cintura (cm) | B40: =B16-(3.1416*B27)/10 -> 0 | C40: =C16-(3.1416*C27)/10 -> 0 | D40: =D16-(3.1416*D27)/10 -> 0 | E40: =E16-(3.1416*E27)/10 -> 0 | F40: =F16-(3.1416*F27)/10 -> 0
A41: Muslo máximo (cm) | B41: =B18-(3.1416*B28)/10 -> 0 | C41: =C18-(3.1416*C28)/10 -> 0 | D41: =D18-(3.1416*D28)/10 -> 0 | E41: =E18-(3.1416*E28)/10 -> 0 | F41: =F18-(3.1416*F28)/10 -> 0
A42: Pantorrilla máximo (cm) | B42: =B20-(3.1416*B29)/10 -> 0 | C42: =C20-(3.1416*C29)/10 -> 0 | D42: =D20-(3.1416*D29)/10 -> 0 | E42: =E20-(3.1416*E29)/10 -> 0 | F42: =F20-(3.1416*F29)/10 -> 0
A43: INDICADORES (2 componentes)
A44: IMC (kg/m2) | B44: =B7/(B8*B8) -> #DIV/0! | C44: =C7/(C8*C8) -> #DIV/0! | D44: =D7/(D8*D8) -> #DIV/0! | E44: =E7/(E8*E8) -> #DIV/0! | F44: =F7/(F8*F8) -> #DIV/0! | G44: =G7/(G8*G8) -> #DIV/0! | H44: =H7/(H8*H8) -> #DIV/0! | I44: =I7/(I8*I8) -> #DIV/0! | ... S44: =S7/(S8*S8) -> #DIV/0!
A45: Contextura | B45: =(B35/(B9/100))*10 -> #DIV/0! | C45: =(C35/(C9/100))*10 -> #DIV/0! | D45: =(D35/(D9/100))*10 -> #DIV/0! | E45: =(E35/(E9/100))*10 -> #DIV/0! | F45: =(F35/(F9/100))*10 -> #DIV/0! | G45: =(G35/(G9/100))*10 -> #DIV/0! | H45: =(H35/(H9/100))*10 -> #DIV/0! | I45: =(I35/(I9/100))*10 -> #DIV/0! | ... S45: =(S35/(S9/100))*10 -> #DIV/0!
A46: A. Grasa Brazo (cm2) | B46: =(B23/10)*B12/2-((B23/10)*(B23/10)*3.1416/4) -> 0 | C46: =(C23/10)*C12/2-((C23/10)*(C23/10)*3.1416/4) -> 0 | D46: =(D23/10)*D12/2-((D23/10)*(D23/10)*3.1416/4) -> 0 | E46: =(E23/10)*E12/2-((E23/10)*(E23/10)*3.1416/4) -> 0 | F46: =(F23/10)*F12/2-((F23/10)*(F23/10)*3.1416/4) -> 0 | G46: =(G23/10)*G12/2-((G23/10)*(G23/10)*3.1416/4) -> 0 | H46: =(H23/10)*H12/2-((H23/10)*(H23/10)*3.1416/4) -> 0 | I46: =(I23/10)*I12/2-((I23/10)*(I23/10)*3.1416/4) -> 0 | ... S46: =(S23/10)*S12/2-((S23/10)*(S23/10)*3.1416/4) -> 0
A47: A. Magra Brazo (cm2) | B47: =(B12-((B23/10)*3.1416))^2/(4*3.1416) -> 0 | C47: =(C12-((C23/10)*3.1416))^2/(4*3.1416) -> 0 | D47: =(D12-((D23/10)*3.1416))^2/(4*3.1416) -> 0 | E47: =(E12-((E23/10)*3.1416))^2/(4*3.1416) -> 0 | F47: =(F12-((F23/10)*3.1416))^2/(4*3.1416) -> 0 | G47: =(G12-((G23/10)*3.1416))^2/(4*3.1416) -> 0 | H47: =(H12-((H23/10)*3.1416))^2/(4*3.1416) -> 0 | I47: =(I12-((I23/10)*3.1416))^2/(4*3.1416) -> 0 | ... S47: =(S12-((S23/10)*3.1416))^2/(4*3.1416) -> 0
A48: Área Magra del Muslo cm2 | B48: =((B19-(B28/10)*3.1416)*(B19-(B28/10)*3.1416)/12.5664) -> 0 | C48: =((C19-(C28/10)*3.1416)*(C19-(C28/10)*3.1416)/12.5664) -> 0 | D48: =((D19-(D28/10)*3.1416)*(D19-(D28/10)*3.1416)/12.5664) -> 0 | E48: =((E19-(E28/10)*3.1416)*(E19-(E28/10)*3.1416)/12.5664) -> 0 | F48: =((F19-(F28/10)*3.1416)*(F19-(F28/10)*3.1416)/12.5664) -> 0 | G48: =((G19-(G28/10)*3.1416)*(G19-(G28/10)*3.1416)/12.5664) -> 0 | H48: =((H19-(H28/10)*3.1416)*(H19-(H28/10)*3.1416)/12.5664) -> 0 | I48: =((I19-(I28/10)*3.1416)*(I19-(I28/10)*3.1416)/12.5664) -> 0 | ... S48: =((S19-(S28/10)*3.1416)*(S19-(S28/10)*3.1416)/12.5664) -> 0
A49: Área Grasa del Muslo cm2 | B49: =(B19/10)*B28/2-((B19/10)*(B28/10)*3.1416/4) -> 0 | C49: =(C19/10)*C28/2-((C19/10)*(C28/10)*3.1416/4) -> 0 | D49: =(D19/10)*D28/2-((D19/10)*(D28/10)*3.1416/4) -> 0 | E49: =(E19/10)*E28/2-((E19/10)*(E28/10)*3.1416/4) -> 0 | F49: =(F19/10)*F28/2-((F19/10)*(F28/10)*3.1416/4) -> 0 | G49: =(G19/10)*G28/2-((G19/10)*(G28/10)*3.1416/4) -> 0 | H49: =(H19/10)*H28/2-((H19/10)*(H28/10)*3.1416/4) -> 0 | I49: =(I19/10)*I28/2-((I19/10)*(I28/10)*3.1416/4) -> 0 | ... S49: =(S19/10)*S28/2-((S19/10)*(S28/10)*3.1416/4) -> 0
A50: Área Magra de la Pantorrilla cm2 | B50: =((B20-(B29/10)*3.1416)*(B20-(B29/10)*3.1416)/12.5664) -> 0 | C50: =((C20-(C29/10)*3.1416)*(C20-(C29/10)*3.1416)/12.5664) -> 0 | D50: =((D20-(D29/10)*3.1416)*(D20-(D29/10)*3.1416)/12.5664) -> 0 | E50: =((E20-(E29/10)*3.1416)*(E20-(E29/10)*3.1416)/12.5664) -> 0 | F50: =((F20-(F29/10)*3.1416)*(F20-(F29/10)*3.1416)/12.5664) -> 0 | G50: =((G20-(G29/10)*3.1416)*(G20-(G29/10)*3.1416)/12.5664) -> 0 | H50: =((H20-(H29/10)*3.1416)*(H20-(H29/10)*3.1416)/12.5664) -> 0 | I50: =((I20-(I29/10)*3.1416)*(I20-(I29/10)*3.1416)/12.5664) -> 0 | ... S50: =((S20-(S29/10)*3.1416)*(S20-(S29/10)*3.1416)/12.5664) -> 0
A51: Área Grasa de la Pantorrilla cm2 | B51: =(B20/10)*B29/2-((B20/10)*(B29/10)*3.1416/4) -> 0 | C51: =(C20/10)*C29/2-((C20/10)*(C29/10)*3.1416/4) -> 0 | D51: =(D20/10)*D29/2-((D20/10)*(D29/10)*3.1416/4) -> 0 | E51: =(E20/10)*E29/2-((E20/10)*(E29/10)*3.1416/4) -> 0 | F51: =(F20/10)*F29/2-((F20/10)*(F29/10)*3.1416/4) -> 0 | G51: =(G20/10)*G29/2-((G20/10)*(G29/10)*3.1416/4) -> 0 | H51: =(H20/10)*H29/2-((H20/10)*(H29/10)*3.1416/4) -> 0 | I51: =(I20/10)*I29/2-((I20/10)*(I29/10)*3.1416/4) -> 0 | ... S51: =(S20/10)*S29/2-((S20/10)*(S29/10)*3.1416/4) -> 0
A52: % Grasa (Carter 1986) | B52: =(3.5803)+(0.1548*(B24+B23+B26+B27+B28+B29)) -> 3.5803 | C52: =(3.5803)+(0.1548*(C24+C23+C26+C27+C28+C29)) -> 3.5803 | D52: =(3.5803)+(0.1548*(D24+D23+D26+D27+D28+D29)) -> 3.5803 | E52: =(3.5803)+(0.1548*(E24+E23+E26+E27+E28+E29)) -> 3.5803 | F52: =(3.5803)+(0.1548*(F24+F23+F26+F27+F28+F29)) -> 3.5803 | G52: =(3.5803)+(0.1548*(G24+G23+G26+G27+G28+G29)) -> 3.5803 | H52: =(3.5803)+(0.1548*(H24+H23+H26+H27+H28+H29)) -> 3.5803 | I52: =(3.5803)+(0.1548*(I24+I23+I26+I27+I28+I29)) -> 3.5803 | ... S52: =(3.5803)+(0.1548*(S24+S23+S26+S27+S28+S29)) -> 3.5803
A53: % Grasa (Durnin y W. 1974) | B53: =((4.95 / (VLOOKUP(HISTORIA!C7, I104:K109, 2, 1) - (VLOOKUP(HISTORIA!C7, I104:K109, 3, 1) *LOG10(SUM(B22:B25))))) - 4.5) * 100 -> #NUM! | C53: =((4.95 / (1.1339 - (0.064 *LOG10(C22+C23+C24+C25)))) - 4.5) * 100 -> #NUM! | D53: =((4.95 / (1.1339 - (0.064 *LOG10(D22+D23+D24+D25)))) - 4.5) * 100 -> #NUM! | E53: =((4.95 / (1.1339 - (0.064 *LOG10(E22+E23+E24+E25)))) - 4.5) * 100 -> #NUM! | F53: =((4.95 / (1.1339 - (0.064 *LOG10(F22+F23+F24+F25)))) - 4.5) * 100 -> #NUM! | H53: =((4.95 / (1.1339 - (0.064 *LOG10(H22+H23+H24+H25)))) - 4.5) * 100 -> #NUM! | I53: =((4.95 / (1.1339 - (0.064 *LOG10(I22+I23+I24+I25)))) - 4.5) * 100 -> #NUM! | J53: =((4.95 / (1.1339 - (0.064 *LOG10(J22+J23+J24+J25)))) - 4.5) * 100 -> #NUM! | K53: =((4.95 / (1.1339 - (0.064 *LOG10(K22+K23+K24+K25)))) - 4.5) * 100 -> #NUM! | L53: =((4.95 / (1.1339 - (0.064 *LOG10(L22+L23+L24+L25)))) - 4.5) * 100 -> #NUM! | M53: =((4.95 / (1.1339 - (0.064 *LOG10(M22+M23+M24+M25)))) - 4.5) * 100 -> #NUM! | N53: =((4.95 / (1.1339 - (0.064 *LOG10(N22+N23+N24+N25)))) - 4.5) * 100 -> #NUM! | O53: =((4.95 / (1.1339 - (0.064 *LOG10(O22+O23+O24+O25)))) - 4.5) * 100 -> #NUM! | ... S53: =((4.95 / (1.1339 - (0.064 *LOG10(S22+S23+S24+S25)))) - 4.5) * 100 -> #NUM!
A54: Sumatoria de 6 Pliegues | B54: =B29+B28+B27+B26+B23+B24 -> 0 | C54: =C29+C28+C27+C26+C23+C24 -> 0 | D54: =D29+D28+D27+D26+D23+D24 -> 0 | E54: =E29+E28+E27+E26+E23+E24 -> 0 | F54: =F29+F28+F27+F26+F23+F24 -> 0 | G54: =G29+G28+G27+G26+G23+G24 -> 0 | H54: =H29+H28+H27+H26+H23+H24 -> 0 | I54: =I29+I28+I27+I26+I23+I24 -> 0 | ... S54: =S29+S28+S27+S26+S23+S24 -> 0
A55: Sumatoria de 8 Pliegues | B55: =B26+B29+B28+B27+B25+B22+B23+B24 -> 0 | C55: =C26+C29+C28+C27+C25+C22+C23+C24 -> 0 | D55: =D26+D29+D28+D27+D25+D22+D23+D24 -> 0 | E55: =E26+E29+E28+E27+E25+E22+E23+E24 -> 0 | F55: =F26+F29+F28+F27+F25+F22+F23+F24 -> 0 | G55: =G26+G29+G28+G27+G25+G22+G23+G24 -> 0 | H55: =H26+H29+H28+H27+H25+H22+H23+H24 -> 0 | I55: =I26+I29+I28+I27+I25+I22+I23+I24 -> 0 | ... S55: =S26+S29+S28+S27+S25+S22+S23+S24 -> 0
A56: Índice cintura/cadera | B56: =B16/B17 -> #DIV/0! | C56: =C16/C17 -> #DIV/0! | D56: =D16/D17 -> #DIV/0! | E56: =E16/E17 -> #DIV/0! | F56: =F16/F17 -> #DIV/0! | G56: =G16/G17 -> #DIV/0! | H56: =H16/H17 -> #DIV/0! | I56: =I16/I17 -> #DIV/0! | ... S56: =S16/S17 -> #DIV/0!
A57: Porcentaje a Utilizar | B57: =B52 -> 3.5803 | C57: =C52 -> 3.5803 | D57: =D52 -> 3.5803 | E57: =E52 -> 3.5803 | F57: =F52 -> 3.5803 | G57: =G52 -> 3.5803 | H57: =H52 -> 3.5803 | I57: =I52 -> 3.5803 | ... S57: =S52 -> 3.5803
A58: Kg. Masa magra | B58: =(100-B57)/100*B7 -> 0 | C58: =(100-C57)/100*C7 -> 0 | D58: =(100-D57)/100*D7 -> 0 | E58: =(100-E57)/100*E7 -> 0 | F58: =(100-F57)/100*F7 -> 0 | G58: =(100-G57)/100*G7 -> 0 | H58: =(100-H57)/100*H7 -> 0 | I58: =(100-I57)/100*I7 -> 0 | ... S58: =(100-S57)/100*S7 -> 0
A59: Kg. Grasa | B59: =B7-B58 -> 0 | C59: =C7-C58 -> 0 | D59: =D7-D58 -> 0 | E59: =E7-E58 -> 0 | F59: =F7-F58 -> 0 | G59: =G7-G58 -> 0 | H59: =H7-H58 -> 0 | I59: =I7-I58 -> 0 | ... S59: =S7-S58 -> 0
A60: Lean Body Mass | B60: =B7-B57 -> -3.5803 | C60: =C7-C57 -> -3.5803 | D60: =D7-D57 -> -3.5803 | E60: =E7-E57 -> -3.5803 | F60: =F7-F57 -> -3.5803 | G60: =G7-G57 -> -3.5803 | H60: =H7-H57 -> -3.5803 | I60: =I7-I57 -> -3.5803 | ... S60: =S7-S57 -> -3.5803
A61: Fat mass | B61: =B7*B57/100 -> 0 | C61: =C7*C57/100 -> 0 | D61: =D7*D57/100 -> 0 | E61: =E7*E57/100 -> 0 | F61: =F7*F57/100 -> 0 | G61: =G7*G57/100 -> 0 | H61: =H7*H57/100 -> 0 | I61: =I7*I57/100 -> 0 | ... S61: =S7*S57/100 -> 0
...

Sheet 5 componentes
A1: DATOS PERSONALES | B1: Nombre y apellido | C1: =[1]HISTORIA!C4 -> 0
B2: Fecha de evaluación
B3: Fecha de nacimiento | C3: =HISTORIA!C6 -> 0
B4: Edad (años) | C4: =(C2-C3)/365 -> 0 | D4: =(D2-D3)/365 -> 0 | E4: =(E2-E3)/365 -> 0 | F4: =(F2-F3)/365 -> 0 | G4: =(G2-G3)/365 -> 0 | H4: =(H2-H3)/365 -> 0 | I4: =(I2-I3)/365 -> 0 | J4: =(J2-J3)/365 -> 0 | ... L4: =(L2-L3)/365 -> 0
A5: Mediciones básicas | B5: Peso (kg)
B6: Talla parado (cm)
B7: Talla sentado corregida (cm) | C7: =C8-43 -> -43 | D7: =D8-43 -> -43 | E7: =E8-43 -> -43 | F7: =F8-43 -> -43 | G7: =G8-43 -> -43 | H7: =H8-43 -> -43 | I7: =I8-43 -> -43 | J7: =J8-43 -> -43 | ... L7: =L8-43 -> -43
B8: Talla sentado (cm)
A10: Pliegues cutáneos (mm) | B10: Tríceps
B11: Subescapular
B12: Bíceps
B13: Cresta Ilíaca
B14: Supraespinal
B15: Abdominal
B16: Muslo frontal
B17: Pantorrilla
A19: Circunferencias (cm) | B19: Cabeza
B20: Cuello
B21: Brazo relajado
B22: Brazo flexionado en tensión
B23: Antebrazo máximo
B24: Muñeca
B25: Tórax (Mesoesternal)
B26: Cintura (Mínimo)
B27: Cadera (Máximo)
B28: Muslo máximo
B29: Muslo medio
B30: Pantorrilla
B31: Tobillo
A33: Diámetros óseos (mm) | B33: Biacromial
B34: Tórax transverso
B35: Tórax anteroposterior
B36: Biiliocrestídeo
B37: Humeral (Biepicondilar)
B38: Femoral (Biepicondilar)
B39: Muñeca (Biestiloidea)
A41: Circunferencias corregidas (mm) | B41: Brazo relajado corregido | C41: =C21-(3.1416*C10)/10 -> 0 | D41: =D21-(3.1416*D10)/10 -> 0 | E41: =E21-(3.1416*E10)/10 -> 0 | F41: =F21-(3.1416*F10)/10 -> 0 | G41: =G21-(3.1416*G10)/10 -> 0 | H41: =H21-(3.1416*H10)/10 -> 0 | I41: =I21-(3.1416*I10)/10 -> 0 | J41: =J21-(3.1416*J10)/10 -> 0 | ... L41: =L21-(3.1416*L10)/10 -> 0
B42: Caja torácica corregida | C42: =C25-(3.1416*C11)/10 -> 0 | D42: =D25-(3.1416*D11)/10 -> 0 | E42: =E25-(3.1416*E11)/10 -> 0 | F42: =F25-(3.1416*F11)/10 -> 0 | G42: =G25-(3.1416*G11)/10 -> 0 | H42: =H25-(3.1416*H11)/10 -> 0 | I42: =I25-(3.1416*I11)/10 -> 0 | J42: =J25-(3.1416*J11)/10 -> 0 | ... L42: =L25-(3.1416*L11)/10 -> 0
B43: Muslo máximo corregido | C43: =C28-(3.1416*C16)/10 -> 0 | D43: =D28-(3.1416*D16)/10 -> 0 | E43: =E28-(3.1416*E16)/10 -> 0 | F43: =F28-(3.1416*F16)/10 -> 0 | G43: =G28-(3.1416*G16)/10 -> 0 | H43: =H28-(3.1416*H16)/10 -> 0 | I43: =I28-(3.1416*I16)/10 -> 0 | J43: =J28-(3.1416*J16)/10 -> 0 | ... L43: =L28-(3.1416*L16)/10 -> 0
B44: Pantorrilla corregida | C44: =C30-(3.1416*C17)/10 -> 0 | D44: =D30-(3.1416*D17)/10 -> 0 | E44: =E30-(3.1416*E17)/10 -> 0 | F44: =F30-(3.1416*F17)/10 -> 0 | G44: =G30-(3.1416*G17)/10 -> 0 | H44: =H30-(3.1416*H17)/10 -> 0 | I44: =I30-(3.1416*I17)/10 -> 0 | J44: =J30-(3.1416*J17)/10 -> 0 | ... L44: =L30-(3.1416*L17)/10 -> 0
...

Sheet REFERENTES
A1: PESO (kg) | K1: ALTURA TIBIAL LATERAL (cm)
A2: Edad | B2: n | C2: Media | D2: Mediana | E2: Desv. Est. | F2: Máximo | G2: Mínimo | H2: IC95%sup | I2: IC95%inf | K2: Edad | L2: n | M2: Media | N2: Mediana | O2: Desv. Est. | P2: Máximo | Q2: Mínimo | R2: IC95%sup | S2: IC95%inf
A3: 7 | B3: 1 | C3: 27 | D3: 27 | E3: , | F3: 27 | G3: 27 | K3: 7 | L3: 1 | M3: 32 | N3: 32 | O3: , | P3: 32 | Q3: 32
A4: 8 | B4: 10 | C4: 28.46 | D4: 28.25 | E4: 5.968 | F4: 39.5 | G4: 19.9 | H4: =C4+(1.96*E4)/(B4)^0.5 -> 32.159005 | I4: =C4-(1.96*E4)/(B4)^0.5 -> 24.760995 | K4: 8 | L4: 10 | M4: 33.89 | N4: 34.1 | O4: 2.792 | P4: 37.7 | Q4: 28.6 | R4: =M4+(1.96*O4)/(L4)^0.5 -> 35.6205 | S4: =M4-(1.96*O4)/(L4)^0.5 -> 32.1595
A5: 9 | B5: 17 | C5: 33.659 | D5: 33.8 | E5: 6.02 | F5: 45.2 | G5: 25.2 | H5: =C5+(1.96*E5)/(B5)^0.5 -> 36.520726 | I5: =C5-(1.96*E5)/(B5)^0.5 -> 30.797274 | K5: 9 | L5: 17 | M5: 36.688 | N5: 36.5 | O5: 2.348 | P5: 41 | Q5: 32.9 | R5: =M5+(1.96*O5)/(L5)^0.5 -> 37.804168 | S5: =M5-(1.96*O5)/(L5)^0.5 -> 35.571832
A6: 10 | B6: 22 | C6: 38.25 | D6: 36.75 | E6: 10.395 | F6: 76.7 | G6: 25 | H6: =C6+(1.96*E6)/(B6)^0.5 -> 42.593794 | I6: =C6-(1.96*E6)/(B6)^0.5 -> 33.906206 | K6: 10 | L6: 22 | M6: 38.627 | N6: 38.75 | O6: 2.458 | P6: 45.6 | Q6: 34.3 | R6: =M6+(1.96*O6)/(L6)^0.5 -> 39.654133 | S6: =M6-(1.96*O6)/(L6)^0.5 -> 37.599867
A7: 11 | B7: 21 | C7: 42.671 | D7: 38.9 | E7: 9.677 | F7: 58 | G7: 25.2 | H7: =C7+(1.96*E7)/(B7)^0.5 -> 46.809921 | I7: =C7-(1.96*E7)/(B7)^0.5 -> 38.532079 | K7: 11 | L7: 20 | M7: 39.36 | N7: 39.55 | O7: 1.876 | P7: 41.9 | Q7: 35 | R7: =M7+(1.96*O7)/(L7)^0.5 -> 40.182193 | S7: =M7-(1.96*O7)/(L7)^0.5 -> 38.537807
A8: 12 | B8: 39 | C8: 44.287 | D8: 44.4 | E8: 8.681 | F8: 73.6 | G8: 28.5 | H8: =C8+(1.96*E8)/(B8)^0.5 -> 47.011542 | I8: =C8-(1.96*E8)/(B8)^0.5 -> 41.562458 | K8: 12 | L8: 39 | M8: 40.679 | N8: 41 | O8: 2.412 | P8: 45.6 | Q8: 36.2 | R8: =M8+(1.96*O8)/(L8)^0.5 -> 41.436009 | S8: =M8-(1.96*O8)/(L8)^0.5 -> 39.921991
A9: 13 | B9: 41 | C9: 49.117 | D9: 49.6 | E9: 9.841 | F9: 78.9 | G9: 32.9 | H9: =C9+(1.96*E9)/(B9)^0.5 -> 52.129336 | I9: =C9-(1.96*E9)/(B9)^0.5 -> 46.104664 | K9: 13 | L9: 41 | M9: 40.971 | N9: 41 | O9: 2.288 | P9: 45.5 | Q9: 36.1 | R9: =M9+(1.96*O9)/(L9)^0.5 -> 41.671358 | S9: =M9-(1.96*O9)/(L9)^0.5 -> 40.270642
A10: 14 | B10: 45 | C10: 52.024 | D10: 50.7 | E10: 8.186 | F10: 72.8 | G10: 39.1 | H10: =C10+(1.96*E10)/(B10)^0.5 -> 54.415782 | I10: =C10-(1.96*E10)/(B10)^0.5 -> 49.632218 | K10: 14 | L10: 45 | M10: 41.44 | N10: 41.4 | O10: 2.091 | P10: 46.2 | Q10: 37 | R10: =M10+(1.96*O10)/(L10)^0.5 -> 42.050947 | S10: =M10-(1.96*O10)/(L10)^0.5 -> 40.829053
A11: 15 | B11: 12 | C11: 52.875 | D11: 52.15 | E11: 6.157 | F11: 65.8 | G11: 41.3 | H11: =C11+(1.96*E11)/(B11)^0.5 -> 56.358651 | I11: =C11-(1.96*E11)/(B11)^0.5 -> 49.391349 | K11: 15 | L11: 12 | M11: 41.408 | N11: 41.85 | O11: 1.75 | P11: 43.9 | Q11: 37.2 | R11: =M11+(1.96*O11)/(L11)^0.5 -> 42.398156 | S11: =M11-(1.96*O11)/(L11)^0.5 -> 40.417844
A12: 16 | B12: 13 | C12: 51.877 | D12: 50.3 | E12: 6.162 | F12: 64.3 | G12: 45.2 | H12: =C12+(1.96*E12)/(B12)^0.5 -> 55.226701 | I12: =C12-(1.96*E12)/(B12)^0.5 -> 48.527299 | K12: 16 | L12: 12 | M12: 41.008 | N12: 41 | O12: 2.271 | P12: 45.1 | Q12: 37.6 | R12: =M12+(1.96*O12)/(L12)^0.5 -> 42.292939 | S12: =M12-(1.96*O12)/(L12)^0.5 -> 39.723061
A13: 17 | B13: 4 | C13: 48.15 | D13: 49 | E13: 2.428 | F13: 49.9 | G13: 44.7 | H13: =C13+(1.96*E13)/(B13)^0.5 -> 50.52944 | I13: =C13-(1.96*E13)/(B13)^0.5 -> 45.77056 | K13: 17 | L13: 4 | M13: 39.7 | N13: 40.6 | O13: 4.017 | P13: 43.5 | Q13: 34.1 | R13: =M13+(1.96*O13)/(L13)^0.5 -> 43.63666 | S13: =M13-(1.96*O13)/(L13)^0.5 -> 35.76334
A14: 18 | B14: 2 | C14: 54 | D14: 54 | E14: 7.92 | F14: 59.6 | G14: 48.4 | H14: =C14+(1.96*E14)/(B14)^0.5 -> 64.97656 | I14: =C14-(1.96*E14)/(B14)^0.5 -> 43.02344 | K14: 18 | L14: 2 | M14: 46.05 | N14: 46.05 | O14: 1.344 | P14: 47 | Q14: 45.1 | R14: =M14+(1.96*O14)/(L14)^0.5 -> 47.912689 | S14: =M14-(1.96*O14)/(L14)^0.5 -> 44.187311
A16: TALLA (cm)
A17: Edad | B17: n | C17: Media | D17: Mediana | E17: Desv. Est. | F17: Máximo | G17: Mínimo | H17: IC95%sup | I17: IC95%inf | K17: LONGITUD TIBIAL MEDIAL-MALEOLAR MEDIAL (cm)
A18: 7 | B18: 1 | C18: 121.5 | D18: 121.5 | E18: , | F18: 121.5 | G18: 121.5 | K18: Edad | L18: n | M18: Media | N18: Mediana | O18: Desv. Est. | P18: Máximo | Q18: Mínimo | R18: IC95%sup | S18: IC95%inf
A19: 8 | B19: 10 | C19: 128.24 | D19: 129 | E19: 7.038 | F19: 137.4 | G19: 115.4 | H19: =C19+(1.96*E19)/(B19)^0.5 -> 132.6022 | I19: =C19-(1.96*E19)/(B19)^0.5 -> 123.8778 | K19: 7 | L19: 1 | M19: 26.3 | N19: 26.3 | O19: , | P19: 26.3 | Q19: 26.3
A20: 9 | B20: 17 | C20: 136.718 | D20: 135 | E20: 6.652 | F20: 151.6 | G20: 127.9 | H20: =C20+(1.96*E20)/(B20)^0.5 -> 139.88016 | I20: =C20-(1.96*E20)/(B20)^0.5 -> 133.55584 | K20: 8 | L20: 10 | M20: 29 | N20: 28.95 | O20: 2.108 | P20: 31.5 | Q20: 24.2 | R20: =M20+(1.96*O20)/(L20)^0.5 -> 30.306552 | S20: =M20-(1.96*O20)/(L20)^0.5 -> 27.693448
A21: 10 | B21: 22 | C21: 141.564 | D21: 142.2 | E21: 5.929 | F21: 152.4 | G21: 129 | H21: =C21+(1.96*E21)/(B21)^0.5 -> 144.04157 | I21: =C21-(1.96*E21)/(B21)^0.5 -> 139.08643 | K21: 9 | L21: 17 | M21: 31.059 | N21: 31 | O21: 1.958 | P21: 34.5 | Q21: 28.4 | R21: =M21+(1.96*O21)/(L21)^0.5 -> 31.989774 | S21: =M21-(1.96*O21)/(L21)^0.5 -> 30.128226
A22: 11 | B22: 21 | C22: 147.243 | D22: 146.8 | E22: 8.496 | F22: 159 | G22: 129 | H22: =C22+(1.96*E22)/(B22)^0.5 -> 150.8768 | I22: =C22-(1.96*E22)/(B22)^0.5 -> 143.6092 | K22: 10 | L22: 22 | M22: 32.695 | N22: 33.1 | O22: 2.067 | P22: 37.6 | Q22: 28.7 | R22: =M22+(1.96*O22)/(L22)^0.5 -> 33.558744 | S22: =M22-(1.96*O22)/(L22)^0.5 -> 31.831256
A23: 12 | B23: 39 | C23: 151.077 | D23: 150.1 | E23: 7.439 | F23: 168.8 | G23: 134.4 | H23: =C23+(1.96*E23)/(B23)^0.5 -> 153.41174 | I23: =C23-(1.96*E23)/(B23)^0.5 -> 148.74226 | K23: 11 | L23: 20 | M23: 33.525 | N23: 33.3 | O23: 1.908 | P23: 36.2 | Q23: 29 | R23: =M23+(1.96*O23)/(L23)^0.5 -> 34.361218 | S23: =M23-(1.96*O23)/(L23)^0.5 -> 32.688782
A24: 13 | B24: 41 | C24: 154.498 | D24: 156.1 | E24: 6.409 | F24: 163.7 | G24: 139.4 | H24: =C24+(1.96*E24)/(B24)^0.5 -> 156.4598 | I24: =C24-(1.96*E24)/(B24)^0.5 -> 152.5362 | K24: 12 | L24: 38 | M24: 34.642 | N24: 35 | O24: 2.397 | P24: 39.6 | Q24: 30.5 | R24: =M24+(1.96*O24)/(L24)^0.5 -> 35.404136 | S24: =M24-(1.96*O24)/(L24)^0.5 -> 33.879864
A25: 14 | B25: 45 | C25: 157.633 | D25: 157.2 | E25: 5.34 | F25: 172.1 | G25: 147.4 | H25: =C25+(1.96*E25)/(B25)^0.5 -> 159.19324 | I25: =C25-(1.96*E25)/(B25)^0.5 -> 156.07276 | K25: 13 | L25: 41 | M25: 35.093 | N25: 35.1 | O25: 2.065 | P25: 39.8 | Q25: 30.4 | R25: =M25+(1.96*O25)/(L25)^0.5 -> 35.725098 | S25: =M25-(1.96*O25)/(L25)^0.5 -> 34.460902
A26: 15 | B26: 12 | C26: 158.917 | D26: 158.75 | E26: 6.175 | F26: 169.4 | G26: 150.4 | H26: =C26+(1.96*E26)/(B26)^0.5 -> 162.41084 | I26: =C26-(1.96*E26)/(B26)^0.5 -> 155.42316 | K26: 14 | L26: 45 | M26: 35.707 | N26: 36 | O26: 2.132 | P26: 41.1 | Q26: 31.1 | R26: =M26+(1.96*O26)/(L26)^0.5 -> 36.329927 | S26: =M26-(1.96*O26)/(L26)^0.5 -> 35.084073
A27: 16 | B27: 13 | C27: 157.092 | D27: 157 | E27: 5.731 | F27: 168.2 | G27: 145.3 | H27: =C27+(1.96*E27)/(B27)^0.5 -> 160.20741 | I27: =C27-(1.96*E27)/(B27)^0.5 -> 153.97659 | K27: 15 | L27: 12 | M27: 35.608 | N27: 35.7 | O27: 1.563 | P27: 37.8 | Q27: 33.4 | R27: =M27+(1.96*O27)/(L27)^0.5 -> 36.492351 | S27: =M27-(1.96*O27)/(L27)^0.5 -> 34.723649
A28: 17 | B28: 4 | C28: 159.925 | D28: 159.15 | E28: 4.17 | F28: 165.1 | G28: 156.3 | H28: =C28+(1.96*E28)/(B28)^0.5 -> 164.0116 | I28: =C28-(1.96*E28)/(B28)^0.5 -> 155.8384 | K28: 16 | L28: 12 | M28: 34.433 | N28: 34.1 | O28: 2.171 | P28: 38.7 | Q28: 30.3 | R28: =M28+(1.96*O28)/(L28)^0.5 -> 35.661359 | S28: =M28-(1.96*O28)/(L28)^0.5 -> 33.204641
A29: 18 | B29: 2 | C29: 158.95 | D29: 158.95 | E29: 9.97 | F29: 166 | G29: 151.9 | H29: =C29+(1.96*E29)/(B29)^0.5 -> 172.76772 | I29: =C29-(1.96*E29)/(B29)^0.5 -> 145.13228 | K29: 17 | L29: 4 | M29: 34.8 | N29: 35.05 | O29: 1.525 | P29: 36.3 | Q29: 32.8 | R29: =M29+(1.96*O29)/(L29)^0.5 -> 36.2945 | S29: =M29-(1.96*O29)/(L29)^0.5 -> 33.3055
K30: 18 | L30: 2 | M30: 34.2 | N30: 34.2 | O30: 4.808 | P30: 37.6 | Q30: 30.8 | R30: =M30+(1.96*O30)/(L30)^0.5 -> 40.863548 | S30: =M30-(1.96*O30)/(L30)^0.5 -> 27.536452
A31: TALLA SENTADO (cm)
A32: Edad | B32: n | C32: Media | D32: Mediana | E32: Desv. Est. | F32: Máximo | G32: Mínimo | H32: IC95%sup | I32: IC95%inf | K32: LONGITUD DEL PIE (cm)
A33: 7 | B33: 1 | C33: 67.4 | D33: 67.4 | E33: , | F33: 67.4 | G33: 67.4 | K33: Edad | L33: n | M33: Media | N33: Mediana | O33: Desv. Est. | P33: Máximo | Q33: Mínimo | R33: IC95%sup | S33: IC95%inf
A34: 8 | B34: 10 | C34: 69.21 | D34: 69.5 | E34: 3.567 | F34: 74.3 | G34: 64 | H34: =C34+(1.96*E34)/(B34)^0.5 -> 71.42085 | I34: =C34-(1.96*E34)/(B34)^0.5 -> 66.99915 | K34: 7 | L34: 1 | M34: 18.8 | N34: 18.8 | O34: , | P34: 18.8 | Q34: 18.8
A35: 9 | B35: 17 | C35: 72.053 | D35: 71.7 | E35: 2.865 | F35: 76.6 | G35: 65.6 | H35: =C35+(1.96*E35)/(B35)^0.5 -> 73.414935 | I35: =C35-(1.96*E35)/(B35)^0.5 -> 70.691065 | K35: 8 | L35: 10 | M35: 19.71 | N35: 19.75 | O35: 1.062 | P35: 21.2 | Q35: 17.7 | R35: =M35+(1.96*O35)/(L35)^0.5 -> 20.368234 | S35: =M35-(1.96*O35)/(L35)^0.5 -> 19.051766
A36: 10 | B36: 22 | C36: 74.541 | D36: 74.65 | E36: 3.432 | F36: 80.3 | G36: 68 | H36: =C36+(1.96*E36)/(B36)^0.5 -> 75.975142 | I36: =C36-(1.96*E36)/(B36)^0.5 -> 73.106858 | K36: 9 | L36: 17 | M36: 21.218 | N36: 21.3 | O36: 1.325 | P36: 23.2 | Q36: 19.2 | R36: =M36+(1.96*O36)/(L36)^0.5 -> 21.847865 | S36: =M36-(1.96*O36)/(L36)^0.5 -> 20.588135
A37: 11 | B37: 21 | C37: 78.395 | D37: 79.4 | E37: 5.201 | F37: 85.9 | G37: 68 | H37: =C37+(1.96*E37)/(B37)^0.5 -> 80.619504 | I37: =C37-(1.96*E37)/(B37)^0.5 -> 76.170496 | K37: 10 | L37: 22 | M37: 21.85 | N37: 21.75 | O37: 1.409 | P37: 25.3 | Q37: 19.7 | R37: =M37+(1.96*O37)/(L37)^0.5 -> 22.438784 | S37: =M37-(1.96*O37)/(L37)^0.5 -> 21.261216
A38: 12 | B38: 39 | C38: 79.856 | D38: 79.3 | E38: 4.313 | F38: 89.1 | G38: 71.9 | H38: =C38+(1.96*E38)/(B38)^0.5 -> 81.20964 | I38: =C38-(1.96*E38)/(B38)^0.5 -> 78.50236 | K38: 11 | L38: 20 | M38: 22.76 | N38: 22.95 | O38: 1.397 | P38: 25.2 | Q38: 19.7 | R38: =M38+(1.96*O38)/(L38)^0.5 -> 23.372262 | S38: =M38-(1.96*O38)/(L38)^0.5 -> 22.147738
A39: 13 | B39: 41 | C39: 81.824 | D39: 81.3 | E39: 3.976 | F39: 88.4 | G39: 74.8 | H39: =C39+(1.96*E39)/(B39)^0.5 -> 83.041056 | I39: =C39-(1.96*E39)/(B39)^0.5 -> 80.606944 | K39: 12 | L39: 39 | M39: 23.015 | N39: 23.1 | O39: 1.234 | P39: 25.3 | Q39: 19.7 | R39: =M39+(1.96*O39)/(L39)^0.5 -> 23.402292 | S39: =M39-(1.96*O39)/(L39)^0.5 -> 22.627708
A40: 14 | B40: 45 | C40: 84.149 | D40: 83.9 | E40: 2.87 | F40: 90.3 | G40: 78.2 | H40: =C40+(1.96*E40)/(B40)^0.5 -> 84.987555 | I40: =C40-(1.96*E40)/(B40)^0.5 -> 83.310445 | K40: 13 | L40: 40 | M40: 23.235 | N40: 23.2 | O40: 1.266 | P40: 26.2 | Q40: 20.3 | R40: =M40+(1.96*O40)/(L40)^0.5 -> 23.627337 | S40: =M40-(1.96*O40)/(L40)^0.5 -> 22.842663
A41: 15 | B41: 12 | C41: 85.15 | D41: 84.95 | E41: 3.153 | F41: 90.3 | G41: 81 | H41: =C41+(1.96*E41)/(B41)^0.5 -> 86.933978 | I41: =C41-(1.96*E41)/(B41)^0.5 -> 83.366022 | K41: 14 | L41: 45 | M41: 23.318 | N41: 23.4 | O41: 0.936 | P41: 25.1 | Q41: 21.3 | R41: =M41+(1.96*O41)/(L41)^0.5 -> 23.59148 | S41: =M41-(1.96*O41)/(L41)^0.5 -> 23.04452
...

Sheet REQUERIMIENTOS
A1: REQUERIMIENTOS Y LISTA DE INTERCAMBIO
A3: Peso actual | B3: ='ANTROPOMETRÍA DEPORTISTAS'!B7 -> 0 | C3: Peso usual | D3: ='ANTROPOMETRÍA DEPORTISTAS'!#REF! -> #REF! | E3: Peso mínimo | G3: Peso máximo | H3: ='ANTROPOMETRÍA DEPORTISTAS'!#REF! -> #REF! | I3: Peso a utilizar
A4: Talla | B4: ='ANTROPOMETRÍA DEPORTISTAS'!B9 -> 0 | I4: Peso Magro | J4: ='ANTROPOMETRÍA DEPORTISTAS'!B58 -> 0 | K4: % de cambio de peso | O4: LBM | P4: LBM
K5: Tiempo | L5: Significativo | M5: Severo
A6: PESO TEÓRICO | E6: PESO TEÓRICO | I6: Porcentaje de cambio de peso | K6: 1 semana | L6: 1 – 2 % | M6: > 2 %
A7: WEST | C7: Derivada del IMC | E7: Hamwi | I7: =((D3-B3)/D3)*100 -> #REF! | K7: 1 mes | L7: 3 – 5 % | M7: > 5 %
A8: Hombres | B8: =22.1*(POWER(B4/100,2)) -> 0 | C8: Hombres | D8: =23*(POWER(B3/100,2)) -> 0 | E8: Hombres | F8: =(B4-152)*1.08+48.5 -> -115.66 | G8: Hombres | H8: =23*(POWER(F4/100,2)) -> 0 | I8: Peso ajustado (Obesidad) | K8: 3 meses | L8: 6 – 8 % | M8: > 8 %
A9: Mujeres | B9: =20.6*(POWER(B4/100,2)) -> 0 | C9: Mujeres | D9: =21.5*(POWER(B3/100,2)) -> 0 | E9: Mujeres | F9: =(B4-152)*0.88+45.5 -> -88.26 | G9: Mujeres | H9: =21.5*(POWER(F4/100,2)) -> 0 | I9: =(B3-F9)*0.25+F9 -> -66.195 | K9: 6 meses | L9: 9 – 10% | M9: > 10 %
A12: METODO TRADICIONAL | E12: MÉTODO DIRECTO | J12: HARRIS Y BENEDICT | P12: HARRIS Y BENEDICT (ROZA) | U12: CUNNINGHAM (1980)
A13: Peso Utilizar | C13: =J3 -> 0 | E13: Hipocalórica | G13: =(J3*F13) -> 0 | H13: < 25 kcal/kg Peso | J13: RCB (Masculino) | L13: =(66.47+(13.75*J3)+(5*B4)-(6.75*HISTORIA!C7)) -> -784.71425 | P13: RCB (Masculino) | R13: =88.362+(13.397*J3)+(4.799*B4)-(5.677*HISTORIA!C7) -> -627.51548 | U13: RCB (Masculino) | W13: =(500+(22*O5)) -> 500
A14: RCB (Masculino) | C14: =(J3*24*1) -> 0 | E14: Normocalórica | G14: =F14*J3 -> 0 | H14: 25-30 kcal/kg Peso | J14: RCB (Femenino) | L14: =(655.1+(9.56*J3)+(1.85*B4)-(4.7*HISTORIA!C7)) -> 62.423562 | P14: RCB (Femenino) | R14: =447.593+(9.247*J3)+(3.098*B4)-(4.33*HISTORIA!C7) -> -98.425932 | U14: RCB (Femenino) | W14: =(500+(22*P5)) -> 500
A15: RCB (Femenino) | C15: =(J3*24*0.98) -> 0 | E15: Hipercalórica | G15: =F15*J3 -> 0 | H15: > 30 kcal/kg Peso | J15: Factor de Actividad | P15: Factor de Actividad | R15: =L15 -> 0 | U15: Factor de Actividad | W15: =S7 -> 0
A16: ETA (Masculino) | C16: =C14/10 -> 0 | J16: Factor de estrés | L16: 1 | P16: RCT (Masculino) | R16: =R13*R15 -> 0 | U16: RCT (Masculino) | W16: =W13*W15 -> 0
A17: ETA (Femenino) | C17: =(C15)/10 -> 0 | E17: MÉTODO HOLLIDAY | J17: RCT (Masculino) | L17: =L13*L15*L16 -> 0 | P17: RCT (Femenino) | R17: =R14*R15 -> 0 | U17: RCT (Femenino) | W17: =W14*W15 -> 0
A18: Actividad Física | C18: 1.5 | E18: 0-10 Kg | F18: 100 Kcal/Kg/día | J18: RCT (Femenino) | L18: =L14*L15*L16 -> 0
A19: RCT (Masculino) | C19: =(C14+C16)*C18 -> 0 | E19: 10,1-20 Kg | F19: 1000 Kcal + 50 Kcal por cada Kg por encima
A20: RCT (Femenino) | C20: =(C15+C17)*C18 -> 0 | E20: >20 Kg | F20: 1000 Kcal + 20 Kcal por cada Kg por encima de 20 Kg | J20: FACTOR DE ACTIVIDAD FÍSICA | N20: MULLER EQUATION | S20: MIFFLIN - ST.JEOR | Y20: 1.2 - Sedentary:
E21: RCB: | H21: 2040 | J21: Sedentary | L21: 1.2 | N21: RCB (Masculino) | P21: =((13.587*'ANTROPOMETRÍA DEPORTISTAS'!B58)+(9.613*'ANTROPOMETRÍA DEPORTISTAS'!B59)+(198*1)-(3.351*HISTORIA!C7)+674) -> 449.43431 | S21: RCB (Masculino) | U21: =(9.99*J3)+(6.25*B4)-(4.92*HISTORIA!C7)+5 -> -615.41874 | Y21: You work a desk job and don’t exercise
E22: ENERGÍA DE ACTIVIDAD: | H22: =HISTORIA!K41 -> #REF! | J22: Light Activity | L22: 1375 | N22: RCB (Femenino) | P22: =((13.587*'ANTROPOMETRÍA DEPORTISTAS'!B58)+(9.613*'ANTROPOMETRÍA DEPORTISTAS'!B59)+(198*0)-(3.351*HISTORIA!C7)+674) -> 251.43431 | S22: RCB (Femenino) | U22: =(9.99*J3)+(6.25*B4)-(4.92*HISTORIA!C7)-161 -> -781.41874 | Y22: 1.375 - Light Activity:
A23: ACTIVIDAD FÍSICA (AF) | E23: ETA: 10% | J23: Moderate Activity | L23: 1.55 | N23: Factor de Actividad | P23: =L15 -> 0 | S23: Factor de Actividad | U23: =L15 -> 0 | Y23: You work a desk job but do a bit of regular exercise. Or you don’t exercise but you work at a
A24: Sedentario | C24: 1 | E24: REQUERIMIENTO CALÓRICO TOTAL | J24: Very Active | L24: 1.725 | N24: RCT (Masculino) | P24: =P21*P23 -> 0 | S24: RCT (Masculino) | U24: =U21*U23 -> 0 | Y24: job that’s pretty active (a nurse, teacher, etc.) where you’re on your for feet most of the day.
A25: Muy Leve | C25: 1.25 | J25: Extra Active | L25: 1.9 | N25: RCT (Femenino) | P25: =P22*P23 -> 0 | S25: RCT (Femenino) | U25: =U22*U23 -> 0 | Y25: 1.55 - Moderate Activity:
A26: Leve | C26: 1.5 | Y26: Most of you will probably fall into this category. Maybe you work a sedentary job, but you
A27: Moderada | C27: 1.75 | Y27: train like a madman. Or maybe you train moderately, but you also have a job where you
A28: Intensa | C28: 2 | T28: Restricción | V28: Valor (Kcal) | Y28: stand on your feet all the time. Someone who doesn’t train but works a hard labor job
T29: 0.1 | V29: =0.1 -> 0.1 | Y29: would also fall into this category.
G30: FORMÚLA DIETÉTICA | M30: Suplementos | T30: 0.12 | V30: =0.12 -> 0.12 | Y30: 1.725 - Very Active:
G31: RCT a Utilizar | T31: 0.15 | V31: =0.15 -> 0.15 | Y31: You train hard most days of the week, and you also work a job where you’re on your feet
I32: % | J32: kcal | K32: g | L32: g/kg Peso | M32: Aporte de Macros | T32: 0.2 | V32: =0.2 -> 0.2 | Y32: quite a bit. Overall, you’re active most of the day.
G33: Proteínas | I33: 15 | J33: =(I33/100)*J31 -> 0 | K33: =J33/4 +M33 -> 0 | L33: =K33/J3 -> #DIV/0! | T33: 0.25 | V33: =0.25 -> 0.25 | Y33: 1.9 - Extra Active:
G34: Grasas | I34: 35 | J34: =(I34*J31)/100 -> 0 | K34: =J34/9 + M34 -> 0 | L34: =K34/J3 -> #DIV/0! | T34: 0.3 | V34: =0.3 -> 0.3 | Y34: You train hard and work a job that is physically intense in nature. As an example, you’re a
G35: CHO | I35: =100-I33-I34 -> 50 | J35: =(I35*J31)/100 -> 0 | K35: =J35/4 + M35 -> 0 | L35: =K35/J3 -> #DIV/0! | Y35: roofer who also goes to the gym five days a week.
G36: Colesterol
G37: Fibra | I37: =(L37*J31)/1000 -> 0
G38: Sodio
G39: Agua | I39: =L39*C13 -> 0
C41: Intervalos de edad.
A42: Rangos óptimos de proteína: | C42: 0-30 | D42: 31-40 | E42: 41-50 | F42: 51-60 | G42: 61-70
A43: No caloric Deficit | C43: 1,8-2,0 | D43: 2,0-2,3 | E43: 2,3-2,6 | F43: 2,6-2,9 | G43: 2,9-3,2 | H43: Kg de masa magra
A44: Deficit Calorico | C44: 2,2-2,4 | D44: 2,4-2,8 | E44: 2,8-3,1 | F44: 3,1-3,5 | G44: 3,5-3,8 | H44: Kg de masa magra
...

Sheet RESUMEN ANTROPOMETRICO
B2: Evaluación | D2: 1era evaluación | E2: Control 1° | F2: Control 2° | G2: Control 3° | H2: Control 4° | I2: Control 5° | J2: Control 6° | K2: Control 7° | L2: Control 8° | M2: Control 9°
B3: Fecha de evaluación | D3: ='ANTROPOMETRÍA DEPORTISTAS'!B6 -> 0 | E3: ='ANTROPOMETRÍA DEPORTISTAS'!C6 -> 0 | F3: ='ANTROPOMETRÍA DEPORTISTAS'!D6 -> 0 | G3: ='ANTROPOMETRÍA DEPORTISTAS'!E6 -> 0 | H3: ='ANTROPOMETRÍA DEPORTISTAS'!F6 -> 0 | I3: ='ANTROPOMETRÍA DEPORTISTAS'!G6 -> 0 | J3: ='ANTROPOMETRÍA DEPORTISTAS'!H6 -> 0 | K3: ='ANTROPOMETRÍA DEPORTISTAS'!I6 -> 0 | ... M3: ='ANTROPOMETRÍA DEPORTISTAS'!K6 -> 0
B4: Peso Actual (Kg) | D4: ='ANTROPOMETRÍA DEPORTISTAS'!B7 -> 0 | E4: ='ANTROPOMETRÍA DEPORTISTAS'!C7 -> 0 | F4: ='ANTROPOMETRÍA DEPORTISTAS'!D7 -> 0 | G4: ='ANTROPOMETRÍA DEPORTISTAS'!E7 -> 0 | H4: ='ANTROPOMETRÍA DEPORTISTAS'!F7 -> 0 | I4: ='ANTROPOMETRÍA DEPORTISTAS'!G7 -> 0 | J4: ='ANTROPOMETRÍA DEPORTISTAS'!H7 -> 0 | K4: ='ANTROPOMETRÍA DEPORTISTAS'!I7 -> 0 | ... M4: ='ANTROPOMETRÍA DEPORTISTAS'!K7 -> 0
B5: Talla parada (cm) | D5: ='ANTROPOMETRÍA DEPORTISTAS'!B9 -> 0 | E5: ='ANTROPOMETRÍA DEPORTISTAS'!C9 -> 0 | F5: ='ANTROPOMETRÍA DEPORTISTAS'!D9 -> 0 | G5: ='ANTROPOMETRÍA DEPORTISTAS'!E9 -> 0 | H5: ='ANTROPOMETRÍA DEPORTISTAS'!F9 -> 0 | I5: ='ANTROPOMETRÍA DEPORTISTAS'!G9 -> 0 | J5: ='ANTROPOMETRÍA DEPORTISTAS'!H9 -> 0 | K5: ='ANTROPOMETRÍA DEPORTISTAS'!I9 -> 0 | ... M5: ='ANTROPOMETRÍA DEPORTISTAS'!K9 -> 0
B6: ='ANTROPOMETRÍA DEPORTISTAS'!A52 -> % Grasa (Carter 1986) | D6: ='ANTROPOMETRÍA DEPORTISTAS'!B52 -> 3.5803 | E6: ='ANTROPOMETRÍA DEPORTISTAS'!C52 -> 3.5803 | F6: ='ANTROPOMETRÍA DEPORTISTAS'!D52 -> 3.5803 | G6: ='ANTROPOMETRÍA DEPORTISTAS'!E52 -> 3.5803 | H6: ='ANTROPOMETRÍA DEPORTISTAS'!F52 -> 3.5803 | I6: ='ANTROPOMETRÍA DEPORTISTAS'!G52 -> 3.5803 | J6: ='ANTROPOMETRÍA DEPORTISTAS'!H52 -> 3.5803 | K6: ='ANTROPOMETRÍA DEPORTISTAS'!I52 -> 3.5803 | ... M6: ='ANTROPOMETRÍA DEPORTISTAS'!K52 -> 3.5803
B7: ='ANTROPOMETRÍA DEPORTISTAS'!A53 -> % Grasa (Durnin y W. 1974) | D7: ='ANTROPOMETRÍA DEPORTISTAS'!B53 -> #NUM! | E7: ='ANTROPOMETRÍA DEPORTISTAS'!C52 -> 3.5803 | F7: ='ANTROPOMETRÍA DEPORTISTAS'!D52 -> 3.5803 | G7: ='ANTROPOMETRÍA DEPORTISTAS'!E52 -> 3.5803 | H7: ='ANTROPOMETRÍA DEPORTISTAS'!F52 -> 3.5803 | I7: ='ANTROPOMETRÍA DEPORTISTAS'!G52 -> 3.5803 | J7: ='ANTROPOMETRÍA DEPORTISTAS'!H52 -> 3.5803 | K7: ='ANTROPOMETRÍA DEPORTISTAS'!I52 -> 3.5803 | L7: ='ANTROPOMETRÍA DEPORTISTAS'!J52 -> 3.5803 | M7: ='ANTROPOMETRÍA DEPORTISTAS'!K52 -> 3.5803
B8: Interpretación | D8: =IF('ANTROPOMETRÍA DEPORTISTAS'!B53<21, "Excelente", IF('ANTROPOMETRÍA DEPORTISTAS'!B53=34, "Saludable/Normal", IF('ANTROPOMETRÍA DEPORTISTAS'!B53=40, "Sobrepeso", "Sobrepeso II"))) -> #NUM!
B9: Kg de Masa Magra | D9: ='ANTROPOMETRÍA DEPORTISTAS'!B58 -> 0 | E9: ='ANTROPOMETRÍA DEPORTISTAS'!C58 -> 0 | F9: ='ANTROPOMETRÍA DEPORTISTAS'!D58 -> 0 | G9: ='ANTROPOMETRÍA DEPORTISTAS'!E58 -> 0 | H9: ='ANTROPOMETRÍA DEPORTISTAS'!F58 -> 0 | I9: ='ANTROPOMETRÍA DEPORTISTAS'!G58 -> 0 | J9: ='ANTROPOMETRÍA DEPORTISTAS'!H58 -> 0 | K9: ='ANTROPOMETRÍA DEPORTISTAS'!I58 -> 0 | ... M9: ='ANTROPOMETRÍA DEPORTISTAS'!K58 -> 0
B10: Kg de Grasa | D10: ='ANTROPOMETRÍA DEPORTISTAS'!B59 -> 0 | E10: ='ANTROPOMETRÍA DEPORTISTAS'!C59 -> 0 | F10: ='ANTROPOMETRÍA DEPORTISTAS'!D59 -> 0 | G10: ='ANTROPOMETRÍA DEPORTISTAS'!E59 -> 0 | H10: ='ANTROPOMETRÍA DEPORTISTAS'!F59 -> 0 | I10: ='ANTROPOMETRÍA DEPORTISTAS'!G59 -> 0 | J10: ='ANTROPOMETRÍA DEPORTISTAS'!H59 -> 0 | K10: ='ANTROPOMETRÍA DEPORTISTAS'!I59 -> 0 | ... M10: ='ANTROPOMETRÍA DEPORTISTAS'!K59 -> 0
B11: Masa Muscular (Kg) | D11: ='ANTROPOMETRÍA DEPORTISTAS'!B64 -> #DIV/0! | E11: ='ANTROPOMETRÍA DEPORTISTAS'!C64 -> #DIV/0! | F11: ='ANTROPOMETRÍA DEPORTISTAS'!D64 -> #DIV/0! | G11: ='ANTROPOMETRÍA DEPORTISTAS'!E64 -> #DIV/0! | H11: ='ANTROPOMETRÍA DEPORTISTAS'!F64 -> #DIV/0! | I11: ='ANTROPOMETRÍA DEPORTISTAS'!G64 -> #DIV/0! | J11: ='ANTROPOMETRÍA DEPORTISTAS'!H64 -> #DIV/0! | K11: ='ANTROPOMETRÍA DEPORTISTAS'!I64 -> #DIV/0! | ... M11: ='ANTROPOMETRÍA DEPORTISTAS'!K64 -> #DIV/0!
B12: Masa Adiposa (Kg) | D12: ='ANTROPOMETRÍA DEPORTISTAS'!B63 -> #DIV/0! | E12: ='ANTROPOMETRÍA DEPORTISTAS'!C63 -> #DIV/0! | F12: ='ANTROPOMETRÍA DEPORTISTAS'!D63 -> #DIV/0! | G12: ='ANTROPOMETRÍA DEPORTISTAS'!E63 -> #DIV/0! | H12: ='ANTROPOMETRÍA DEPORTISTAS'!F63 -> #DIV/0! | I12: ='ANTROPOMETRÍA DEPORTISTAS'!G63 -> #DIV/0! | J12: ='ANTROPOMETRÍA DEPORTISTAS'!H63 -> #DIV/0! | K12: ='ANTROPOMETRÍA DEPORTISTAS'!I63 -> #DIV/0! | ... M12: ='ANTROPOMETRÍA DEPORTISTAS'!K63 -> #DIV/0!
B13: Sumatoria de 6 pliegues | D13: ='ANTROPOMETRÍA DEPORTISTAS'!B54 -> 0 | E13: ='ANTROPOMETRÍA DEPORTISTAS'!C54 -> 0 | F13: ='ANTROPOMETRÍA DEPORTISTAS'!D54 -> 0 | G13: ='ANTROPOMETRÍA DEPORTISTAS'!E54 -> 0 | H13: ='ANTROPOMETRÍA DEPORTISTAS'!F54 -> 0 | I13: ='ANTROPOMETRÍA DEPORTISTAS'!G54 -> 0 | J13: ='ANTROPOMETRÍA DEPORTISTAS'!H54 -> 0 | K13: ='ANTROPOMETRÍA DEPORTISTAS'!I54 -> 0 | ... M13: ='ANTROPOMETRÍA DEPORTISTAS'!K54 -> 0
B14: Somatotipo | D14: =IF(AND('ANTROPOMETRÍA DEPORTISTAS'!B68>'ANTROPOMETRÍA DEPORTISTAS'!B67, 'ANTROPOMETRÍA DEPORTISTAS'!B68>'ANTROPOMETRÍA DEPORTISTAS'!B66), "Endomorfo", IF(AND('ANTROPOMETRÍA DEPORTISTAS'!B67>'ANTROPOMETRÍA DEPORTISTAS'!B68, 'ANTROPOMETRÍA DEPORTISTAS'!B67>'ANTROPOMETRÍA DEPORTISTAS'!B66), "Mesomorfo", IF(AND('ANTROPOMETRÍA DEPORTISTAS'!B66>'ANTROPOMETRÍA DEPORTISTAS'!B68, 'ANTROPOMETRÍA DEPORTISTAS'!B66>'ANTROPOMETRÍA DEPORTISTAS'!B67), "Ectomorfo", "Somatotipo Balanceado"))) -> #DIV/0! | E14: =IF(AND('ANTROPOMETRÍA DEPORTISTAS'!C68>'ANTROPOMETRÍA DEPORTISTAS'!C67, 'ANTROPOMETRÍA DEPORTISTAS'!C68>'ANTROPOMETRÍA DEPORTISTAS'!C66), "Endomorfo", IF(AND('ANTROPOMETRÍA DEPORTISTAS'!C67>'ANTROPOMETRÍA DEPORTISTAS'!C68, 'ANTROPOMETRÍA DEPORTISTAS'!C67>'ANTROPOMETRÍA DEPORTISTAS'!C66), "Mesomorfo", IF(AND('ANTROPOMETRÍA DEPORTISTAS'!C66>'ANTROPOMETRÍA DEPORTISTAS'!C68, 'ANTROPOMETRÍA DEPORTISTAS'!C66>'ANTROPOMETRÍA DEPORTISTAS'!C67), "Ectomorfo", "Somatotipo Balanceado"))) -> #DIV/0! | F14: =IF(AND('ANTROPOMETRÍA DEPORTISTAS'!D68>'ANTROPOMETRÍA DEPORTISTAS'!D67, 'ANTROPOMETRÍA DEPORTISTAS'!D68>'ANTROPOMETRÍA DEPORTISTAS'!D66), "Endomorfo", IF(AND('ANTROPOMETRÍA DEPORTISTAS'!D67>'ANTROPOMETRÍA DEPORTISTAS'!D68, 'ANTROPOMETRÍA DEPORTISTAS'!D67>'ANTROPOMETRÍA DEPORTISTAS'!D66), "Mesomorfo", IF(AND('ANTROPOMETRÍA DEPORTISTAS'!D66>'ANTROPOMETRÍA DEPORTISTAS'!D68, 'ANTROPOMETRÍA DEPORTISTAS'!D66>'ANTROPOMETRÍA DEPORTISTAS'!D67), "Ectomorfo", "Somatotipo Balanceado"))) -> #DIV/0! | G14: =IF(AND('ANTROPOMETRÍA DEPORTISTAS'!E68>'ANTROPOMETRÍA DEPORTISTAS'!E67, 'ANTROPOMETRÍA DEPORTISTAS'!E68>'ANTROPOMETRÍA DEPORTISTAS'!E66), "Endomorfo", IF(AND('ANTROPOMETRÍA DEPORTISTAS'!E67>'ANTROPOMETRÍA DEPORTISTAS'!E68, 'ANTROPOMETRÍA DEPORTISTAS'!E67>'ANTROPOMETRÍA DEPORTISTAS'!E66), "Mesomorfo", IF(AND('ANTROPOMETRÍA DEPORTISTAS'!E66>'ANTROPOMETRÍA DEPORTISTAS'!E68, 'ANTROPOMETRÍA DEPORTISTAS'!E66>'ANTROPOMETRÍA DEPORTISTAS'!E67), "Ectomorfo", "Somatotipo Balanceado"))) -> #DIV/0! | H14: =IF(AND('ANTROPOMETRÍA DEPORTISTAS'!F68>'ANTROPOMETRÍA DEPORTISTAS'!F67, 'ANTROPOMETRÍA DEPORTISTAS'!F68>'ANTROPOMETRÍA DEPORTISTAS'!F66), "Endomorfo", IF(AND('ANTROPOMETRÍA DEPORTISTAS'!F67>'ANTROPOMETRÍA DEPORTISTAS'!F68, 'ANTROPOMETRÍA DEPORTISTAS'!F67>'ANTROPOMETRÍA DEPORTISTAS'!F66), "Mesomorfo", IF(AND('ANTROPOMETRÍA DEPORTISTAS'!F66>'ANTROPOMETRÍA DEPORTISTAS'!F68, 'ANTROPOMETRÍA DEPORTISTAS'!F66>'ANTROPOMETRÍA DEPORTISTAS'!F67), "Ectomorfo", "Somatotipo Balanceado"))) -> #DIV/0! | I14: =IF(AND('ANTROPOMETRÍA DEPORTISTAS'!G68>'ANTROPOMETRÍA DEPORTISTAS'!G67, 'ANTROPOMETRÍA DEPORTISTAS'!G68>'ANTROPOMETRÍA DEPORTISTAS'!G66), "Endomorfo", IF(AND('ANTROPOMETRÍA DEPORTISTAS'!G67>'ANTROPOMETRÍA DEPORTISTAS'!G68, 'ANTROPOMETRÍA DEPORTISTAS'!G67>'ANTROPOMETRÍA DEPORTISTAS'!G66), "Mesomorfo", IF(AND('ANTROPOMETRÍA DEPORTISTAS'!G66>'ANTROPOMETRÍA DEPORTISTAS'!G68, 'ANTROPOMETRÍA DEPORTISTAS'!G66>'ANTROPOMETRÍA DEPORTISTAS'!G67), "Ectomorfo", "Somatotipo Balanceado"))) -> #DIV/0! | J14: =IF(AND('ANTROPOMETRÍA DEPORTISTAS'!H68>'ANTROPOMETRÍA DEPORTISTAS'!H67, 'ANTROPOMETRÍA DEPORTISTAS'!H68>'ANTROPOMETRÍA DEPORTISTAS'!H66), "Endomorfo", IF(AND('ANTROPOMETRÍA DEPORTISTAS'!H67>'ANTROPOMETRÍA DEPORTISTAS'!H68, 'ANTROPOMETRÍA DEPORTISTAS'!H67>'ANTROPOMETRÍA DEPORTISTAS'!H66), "Mesomorfo", IF(AND('ANTROPOMETRÍA DEPORTISTAS'!H66>'ANTROPOMETRÍA DEPORTISTAS'!H68, 'ANTROPOMETRÍA DEPORTISTAS'!H66>'ANTROPOMETRÍA DEPORTISTAS'!H67), "Ectomorfo", "Somatotipo Balanceado"))) -> #DIV/0! | K14: =IF(AND('ANTROPOMETRÍA DEPORTISTAS'!I68>'ANTROPOMETRÍA DEPORTISTAS'!I67, 'ANTROPOMETRÍA DEPORTISTAS'!I68>'ANTROPOMETRÍA DEPORTISTAS'!I66), "Endomorfo", IF(AND('ANTROPOMETRÍA DEPORTISTAS'!I67>'ANTROPOMETRÍA DEPORTISTAS'!I68, 'ANTROPOMETRÍA DEPORTISTAS'!I67>'ANTROPOMETRÍA DEPORTISTAS'!I66), "Mesomorfo", IF(AND('ANTROPOMETRÍA DEPORTISTAS'!I66>'ANTROPOMETRÍA DEPORTISTAS'!I68, 'ANTROPOMETRÍA DEPORTISTAS'!I66>'ANTROPOMETRÍA DEPORTISTAS'!I67), "Ectomorfo", "Somatotipo Balanceado"))) -> #DIV/0! | ... M14: =IF(AND('ANTROPOMETRÍA DEPORTISTAS'!K68>'ANTROPOMETRÍA DEPORTISTAS'!K67, 'ANTROPOMETRÍA DEPORTISTAS'!K68>'ANTROPOMETRÍA DEPORTISTAS'!K66), "Endomorfo", IF(AND('ANTROPOMETRÍA DEPORTISTAS'!K67>'ANTROPOMETRÍA DEPORTISTAS'!K68, 'ANTROPOMETRÍA DEPORTISTAS'!K67>'ANTROPOMETRÍA DEPORTISTAS'!K66), "Mesomorfo", IF(AND('ANTROPOMETRÍA DEPORTISTAS'!K66>'ANTROPOMETRÍA DEPORTISTAS'!K68, 'ANTROPOMETRÍA DEPORTISTAS'!K66>'ANTROPOMETRÍA DEPORTISTAS'!K67), "Ectomorfo", "Somatotipo Balanceado"))) -> #DIV/0!
B17: DATOS DEL INFORME
B19: Fecha de evaluación | D19: ='ANTROPOMETRÍA DEPORTISTAS'!B6 -> 0 | E19: ='ANTROPOMETRÍA DEPORTISTAS'!C6 -> 0 | F19: ='ANTROPOMETRÍA DEPORTISTAS'!D6 -> 0 | G19: ='ANTROPOMETRÍA DEPORTISTAS'!E6 -> 0 | H19: ='ANTROPOMETRÍA DEPORTISTAS'!F6 -> 0 | I19: ='ANTROPOMETRÍA DEPORTISTAS'!G6 -> 0 | J19: ='ANTROPOMETRÍA DEPORTISTAS'!H6 -> 0 | K19: ='ANTROPOMETRÍA DEPORTISTAS'!I6 -> 0 | ... M19: ='ANTROPOMETRÍA DEPORTISTAS'!K6 -> 0
B20: Peso actual (kg) | D20: ='ANTROPOMETRÍA DEPORTISTAS'!B7 -> 0 | E20: ='ANTROPOMETRÍA DEPORTISTAS'!C7 -> 0 | F20: ='ANTROPOMETRÍA DEPORTISTAS'!D7 -> 0 | G20: ='ANTROPOMETRÍA DEPORTISTAS'!E7 -> 0 | H20: ='ANTROPOMETRÍA DEPORTISTAS'!F7 -> 0 | I20: ='ANTROPOMETRÍA DEPORTISTAS'!G7 -> 0 | J20: ='ANTROPOMETRÍA DEPORTISTAS'!H7 -> 0 | K20: ='ANTROPOMETRÍA DEPORTISTAS'!I7 -> 0 | ... M20: ='ANTROPOMETRÍA DEPORTISTAS'!K7 -> 0
B21: Talla (m) | D21: ='ANTROPOMETRÍA DEPORTISTAS'!B8 -> 0 | E21: ='ANTROPOMETRÍA DEPORTISTAS'!C8 -> 0 | F21: ='ANTROPOMETRÍA DEPORTISTAS'!D8 -> 0 | G21: ='ANTROPOMETRÍA DEPORTISTAS'!E8 -> 0 | H21: ='ANTROPOMETRÍA DEPORTISTAS'!F8 -> 0 | I21: ='ANTROPOMETRÍA DEPORTISTAS'!G8 -> 0 | J21: ='ANTROPOMETRÍA DEPORTISTAS'!H8 -> 0 | K21: ='ANTROPOMETRÍA DEPORTISTAS'!I8 -> 0 | ... M21: ='ANTROPOMETRÍA DEPORTISTAS'!K8 -> 0
B22: Talla (cm) | D22: ='ANTROPOMETRÍA DEPORTISTAS'!B9 -> 0 | E22: ='ANTROPOMETRÍA DEPORTISTAS'!C9 -> 0 | F22: ='ANTROPOMETRÍA DEPORTISTAS'!D9 -> 0 | G22: ='ANTROPOMETRÍA DEPORTISTAS'!E9 -> 0 | H22: ='ANTROPOMETRÍA DEPORTISTAS'!F9 -> 0 | I22: ='ANTROPOMETRÍA DEPORTISTAS'!G9 -> 0 | J22: ='ANTROPOMETRÍA DEPORTISTAS'!H9 -> 0 | K22: ='ANTROPOMETRÍA DEPORTISTAS'!I9 -> 0 | ... M22: ='ANTROPOMETRÍA DEPORTISTAS'!K9 -> 0
B23: Circunferencias(cm)
B24: Brazo relajado (cm) | D24: ='ANTROPOMETRÍA DEPORTISTAS'!B12 -> 0 | E24: ='ANTROPOMETRÍA DEPORTISTAS'!C12 -> 0 | F24: ='ANTROPOMETRÍA DEPORTISTAS'!D12 -> 0 | G24: ='ANTROPOMETRÍA DEPORTISTAS'!E12 -> 0 | H24: ='ANTROPOMETRÍA DEPORTISTAS'!F12 -> 0 | I24: ='ANTROPOMETRÍA DEPORTISTAS'!G12 -> 0 | J24: ='ANTROPOMETRÍA DEPORTISTAS'!H12 -> 0 | K24: ='ANTROPOMETRÍA DEPORTISTAS'!I12 -> 0 | ... M24: ='ANTROPOMETRÍA DEPORTISTAS'!K12 -> 0
B25: Brazo Flexionado en Tensión (cm) | D25: ='ANTROPOMETRÍA DEPORTISTAS'!B13 -> 0 | E25: ='ANTROPOMETRÍA DEPORTISTAS'!C13 -> 0 | F25: ='ANTROPOMETRÍA DEPORTISTAS'!D13 -> 0 | G25: ='ANTROPOMETRÍA DEPORTISTAS'!E13 -> 0 | H25: ='ANTROPOMETRÍA DEPORTISTAS'!F13 -> 0 | I25: ='ANTROPOMETRÍA DEPORTISTAS'!G13 -> 0 | J25: ='ANTROPOMETRÍA DEPORTISTAS'!H13 -> 0 | K25: ='ANTROPOMETRÍA DEPORTISTAS'!I13 -> 0 | ... M25: ='ANTROPOMETRÍA DEPORTISTAS'!K13 -> 0
B26: Antebrazo máximo (cm) | D26: ='ANTROPOMETRÍA DEPORTISTAS'!B14 -> 0 | E26: ='ANTROPOMETRÍA DEPORTISTAS'!C14 -> 0 | F26: ='ANTROPOMETRÍA DEPORTISTAS'!D14 -> 0 | G26: ='ANTROPOMETRÍA DEPORTISTAS'!E14 -> 0 | H26: ='ANTROPOMETRÍA DEPORTISTAS'!F14 -> 0 | I26: ='ANTROPOMETRÍA DEPORTISTAS'!G14 -> 0 | J26: ='ANTROPOMETRÍA DEPORTISTAS'!H14 -> 0 | K26: ='ANTROPOMETRÍA DEPORTISTAS'!I14 -> 0 | ... M26: ='ANTROPOMETRÍA DEPORTISTAS'!K14 -> 0
B27: Tórax (Mesoesternal) (cm) | D27: ='ANTROPOMETRÍA DEPORTISTAS'!B15 -> 0 | E27: ='ANTROPOMETRÍA DEPORTISTAS'!C15 -> 0 | F27: ='ANTROPOMETRÍA DEPORTISTAS'!D15 -> 0 | G27: ='ANTROPOMETRÍA DEPORTISTAS'!E15 -> 0 | H27: ='ANTROPOMETRÍA DEPORTISTAS'!F15 -> 0 | I27: ='ANTROPOMETRÍA DEPORTISTAS'!G15 -> 0 | J27: ='ANTROPOMETRÍA DEPORTISTAS'!H15 -> 0 | K27: ='ANTROPOMETRÍA DEPORTISTAS'!I15 -> 0 | ... M27: ='ANTROPOMETRÍA DEPORTISTAS'!K15 -> 0
B28: Cintura mínimo (cm) | D28: ='ANTROPOMETRÍA DEPORTISTAS'!B16 -> 0 | E28: ='ANTROPOMETRÍA DEPORTISTAS'!C16 -> 0 | F28: ='ANTROPOMETRÍA DEPORTISTAS'!D16 -> 0 | G28: ='ANTROPOMETRÍA DEPORTISTAS'!E16 -> 0 | H28: ='ANTROPOMETRÍA DEPORTISTAS'!F16 -> 0 | I28: ='ANTROPOMETRÍA DEPORTISTAS'!G16 -> 0 | J28: ='ANTROPOMETRÍA DEPORTISTAS'!H16 -> 0 | K28: ='ANTROPOMETRÍA DEPORTISTAS'!I16 -> 0 | ... M28: ='ANTROPOMETRÍA DEPORTISTAS'!K16 -> 0
B29: Cadera máximo (cm) | D29: ='ANTROPOMETRÍA DEPORTISTAS'!B17 -> 0 | E29: ='ANTROPOMETRÍA DEPORTISTAS'!C17 -> 0 | F29: ='ANTROPOMETRÍA DEPORTISTAS'!D17 -> 0 | G29: ='ANTROPOMETRÍA DEPORTISTAS'!E17 -> 0 | H29: ='ANTROPOMETRÍA DEPORTISTAS'!F17 -> 0 | I29: ='ANTROPOMETRÍA DEPORTISTAS'!G17 -> 0 | J29: ='ANTROPOMETRÍA DEPORTISTAS'!H17 -> 0 | K29: ='ANTROPOMETRÍA DEPORTISTAS'!I17 -> 0 | ... M29: ='ANTROPOMETRÍA DEPORTISTAS'!K17 -> 0
B30: Muslo máximo (cm) | D30: ='ANTROPOMETRÍA DEPORTISTAS'!B18 -> 0 | E30: ='ANTROPOMETRÍA DEPORTISTAS'!C18 -> 0 | F30: ='ANTROPOMETRÍA DEPORTISTAS'!D18 -> 0 | G30: ='ANTROPOMETRÍA DEPORTISTAS'!E18 -> 0 | H30: ='ANTROPOMETRÍA DEPORTISTAS'!F18 -> 0 | I30: ='ANTROPOMETRÍA DEPORTISTAS'!G18 -> 0 | J30: ='ANTROPOMETRÍA DEPORTISTAS'!H18 -> 0 | K30: ='ANTROPOMETRÍA DEPORTISTAS'!I18 -> 0 | ... M30: ='ANTROPOMETRÍA DEPORTISTAS'!K18 -> 0
B31: Muslo medial (cm) | D31: ='ANTROPOMETRÍA DEPORTISTAS'!B19 -> 0 | E31: ='ANTROPOMETRÍA DEPORTISTAS'!C19 -> 0 | F31: ='ANTROPOMETRÍA DEPORTISTAS'!D19 -> 0 | G31: ='ANTROPOMETRÍA DEPORTISTAS'!E19 -> 0 | H31: ='ANTROPOMETRÍA DEPORTISTAS'!F19 -> 0 | I31: ='ANTROPOMETRÍA DEPORTISTAS'!G19 -> 0 | J31: ='ANTROPOMETRÍA DEPORTISTAS'!H19 -> 0 | K31: ='ANTROPOMETRÍA DEPORTISTAS'!I19 -> 0 | ... M31: ='ANTROPOMETRÍA DEPORTISTAS'!K19 -> 0
B32: Pantorrilla máximo (cm) | D32: ='ANTROPOMETRÍA DEPORTISTAS'!B20 -> 0 | E32: ='ANTROPOMETRÍA DEPORTISTAS'!C20 -> 0 | F32: ='ANTROPOMETRÍA DEPORTISTAS'!D20 -> 0 | G32: ='ANTROPOMETRÍA DEPORTISTAS'!E20 -> 0 | H32: ='ANTROPOMETRÍA DEPORTISTAS'!F20 -> 0 | I32: ='ANTROPOMETRÍA DEPORTISTAS'!G20 -> 0 | J32: ='ANTROPOMETRÍA DEPORTISTAS'!H20 -> 0 | K32: ='ANTROPOMETRÍA DEPORTISTAS'!I20 -> 0 | ... M32: ='ANTROPOMETRÍA DEPORTISTAS'!K20 -> 0
B33: Pliegues (mm)
B34: Bíceps (mm) | D34: ='ANTROPOMETRÍA DEPORTISTAS'!B22 -> 0 | E34: ='ANTROPOMETRÍA DEPORTISTAS'!C22 -> 0 | F34: ='ANTROPOMETRÍA DEPORTISTAS'!D22 -> 0 | G34: ='ANTROPOMETRÍA DEPORTISTAS'!E22 -> 0 | H34: ='ANTROPOMETRÍA DEPORTISTAS'!F22 -> 0 | I34: ='ANTROPOMETRÍA DEPORTISTAS'!G22 -> 0 | J34: ='ANTROPOMETRÍA DEPORTISTAS'!H22 -> 0 | K34: ='ANTROPOMETRÍA DEPORTISTAS'!I22 -> 0 | ... M34: ='ANTROPOMETRÍA DEPORTISTAS'!K22 -> 0
B35: Tríceps (mm) | D35: ='ANTROPOMETRÍA DEPORTISTAS'!B23 -> 0 | E35: ='ANTROPOMETRÍA DEPORTISTAS'!C23 -> 0 | F35: ='ANTROPOMETRÍA DEPORTISTAS'!D23 -> 0 | G35: ='ANTROPOMETRÍA DEPORTISTAS'!E23 -> 0 | H35: ='ANTROPOMETRÍA DEPORTISTAS'!F23 -> 0 | I35: ='ANTROPOMETRÍA DEPORTISTAS'!G23 -> 0 | J35: ='ANTROPOMETRÍA DEPORTISTAS'!H23 -> 0 | K35: ='ANTROPOMETRÍA DEPORTISTAS'!I23 -> 0 | ... M35: ='ANTROPOMETRÍA DEPORTISTAS'!K23 -> 0
B36: Subescapular (mm) | D36: ='ANTROPOMETRÍA DEPORTISTAS'!B24 -> 0 | E36: ='ANTROPOMETRÍA DEPORTISTAS'!C24 -> 0 | F36: ='ANTROPOMETRÍA DEPORTISTAS'!D24 -> 0 | G36: ='ANTROPOMETRÍA DEPORTISTAS'!E24 -> 0 | H36: ='ANTROPOMETRÍA DEPORTISTAS'!F24 -> 0 | I36: ='ANTROPOMETRÍA DEPORTISTAS'!G24 -> 0 | J36: ='ANTROPOMETRÍA DEPORTISTAS'!H24 -> 0 | K36: ='ANTROPOMETRÍA DEPORTISTAS'!I24 -> 0 | ... M36: ='ANTROPOMETRÍA DEPORTISTAS'!K24 -> 0
B37: Ileo-crestal (mm) | D37: ='ANTROPOMETRÍA DEPORTISTAS'!B25 -> 0 | E37: ='ANTROPOMETRÍA DEPORTISTAS'!C25 -> 0 | F37: ='ANTROPOMETRÍA DEPORTISTAS'!D25 -> 0 | G37: ='ANTROPOMETRÍA DEPORTISTAS'!E25 -> 0 | H37: ='ANTROPOMETRÍA DEPORTISTAS'!F25 -> 0 | I37: ='ANTROPOMETRÍA DEPORTISTAS'!G25 -> 0 | J37: ='ANTROPOMETRÍA DEPORTISTAS'!H25 -> 0 | K37: ='ANTROPOMETRÍA DEPORTISTAS'!I25 -> 0 | ... M37: ='ANTROPOMETRÍA DEPORTISTAS'!K25 -> 0
B38: Supra-espinal (mm) | D38: ='ANTROPOMETRÍA DEPORTISTAS'!B26 -> 0 | E38: ='ANTROPOMETRÍA DEPORTISTAS'!C26 -> 0 | F38: ='ANTROPOMETRÍA DEPORTISTAS'!D26 -> 0 | G38: ='ANTROPOMETRÍA DEPORTISTAS'!E26 -> 0 | H38: ='ANTROPOMETRÍA DEPORTISTAS'!F26 -> 0 | I38: ='ANTROPOMETRÍA DEPORTISTAS'!G26 -> 0 | J38: ='ANTROPOMETRÍA DEPORTISTAS'!H26 -> 0 | K38: ='ANTROPOMETRÍA DEPORTISTAS'!I26 -> 0 | ... M38: ='ANTROPOMETRÍA DEPORTISTAS'!K26 -> 0
B39: Abdominal (mm) | D39: ='ANTROPOMETRÍA DEPORTISTAS'!B27 -> 0 | E39: ='ANTROPOMETRÍA DEPORTISTAS'!C27 -> 0 | F39: ='ANTROPOMETRÍA DEPORTISTAS'!D27 -> 0 | G39: ='ANTROPOMETRÍA DEPORTISTAS'!E27 -> 0 | H39: ='ANTROPOMETRÍA DEPORTISTAS'!F27 -> 0 | I39: ='ANTROPOMETRÍA DEPORTISTAS'!G27 -> 0 | J39: ='ANTROPOMETRÍA DEPORTISTAS'!H27 -> 0 | K39: ='ANTROPOMETRÍA DEPORTISTAS'!I27 -> 0 | ... M39: ='ANTROPOMETRÍA DEPORTISTAS'!K27 -> 0
B40: Muslo frontal (mm) | D40: ='ANTROPOMETRÍA DEPORTISTAS'!B28 -> 0 | E40: ='ANTROPOMETRÍA DEPORTISTAS'!C28 -> 0 | F40: ='ANTROPOMETRÍA DEPORTISTAS'!D28 -> 0 | G40: ='ANTROPOMETRÍA DEPORTISTAS'!E28 -> 0 | H40: ='ANTROPOMETRÍA DEPORTISTAS'!F28 -> 0 | I40: ='ANTROPOMETRÍA DEPORTISTAS'!G28 -> 0 | J40: ='ANTROPOMETRÍA DEPORTISTAS'!H28 -> 0 | K40: ='ANTROPOMETRÍA DEPORTISTAS'!I28 -> 0 | ... M40: ='ANTROPOMETRÍA DEPORTISTAS'!K28 -> 0
B41: Pantorrilla (mm) | D41: ='ANTROPOMETRÍA DEPORTISTAS'!B29 -> 0 | E41: ='ANTROPOMETRÍA DEPORTISTAS'!C29 -> 0 | F41: ='ANTROPOMETRÍA DEPORTISTAS'!D29 -> 0 | G41: ='ANTROPOMETRÍA DEPORTISTAS'!E29 -> 0 | H41: ='ANTROPOMETRÍA DEPORTISTAS'!F29 -> 0 | I41: ='ANTROPOMETRÍA DEPORTISTAS'!G29 -> 0 | J41: ='ANTROPOMETRÍA DEPORTISTAS'!H29 -> 0 | K41: ='ANTROPOMETRÍA DEPORTISTAS'!I29 -> 0 | ... M41: ='ANTROPOMETRÍA DEPORTISTAS'!K29 -> 0
B42: Diametros óseos (cm)
B43: Humeral (Biepicondilar) | D43: ='ANTROPOMETRÍA DEPORTISTAS'!B35 -> 0 | E43: ='ANTROPOMETRÍA DEPORTISTAS'!C35 -> 0 | F43: ='ANTROPOMETRÍA DEPORTISTAS'!D35 -> 0 | G43: ='ANTROPOMETRÍA DEPORTISTAS'!E35 -> 0 | H43: ='ANTROPOMETRÍA DEPORTISTAS'!F35 -> 0 | I43: ='ANTROPOMETRÍA DEPORTISTAS'!G35 -> 0 | J43: ='ANTROPOMETRÍA DEPORTISTAS'!H35 -> 0 | K43: ='ANTROPOMETRÍA DEPORTISTAS'!I35 -> 0 | ... M43: ='ANTROPOMETRÍA DEPORTISTAS'!K35 -> 0
B44: Femoral (Biepicondilar) | D44: ='ANTROPOMETRÍA DEPORTISTAS'!B36 -> 0 | E44: ='ANTROPOMETRÍA DEPORTISTAS'!C36 -> 0 | F44: ='ANTROPOMETRÍA DEPORTISTAS'!D36 -> 0 | G44: ='ANTROPOMETRÍA DEPORTISTAS'!E36 -> 0 | H44: ='ANTROPOMETRÍA DEPORTISTAS'!F36 -> 0 | I44: ='ANTROPOMETRÍA DEPORTISTAS'!G36 -> 0 | J44: ='ANTROPOMETRÍA DEPORTISTAS'!H36 -> 0 | K44: ='ANTROPOMETRÍA DEPORTISTAS'!I36 -> 0 | ... M44: ='ANTROPOMETRÍA DEPORTISTAS'!K36 -> 0
...

Sheet Feedback
E3: Evaluación | G3: 2 | H3: 3 | I3: 3 | J3: 4 | K3: 5
E4: Fecha:
E5: Cumplimiento 1/10
E6: Observaciones:

Sheet DATOS ANTROPOMÉTRICOS
A14: DATOS ANTROPOMETRICOS
B16: FECHA DE EVALUACION
A17: BASICOS
A18: Peso (kg)
A19: Talla (cm)
A20: PLIEGUES CUTANEOS (mm)
A21: Tríceps
A22: Subescapular
A23: Bíceps
A24: Cresta Iliaca
A25: Supraespinal
A26: Abdominal
A27: Muslo Frontal
A28: Pantorrilla Medial
... A38: ESTIMACIÓN DE VARIABLES ANTROPOMETRICAS
A39: % Grasa Durning & W. (adultos 17 años y mas) | B39: =IF(HISTORIA!C10="masculino",(495/(1.1765-(0.0744*LOG10(B21+B22+B23+B24)))-450),(495/(1.1567-(0.0717*LOG10(B21+B22+B23+B24)))-450)) -> #NUM! | C39: =IF(HISTORIA!C10="masculino",(495/(1.1765-(0.0744*LOG10(C21+C22+C23+C24)))-450),(495/(1.1567-(0.0717*LOG10(C21+C22+C23+C24)))-450)) -> #NUM! | D39: =IF(HISTORIA!C10="masculino",(495/(1.1765-(0.0744*LOG10(D21+D22+D23+D24)))-450),(495/(1.1567-(0.0717*LOG10(D21+D22+D23+D24)))-450)) -> #NUM! | E39: =IF(HISTORIA!C10="masculino",(495/(1.1765-(0.0744*LOG10(E21+E22+E23+E24)))-450),(495/(1.1567-(0.0717*LOG10(E21+E22+E23+E24)))-450)) -> #NUM! | F39: =IF(HISTORIA!C10="masculino",(495/(1.1765-(0.0744*LOG10(F21+F22+F23+F24)))-450),(495/(1.1567-(0.0717*LOG10(F21+F22+F23+F24)))-450)) -> #NUM! | G39: =IF(HISTORIA!C10="masculino",(495/(1.1765-(0.0744*LOG10(G21+G22+G23+G24)))-450),(495/(1.1567-(0.0717*LOG10(G21+G22+G23+G24)))-450)) -> #NUM! | H39: =IF(HISTORIA!C10="masculino",(495/(1.1765-(0.0744*LOG10(H21+H22+H23+H24)))-450),(495/(1.1567-(0.0717*LOG10(H21+H22+H23+H24)))-450)) -> #NUM! | I39: =IF(HISTORIA!C10="masculino",(495/(1.1765-(0.0744*LOG10(I21+I22+I23+I24)))-450),(495/(1.1567-(0.0717*LOG10(I21+I22+I23+I24)))-450)) -> #NUM! | J39: =IF(HISTORIA!C10="masculino",(495/(1.1765-(0.0744*LOG10(J21+J22+J23+J24)))-450),(495/(1.1567-(0.0717*LOG10(J21+J22+J23+J24)))-450)) -> #NUM! | K39: =IF(HISTORIA!C10="masculino",(495/(1.1765-(0.0744*LOG10(K21+K22+K23+K24)))-450),(495/(1.1567-(0.0717*LOG10(K21+K22+K23+K24)))-450)) -> #NUM! | L39: =IF(HISTORIA!C10="masculino",(495/(1.1765-(0.0744*LOG10(L21+L22+L23+L24)))-450),(495/(1.1567-(0.0717*LOG10(L21+L22+L23+L24)))-450)) -> #NUM! | M39: =IF(HISTORIA!C10="masculino",(495/(1.1765-(0.0744*LOG10(M21+M22+M23+M24)))-450),(495/(1.1567-(0.0717*LOG10(M21+M22+M23+M24)))-450)) -> #NUM!
A40: % Grasa Carter-Yuhasz (Atletas) | B40: =IF(HISTORIA!C10="masculino",(0.1051*(B21+B22+B25+B26+B27+B28)+2.585),(0.1548*(B21+B22+B25+B26+B27+B28)+3.58)) -> 3.58 | C40: =IF(HISTORIA!C10="masculino",(0.1051*(C21+C22+C25+C26+C27+C28)+2.585),(0.1548*(C21+C22+C25+C26+C27+C28)+3.58)) -> 3.58 | D40: =IF(HISTORIA!C10="masculino",(0.1051*(D21+D22+D25+D26+D27+D28)+2.585),(0.1548*(D21+D22+D25+D26+D27+D28)+3.58)) -> 3.58 | E40: =IF(HISTORIA!C10="masculino",(0.1051*(E21+E22+E25+E26+E27+E28)+2.585),(0.1548*(E21+E22+E25+E26+E27+E28)+3.58)) -> 3.58 | F40: =IF(HISTORIA!C10="masculino",(0.1051*(F21+F22+F25+F26+F27+F28)+2.585),(0.1548*(F21+F22+F25+F26+F27+F28)+3.58)) -> 3.58 | G40: =IF(HISTORIA!C10="masculino",(0.1051*(G21+G22+G25+G26+G27+G28)+2.585),(0.1548*(G21+G22+G25+G26+G27+G28)+3.58)) -> 3.58 | H40: =IF(HISTORIA!C10="masculino",(0.1051*(H21+H22+H25+H26+H27+H28)+2.585),(0.1548*(H21+H22+H25+H26+H27+H28)+3.58)) -> 3.58 | I40: =IF(HISTORIA!C10="masculino",(0.1051*(I21+I22+I25+I26+I27+I28)+2.585),(0.1548*(I21+I22+I25+I26+I27+I28)+3.58)) -> 3.58 | J40: =IF(HISTORIA!C10="masculino",(0.1051*(J21+J22+J25+J26+J27+J28)+2.585),(0.1548*(J21+J22+J25+J26+J27+J28)+3.58)) -> 3.58 | K40: =IF(HISTORIA!C10="masculino",(0.1051*(K21+K22+K25+K26+K27+K28)+2.585),(0.1548*(K21+K22+K25+K26+K27+K28)+3.58)) -> 3.58 | L40: =IF(HISTORIA!C10="masculino",(0.1051*(L21+L22+L25+L26+L27+L28)+2.585),(0.1548*(L21+L22+L25+L26+L27+L28)+3.58)) -> 3.58 | M40: =IF(HISTORIA!C10="masculino",(0.1051*(M21+M22+M25+M26+M27+M28)+2.585),(0.1548*(M21+M22+M25+M26+M27+M28)+3.58)) -> 3.58
A41: % Grasa Durnin ADULTOS | B41: =(((0.2467)*(B21+B22++B23+B24))+((0.12*B32)))+4.98 -> 4.98 | C41: =(((0.2467)*(C21+C22++C23+C24))+((0.12*C32)))+4.98 -> 4.98 | D41: =(((0.2467)*(D21+D22++D23+D24))+((0.12*D32)))+4.98 -> 4.98 | E41: =(((0.2467)*(E21+E22++E23+E24))+((0.12*E32)))+4.98 -> 4.98 | F41: =(((0.2467)*(F21+F22++F23+F24))+((0.12*F32)))+4.98 -> 4.98 | G41: =(((0.2467)*(G21+G22++G23+G24))+((0.12*G32)))+4.98 -> 4.98 | H41: =(((0.2467)*(H21+H22++H23+H24))+((0.12*H32)))+4.98 -> 4.98 | I41: =(((0.2467)*(I21+I22++I23+I24))+((0.12*I32)))+4.98 -> 4.98 | ... M41: =(((0.2467)*(M21+M22++M23+M24))+((0.12*M32)))+4.98 -> 4.98
A42: % Grasa Brook (1-11 años) | B42: =IF(HISTORIA!C10="masculino",(530/(1.169-(0.078*LOG10(B21+B22+B23+B25)))-489),(530/(1.2063-(0.0999*LOG10(B21+B22+B23+B25)))-489)) -> #NUM! | C42: =IF(HISTORIA!C10="masculino",(530/(1.169-(0.078*LOG10(C21+C22+C23+C25)))-489),(530/(1.2063-(0.0999*LOG10(C21+C22+C23+C25)))-489)) -> #NUM! | D42: =IF(HISTORIA!C10="masculino",(530/(1.169-(0.078*LOG10(D21+D22+D23+D25)))-489),(530/(1.2063-(0.0999*LOG10(D21+D22+D23+D25)))-489)) -> #NUM! | E42: =IF(HISTORIA!C10="masculino",(530/(1.169-(0.078*LOG10(E21+E22+E23+E25)))-489),(530/(1.2063-(0.0999*LOG10(E21+E22+E23+E25)))-489)) -> #NUM! | F42: =IF(HISTORIA!C10="masculino",(530/(1.169-(0.078*LOG10(F21+F22+F23+F25)))-489),(530/(1.2063-(0.0999*LOG10(F21+F22+F23+F25)))-489)) -> #NUM! | G42: =IF(HISTORIA!C10="masculino",(530/(1.169-(0.078*LOG10(G21+G22+G23+G25)))-489),(530/(1.2063-(0.0999*LOG10(G21+G22+G23+G25)))-489)) -> #NUM! | H42: =IF(HISTORIA!C10="masculino",(530/(1.169-(0.078*LOG10(H21+H22+H23+H25)))-489),(530/(1.2063-(0.0999*LOG10(H21+H22+H23+H25)))-489)) -> #NUM! | I42: =IF(HISTORIA!C10="masculino",(530/(1.169-(0.078*LOG10(I21+I22+I23+I25)))-489),(530/(1.2063-(0.0999*LOG10(I21+I22+I23+I25)))-489)) -> #NUM! | J42: =IF(HISTORIA!C10="masculino",(530/(1.169-(0.078*LOG10(J21+J22+J23+J25)))-489),(530/(1.2063-(0.0999*LOG10(J21+J22+J23+J25)))-489)) -> #NUM! | K42: =IF(HISTORIA!C10="masculino",(530/(1.169-(0.078*LOG10(K21+K22+K23+K25)))-489),(530/(1.2063-(0.0999*LOG10(K21+K22+K23+K25)))-489)) -> #NUM! | L42: =IF(HISTORIA!C10="masculino",(530/(1.169-(0.078*LOG10(L21+L22+L23+L25)))-489),(530/(1.2063-(0.0999*LOG10(L21+L22+L23+L25)))-489)) -> #NUM! | M42: =IF(HISTORIA!C10="masculino",(530/(1.169-(0.078*LOG10(M21+M22+M23+M25)))-489),(530/(1.2063-(0.0999*LOG10(M21+M22+M23+M25)))-489)) -> #NUM!
