Workbook

Sheet HISTORIA
A1: HISTORIA CLÍNICO-NUTRICIONAL | AC1: Masculino
A2: Fecha: | B2: 46045 | AC2: Femenino
A3: 1- DATOS PERSONALES
A4: Nombre y Apellido | C4: Javier Ignacio Alvarez Izaguirre | G4: Ocupación | I4: Desarrollo de sotfware
A5: Cédula | C5: 29625616 | G5: Nivel de actividad en el trabajo | I5: Muy activo
A6: Fecha de nacimiento | C6: 37404 | G6: Teléfono
A7: Edad | C7: =(B2-C6)/365 -> 23.673973 | G7: Correo electrónico
A8: Estado civil | G8: Deporte/Actividad | K8: Posición
A9: Dirección | C9: La Alameda | K9: Perfil
A10: Sexo | C10: Masculino
A11: Motivo de consulta | C11: Afirma relación rara con la comida. Perder grasa como objetivo visual
A12: Tratamiento médico | C12: Ashwagandha a veces, Magnesio, Melatonina cuando le cuesta dormir. 3 meses de creatina, para un mes y proteina en polvo.
A13: 2-ANTECEDENTES PERSONALES
A14: Enfermedad(es) importante(s) diagnosticada(s) | E14: Niega
A15: Operación(es) realizada(s) | E15: Rinoplastia
A16: 3- ANTECEDENTES FAMILIARES
A17: Enfermedad(es) importante(s) diagnosticada(s) | E17: Abuela materna DM, HTA.
A18: 4- HÁBITOS (PSICOBIOLÓGICO Y FUNCIONALES)
A19: Café | C19: 3 tazas sin azúcar | E19: Agua | H19: 4 litros aprox diarios
A20: Alcohol | C20: Niega | E20: Apetito/Ansiedad | H20: Alto
A21: Tabaco | C21: NIega | E21: Alguna otra información relevante:
A22: Consumo de drogas | C22: Niega
A23: Horas de sueño nocturnas | C23: Reparador. A veces intermitente
A24: Hábitos intestinales | D24: Regular
A25: Hábitos miccionales | D25: Regular
A26: Acidez/Pirosis/Náuseas | D26: Niega
A27: 5- HÁBITOS Y CONDUCTAS ALIMENTARIAS
A28: Horas de mayor apetito | D28: Noche | G28: Rechazos alimentarios | J28: Queso de cabra y mostaza
A29: Comidas fuera de casa | D29: 1 vez a la semana
A30: Alergias alimentarias | D30: NIega
A31: Intolerancias alimentarias | D31: Niega
A32: 6- DEPORTE/ACTIVIDAD FÍSICA/ENERGÍA DE ACTIVIDAD
A33: Tipo de Actividad | E33: Horas/Día | H33: Coeficiente | K33: Coeficiente x hora
A34: Deporte | H34: 3 | K34: =PRODUCT(E34*H34) -> 0
A35: Tv -Lectura | H35: 1 | K35: =PRODUCT(E35*H35) -> 0
A36: Juegos Pasivos | H36: 1.5 | K36: =PRODUCT(E36*H36) -> 0
A37: Juegos Activos | H37: 2.5 | K37: =PRODUCT(E37*H37) -> 0
A38: Escolar | H38: 1 | K38: =PRODUCT(E38*H38) -> 0
A39: Descanso | H39: 0 | K39: =PRODUCT(E39*H39) -> 0
A40: TOTAL | E40: =SUM(E34:G39) -> 0 | K40: =SUM(K34:M39) -> 0
...

Sheet LABORATORIO
A1: LABORATORIO
A4: ANALISÍS QUÍMICO Y HEMATOLÓGIO
A5: PARÁMETRO | B5: VALOR CONSULTA 1 | C5: VALOR CONSULTA 2 | D5: VALOR CONSULTA 3 | E5: VALORES DE REFERENCIA
A6: Hemoglobina | E6: H: 13 – 18 g/dL M: 12 -14 G/dL
A7: Hematocrito | E7: H: 37 – 49 g/dL M: 36 -46 d/dL
A8: Glucosa | E8: 70 – 100 mg/dL
A9: Colesterol total | E9: Hasta 200 mg/dL
A10: Colesterol HDL | E10: H: mayor a 40 mg/dL M: mayor a 50 mg/dL
A12: Colesterol LDL | E12: Menor 130 mg/dL
A13: Triglicéridos | E13: Hasta 150 mg/dL
A14: Urea | E14: 10 – 50 g/dL
A15: Creatinina | E15: 0.8 – 1.2 mg/dL
A16: Ácido úrico | E16: 2.4 – 7.2 mg/dL
A17: BUN | E17: 8 – 20 mg/dL
A18: Proteínas totales | E18: 5.5 – 8 g/dL
... A46: Insulina | E46: <9 µg/mL
A48: Heces
A49: Orina

Sheet ANTROPOMETRÍA DEPORTISTAS
B1: VALORES ANTROPOMÉTRICOS | O1: VALORES ANTROPOMÉTRICOS
A5: Número de evaluación | B5: 1
A6: Fecha de evaluación | B6: 45994
A7: Peso actual (kg) | B7: 90.05
A8: Talla (m) | B8: 1.86
A9: Talla (cm) | B9: =B8*100 -> 186 | C9: =C8*100 -> 0 | D9: =D8*100 -> 0 | E9: =E8*100 -> 0 | F9: =F8*100 -> 0 | G9: =G8*100 -> 0 | H9: =H8*100 -> 0 | I9: =I8*100 -> 0 | ... O9: =O8*100 -> 0
A10: Talla sentada (cm)
A11: Circunferencias(cm)
A12: Brazo relajado (cm) | B12: 39.1
A13: Brazo Flexionado en Tensión (cm) | B13: 41.5
A14: Antebrazo máximo (cm) | B14: 31
A15: Tórax (Mesoesternal) (cm) | B15: 108
A16: Cintura mínimo (cm) | B16: 85
A17: Cadera máximo (cm) | B17: 99.8
A18: Muslo máximo (cm) | B18: 61.3
A19: Muslo medial (cm) | B19: 58.3
A20: Pantorrilla máximo (cm) | B20: 38.6
A21: Pliegues (mm)
A22: Bíceps (mm) | B22: 3.5
A23: Tríceps (mm) | B23: 6.5
A24: Subescapular (mm) | B24: 11.5
A25: Ileo-crestal (mm) | B25: 15.5
A26: Supra-espinal (mm) | B26: 14
A27: Abdominal (mm) | B27: 28.5
A28: Muslo frontal (mm) | B28: 10.5
A29: Pantorrilla (mm) | B29: 6.5
A30: Diametros óseos (cm)
A31: Biacromial (cm)
A32: Toráx Tranverso (cm)
A33: Toráx Anteroposterior (cm)
A34: Biilocrestídio (cm)
A35: Humeral (Biepicondilar) | B35: 8
A36: Femoral (Biepicondilar) | B36: 10.5
A37: Circunferencias corregidas por pliegues (cm)
A38: Brazo relajado (cm) | B38: =B12-(3.1416*B23)/10 -> 37.05796 | C38: =C12-(3.1416*C23)/10 -> 0 | D38: =D12-(3.1416*D23)/10 -> 0 | E38: =E12-(3.1416*E23)/10 -> 0 | F38: =F12-(3.1416*F23)/10 -> 0 | G38: =G12-(3.1416*G23)/10 -> 0 | H38: =H12-(3.1416*H23)/10 -> 0 | I38: =I12-(3.1416*I23)/10 -> 0 | ... O38: =O12-(3.1416*O23)/10 -> 0
A39: Caja torácica (cm) | B39: =B15-(3.1416*B24)/10 -> 104.38716 | C39: =C15-(3.1416*C24)/10 -> 0 | D39: =D15-(3.1416*D24)/10 -> 0 | E39: =E15-(3.1416*E24)/10 -> 0 | F39: =F15-(3.1416*F24)/10 -> 0 | G39: =G15-(3.1416*G24)/10 -> 0 | H39: =H15-(3.1416*H24)/10 -> 0 | I39: =I15-(3.1416*I24)/10 -> 0 | ... O39: =O15-(3.1416*O24)/10 -> 0
A40: Cintura (cm) | B40: =B16-(3.1416*B27)/10 -> 76.04644 | C40: =C16-(3.1416*C27)/10 -> 0 | D40: =D16-(3.1416*D27)/10 -> 0 | E40: =E16-(3.1416*E27)/10 -> 0 | F40: =F16-(3.1416*F27)/10 -> 0 | G40: =G16-(3.1416*G27)/10 -> 0 | H40: =H16-(3.1416*H27)/10 -> 0 | I40: =I16-(3.1416*I27)/10 -> 0 | ... O40: =O16-(3.1416*O27)/10 -> 0
A41: Muslo máximo (cm) | B41: =B18-(3.1416*B28)/10 -> 58.00132 | C41: =C18-(3.1416*C28)/10 -> 0 | D41: =D18-(3.1416*D28)/10 -> 0 | E41: =E18-(3.1416*E28)/10 -> 0 | F41: =F18-(3.1416*F28)/10 -> 0 | G41: =G18-(3.1416*G28)/10 -> 0 | H41: =H18-(3.1416*H28)/10 -> 0 | I41: =I18-(3.1416*I28)/10 -> 0 | ... O41: =O18-(3.1416*O28)/10 -> 0
A42: Pantorrilla máximo (cm) | B42: =B20-(3.1416*B29)/10 -> 36.55796 | C42: =C20-(3.1416*C29)/10 -> 0 | D42: =D20-(3.1416*D29)/10 -> 0 | E42: =E20-(3.1416*E29)/10 -> 0 | F42: =F20-(3.1416*F29)/10 -> 0 | G42: =G20-(3.1416*G29)/10 -> 0 | H42: =H20-(3.1416*H29)/10 -> 0 | I42: =I20-(3.1416*I29)/10 -> 0 | ... O42: =O20-(3.1416*O29)/10 -> 0
A43: INDICADORES (2 componentes)
...

Sheet 5 COMPONENTES
A1: DATOS PERSONALES | B1: Nombre y apellido | C1: =HISTORIA!C4 -> Javier Ignacio Alvarez Izaguirre
B2: Fecha de evaluación
B3: Fecha de nacimiento | C3: =HISTORIA!C6 -> 37404
B4: Edad (años) | C4: =(C2-C3)/365 -> -102.47671 | D4: =(D2-D3)/365 -> 0 | E4: =(E2-E3)/365 -> 0 | F4: =(F2-F3)/365 -> 0 | G4: =(G2-G3)/365 -> 0 | H4: =(H2-H3)/365 -> 0 | I4: =(I2-I3)/365 -> 0 | J4: =(J2-J3)/365 -> 0 | ... L4: =(L2-L3)/365 -> 0
A5: Mediciones básicas | B5: Peso (kg)
B6: Talla parado (cm) | C6: 185 | D6: 185 | E6: 185 | F6: 185 | G6: 185 | H6: 185 | I6: 185 | J6: 185 | K6: 185 | L6: 185
B7: Talla sentado corregida (cm) | C7: =C8-43 -> -43 | D7: =D8-43 -> -43 | E7: =E8-43 -> -43 | F7: =F8-43 -> -43 | G7: =G8-43 -> -43 | H7: =H8-43 -> -43 | I7: =I8-43 -> -43 | J7: =J8-43 -> -43 | ... L7: =L8-43 -> -43
B8: Talla sentado (cm)
A10: Pliegues cutáneos (mm) | B10: Tríceps
B11: Subescapular
B12: Bíceps
B13: Cresta Ilíaca
B14: Supraespinal
B15: Abdominal
B16: Muslo frontal
B17: Pantorrilla
A19: Circunferencias (cm) | B19: Cabeza
B20: Cuello
B21: Brazo relajado
B22: Brazo flexionado en tensión
B23: Antebrazo máximo
B24: Muñeca
B25: Tórax (Mesoesternal)
B26: Cintura (Mínimo)
B27: Cadera (Máximo)
B28: Muslo máximo
B29: Muslo medio
B30: Pantorrilla
B31: Tobillo
A33: Diámetros óseos (mm) | B33: Biacromial
B34: Tórax transverso
B35: Tórax anteroposterior
B36: Biiliocrestídeo
B37: Humeral (Biepicondilar)
B38: Femoral (Biepicondilar)
B39: Muñeca (Biestiloidea)
A41: Circunferencias corregidas (mm) | B41: Brazo relajado corregido | C41: =C21-(3.1416*C10)/10 -> 0 | D41: =D21-(3.1416*D10)/10 -> 0 | E41: =E21-(3.1416*E10)/10 -> 0 | F41: =F21-(3.1416*F10)/10 -> 0 | G41: =G21-(3.1416*G10)/10 -> 0 | H41: =H21-(3.1416*H10)/10 -> 0 | I41: =I21-(3.1416*I10)/10 -> 0 | J41: =J21-(3.1416*J10)/10 -> 0 | ... L41: =L21-(3.1416*L10)/10 -> 0
B42: Caja torácica corregida | C42: =C25-(3.1416*C11)/10 -> 0 | D42: =D25-(3.1416*D11)/10 -> 0 | E42: =E25-(3.1416*E11)/10 -> 0 | F42: =F25-(3.1416*F11)/10 -> 0 | G42: =G25-(3.1416*G11)/10 -> 0 | H42: =H25-(3.1416*H11)/10 -> 0 | I42: =I25-(3.1416*I11)/10 -> 0 | J42: =J25-(3.1416*J11)/10 -> 0 | ... L42: =L25-(3.1416*L11)/10 -> 0
B43: Muslo máximo corregido | C43: =C28-(3.1416*C16)/10 -> 0 | D43: =D28-(3.1416*D16)/10 -> 0 | E43: =E28-(3.1416*E16)/10 -> 0 | F43: =F28-(3.1416*F16)/10 -> 0 | G43: =G28-(3.1416*G16)/10 -> 0 | H43: =H28-(3.1416*H16)/10 -> 0 | I43: =I28-(3.1416*I16)/10 -> 0 | J43: =J28-(3.1416*J16)/10 -> 0 | ... L43: =L28-(3.1416*L16)/10 -> 0
B44: Pantorrilla corregida | C44: =C30-(3.1416*C17)/10 -> 0 | D44: =D30-(3.1416*D17)/10 -> 0 | E44: =E30-(3.1416*E17)/10 -> 0 | F44: =F30-(3.1416*F17)/10 -> 0 | G44: =G30-(3.1416*G17)/10 -> 0 | H44: =H30-(3.1416*H17)/10 -> 0 | I44: =I30-(3.1416*I17)/10 -> 0 | J44: =J30-(3.1416*J17)/10 -> 0 | ... L44: =L30-(3.1416*L17)/10 -> 0
...

Sheet ARGO-REF
A1: PESO (kg) | K1: PUNTUACIÓN Z PHANTOM ADIPOSA
A2: Edad | B2: n | C2: Media | D2: Mediana | E2: Desv. Est. | F2: Máximo | G2: Mínimo | H2: IC95%sup | I2: IC95%inf | K2: Edad | L2: n | M2: Media | N2: Mediana | O2: Desv. Est. | P2: Máximo | Q2: Mínimo | R2: IC95%sup | S2: IC95%inf
A3: 7 | B3: 14 | C3: 29.421 | D3: 27.5 | E3: 4.897 | F3: 40 | G3: 23.6 | H3: =C3+(1.96*E3)/(B3)^0.5 -> 31.986205 | I3: =C3-(1.96*E3)/(B3)^0.5 -> 26.855795 | K3: 7 | L3: 14 | M3: -1.086 | N3: -1.5 | O3: 0.921 | P3: 0.7 | Q3: -2.2 | R3: =M3+(1.96*O3)/(L3)^0.5 -> -0.6035507 | S3: =M3-(1.96*O3)/(L3)^0.5 -> -1.5684493
A4: 8 | B4: 39 | C4: 31.313 | D4: 28.6 | E4: 7.714 | F4: 49 | G4: 21 | H4: =C4+(1.96*E4)/(B4)^0.5 -> 33.734048 | I4: =C4-(1.96*E4)/(B4)^0.5 -> 28.891952 | K4: 8 | L4: 39 | M4: -0.541 | N4: -1.2 | O4: 1.544 | P4: 3.1 | Q4: -2.1 | R4: =M4+(1.96*O4)/(L4)^0.5 -> -0.056413776 | S4: =M4-(1.96*O4)/(L4)^0.5 -> -1.0255862
A5: 9 | B5: 57 | C5: 32 | D5: 30 | E5: 7.151 | F5: 62.9 | G5: 20.7 | H5: =C5+(1.96*E5)/(B5)^0.5 -> 33.856459 | I5: =C5-(1.96*E5)/(B5)^0.5 -> 30.143541 | K5: 9 | L5: 57 | M5: -1.065 | N5: -1.5 | O5: 1.172 | P5: 2.8 | Q5: -2.4 | R5: =M5+(1.96*O5)/(L5)^0.5 -> -0.76073902 | S5: =M5-(1.96*O5)/(L5)^0.5 -> -1.369261
A6: 10 | B6: 66 | C6: 35.612 | D6: 32.5 | E6: 8.438 | F6: 61.1 | G6: 22.8 | H6: =C6+(1.96*E6)/(B6)^0.5 -> 37.647746 | I6: =C6-(1.96*E6)/(B6)^0.5 -> 33.576254 | K6: 10 | L6: 66 | M6: -0.617 | N6: -1.05 | O6: 1.535 | P6: 4.6 | Q6: -2.4 | R6: =M6+(1.96*O6)/(L6)^0.5 -> -0.24666694 | S6: =M6-(1.96*O6)/(L6)^0.5 -> -0.98733306
A7: 11 | B7: 55 | C7: 39.996 | D7: 39 | E7: 9.772 | F7: 76 | G7: 24.6 | H7: =C7+(1.96*E7)/(B7)^0.5 -> 42.578606 | I7: =C7-(1.96*E7)/(B7)^0.5 -> 37.413394 | K7: 11 | L7: 55 | M7: -0.76 | N7: -1.4 | O7: 1.59 | P7: 4.4 | Q7: -2.2 | R7: =M7+(1.96*O7)/(L7)^0.5 -> -0.33978471 | S7: =M7-(1.96*O7)/(L7)^0.5 -> -1.1802153
A8: 12 | B8: 35 | C8: 46.289 | D8: 44 | E8: 13.53 | F8: 99.9 | G8: 30.4 | H8: =C8+(1.96*E8)/(B8)^0.5 -> 50.771495 | I8: =C8-(1.96*E8)/(B8)^0.5 -> 41.806505 | K8: 12 | L8: 35 | M8: -0.494 | N8: -0.9 | O8: 1.439 | P8: 4.1 | Q8: -2.3 | R8: =M8+(1.96*O8)/(L8)^0.5 -> -0.017258627 | S8: =M8-(1.96*O8)/(L8)^0.5 -> -0.97074137
A9: 13 | B9: 64 | C9: 51.791 | D9: 51 | E9: 9.914 | F9: 78.9 | G9: 32.4 | H9: =C9+(1.96*E9)/(B9)^0.5 -> 54.21993 | I9: =C9-(1.96*E9)/(B9)^0.5 -> 49.36207 | K9: 13 | L9: 64 | M9: -1.263 | N9: -1.6 | O9: 0.93 | P9: 2.4 | Q9: -2.3 | R9: =M9+(1.96*O9)/(L9)^0.5 -> -1.03515 | S9: =M9-(1.96*O9)/(L9)^0.5 -> -1.49085
A10: 14 | B10: 87 | C10: 58.705 | D10: 57.1 | E10: 14.336 | F10: 132.2 | G10: 34 | H10: =C10+(1.96*E10)/(B10)^0.5 -> 61.717482 | I10: =C10-(1.96*E10)/(B10)^0.5 -> 55.692518 | K10: 14 | L10: 87 | M10: -1.222 | N10: -1.6 | O10: 1.162 | P10: 3.2 | Q10: -2.4 | R10: =M10+(1.96*O10)/(L10)^0.5 -> -0.97782423 | S10: =M10-(1.96*O10)/(L10)^0.5 -> -1.4661758
A11: 15 | B11: 70 | C11: 63.237 | D11: 60.4 | E11: 13.3 | F11: 117.4 | G11: 43.8 | H11: =C11+(1.96*E11)/(B11)^0.5 -> 66.352722 | I11: =C11-(1.96*E11)/(B11)^0.5 -> 60.121278 | K11: 15 | L11: 70 | M11: -1.257 | N11: -1.65 | O11: 1.052 | P11: 2.7 | Q11: -2.5 | R11: =M11+(1.96*O11)/(L11)^0.5 -> -1.0105534 | S11: =M11-(1.96*O11)/(L11)^0.5 -> -1.5034466
A12: 16 | B12: 38 | C12: 66.558 | D12: 62.35 | E12: 17.262 | F12: 133.8 | G12: 46.9 | H12: =C12+(1.96*E12)/(B12)^0.5 -> 72.046522 | I12: =C12-(1.96*E12)/(B12)^0.5 -> 61.069478 | K12: 16 | L12: 38 | M12: -1.132 | N12: -1.6 | O12: 1.307 | P12: 3.9 | Q12: -2.2 | R12: =M12+(1.96*O12)/(L12)^0.5 -> -0.71643414 | S12: =M12-(1.96*O12)/(L12)^0.5 -> -1.5475659
A13: 17 | B13: 30 | C13: 70.98 | D13: 66.75 | E13: 15.423 | F13: 100.3 | G13: 52.4 | H13: =C13+(1.96*E13)/(B13)^0.5 -> 76.49905 | I13: =C13-(1.96*E13)/(B13)^0.5 -> 65.46095 | K13: 17 | L13: 30 | M13: -1.053 | N13: -1.6 | O13: 1.269 | P13: 2.4 | Q13: -2.3 | R13: =M13+(1.96*O13)/(L13)^0.5 -> -0.59889418 | S13: =M13-(1.96*O13)/(L13)^0.5 -> -1.5071058
A14: 18 | B14: 21 | C14: 68.581 | D14: 67.3 | E14: 6.51 | F14: 82.8 | G14: 58 | H14: =C14+(1.96*E14)/(B14)^0.5 -> 71.365373 | I14: =C14-(1.96*E14)/(B14)^0.5 -> 65.796627 | K14: 18 | L14: 21 | M14: -1.51 | N14: -1.7 | O14: 0.731 | P14: 0.4 | Q14: -2.4 | R14: =M14+(1.96*O14)/(L14)^0.5 -> -1.1973461 | S14: =M14-(1.96*O14)/(L14)^0.5 -> -1.8226539
A15: 19 | B15: 7 | C15: 78.243 | D15: 75.7 | E15: 20.635 | F15: 108.3 | G15: 50.4 | H15: =C15+(1.96*E15)/(B15)^0.5 -> 93.529622 | I15: =C15-(1.96*E15)/(B15)^0.5 -> 62.956378 | K15: 19 | L15: 7 | M15: -0.614 | N15: -1.6 | O15: 1.815 | P15: 2.3 | Q15: -2.3 | R15: =M15+(1.96*O15)/(L15)^0.5 -> 0.73057082 | S15: =M15-(1.96*O15)/(L15)^0.5 -> -1.9585708
A18: TALLA (cm) | K18: PUNTUACIÓN Z PHANTOM MUSCULAR
A19: Edad | B19: n | C19: Media | D19: Mediana | E19: Desv. Est. | F19: Máximo | G19: Mínimo | H19: IC95%sup | I19: IC95%inf | K19: Edad | L19: n | M19: Media | N19: Mediana | O19: Desv. Est. | P19: Máximo | Q19: Mínimo | R19: IC95%sup | S19: IC95%inf
A20: 7 | B20: 14 | C20: 130.671 | D20: 131.25 | E20: 3.868 | F20: 136.1 | G20: 124.7 | H20: =C20+(1.96*E20)/(B20)^0.5 -> 132.69718 | I20: =C20-(1.96*E20)/(B20)^0.5 -> 128.64482 | K20: 7 | L20: 14 | M20: -0.243 | N20: -0.3 | O20: 0.697 | P20: 0.9 | Q20: -1.3 | R20: =M20+(1.96*O20)/(L20)^0.5 -> 0.12211093 | S20: =M20-(1.96*O20)/(L20)^0.5 -> -0.60811093
A21: 8 | B21: 39 | C21: 130.044 | D21: 129.9 | E21: 5.271 | F21: 141.2 | G21: 114.5 | H21: =C21+(1.96*E21)/(B21)^0.5 -> 131.69831 | I21: =C21-(1.96*E21)/(B21)^0.5 -> 128.38969 | K21: 8 | L21: 39 | M21: 0.326 | N21: 0 | O21: 1.055 | P21: 3 | Q21: -1.1 | R21: =M21+(1.96*O21)/(L21)^0.5 -> 0.657113 | S21: =M21-(1.96*O21)/(L21)^0.5 -> -0.0051129964
A22: 9 | B22: 57 | C22: 134.733 | D22: 135.7 | E22: 5.623 | F22: 148.1 | G22: 116 | H22: =C22+(1.96*E22)/(B22)^0.5 -> 136.19278 | I22: =C22-(1.96*E22)/(B22)^0.5 -> 133.27322 | K22: 9 | L22: 57 | M22: -0.007018 | N22: 0.1 | O22: 0.827 | P22: 2 | Q22: -1.7 | R22: =M22+(1.96*O22)/(L22)^0.5 -> 0.2076781 | S22: =M22-(1.96*O22)/(L22)^0.5 -> -0.2217141
A23: 10 | B23: 66 | C23: 138.265 | D23: 137.5 | E23: 6.251 | F23: 153.3 | G23: 125.4 | H23: =C23+(1.96*E23)/(B23)^0.5 -> 139.77311 | I23: =C23-(1.96*E23)/(B23)^0.5 -> 136.75689 | K23: 10 | L23: 66 | M23: 0.02727 | N23: 0 | O23: 0.926 | P23: 2.9 | Q23: -1.5 | R23: =M23+(1.96*O23)/(L23)^0.5 -> 0.25067613 | S23: =M23-(1.96*O23)/(L23)^0.5 -> -0.19613613
A24: 11 | B24: 55 | C24: 144.916 | D24: 145.6 | E24: 7.331 | F24: 161.4 | G24: 131.2 | H24: =C24+(1.96*E24)/(B24)^0.5 -> 146.85348 | I24: =C24-(1.96*E24)/(B24)^0.5 -> 142.97852 | K24: 11 | L24: 55 | M24: -0.01091 | N24: 0 | O24: 1.015 | P24: 2.2 | Q24: -2.2 | R24: =M24+(1.96*O24)/(L24)^0.5 -> 0.25734064 | S24: =M24-(1.96*O24)/(L24)^0.5 -> -0.27916064
A25: 12 | B25: 35 | C25: 151.42 | D25: 150.7 | E25: 7.245 | F25: 165.8 | G25: 140.5 | H25: =C25+(1.96*E25)/(B25)^0.5 -> 153.82027 | I25: =C25-(1.96*E25)/(B25)^0.5 -> 149.01973 | K25: 12 | L25: 35 | M25: 0.12 | N25: -0.1 | O25: 1.138 | P25: 4.1 | Q25: -1.4 | R25: =M25+(1.96*O25)/(L25)^0.5 -> 0.49701993 | S25: =M25-(1.96*O25)/(L25)^0.5 -> -0.25701993
A26: 13 | B26: 64 | C26: 161.167 | D26: 161.75 | E26: 8.103 | F26: 177.5 | G26: 142.4 | H26: =C26+(1.96*E26)/(B26)^0.5 -> 163.15223 | I26: =C26-(1.96*E26)/(B26)^0.5 -> 159.18177 | K26: 13 | L26: 64 | M26: -0.003125 | N26: -0.1 | O26: 0.874 | P26: 3 | Q26: -2 | R26: =M26+(1.96*O26)/(L26)^0.5 -> 0.211005 | S26: =M26-(1.96*O26)/(L26)^0.5 -> -0.217255
A27: 14 | B27: 87 | C27: 165.598 | D27: 165.3 | E27: 7.979 | F27: 182.6 | G27: 144.4 | H27: =C27+(1.96*E27)/(B27)^0.5 -> 167.27466 | I27: =C27-(1.96*E27)/(B27)^0.5 -> 163.92134 | K27: 14 | L27: 87 | M27: 0.362 | N27: 0.1 | O27: 1.12 | P27: 4 | Q27: -2.2 | R27: =M27+(1.96*O27)/(L27)^0.5 -> 0.59735014 | S27: =M27-(1.96*O27)/(L27)^0.5 -> 0.12664986
A28: 15 | B28: 70 | C28: 169.761 | D28: 169.2 | E28: 6.317 | F28: 184.7 | G28: 157.9 | H28: =C28+(1.96*E28)/(B28)^0.5 -> 171.24085 | I28: =C28-(1.96*E28)/(B28)^0.5 -> 168.28115 | K28: 15 | L28: 70 | M28: 0.447 | N28: 0.3 | O28: 0.944 | P28: 2.8 | Q28: -1.5 | R28: =M28+(1.96*O28)/(L28)^0.5 -> 0.66814598 | S28: =M28-(1.96*O28)/(L28)^0.5 -> 0.22585402
A29: 16 | B29: 38 | C29: 169.916 | D29: 170 | E29: 5.023 | F29: 184.1 | G29: 159.7 | H29: =C29+(1.96*E29)/(B29)^0.5 -> 171.51308 | I29: =C29-(1.96*E29)/(B29)^0.5 -> 168.31892 | K29: 16 | L29: 38 | M29: 0.871 | N29: 0.45 | O29: 1.268 | P29: 5.2 | Q29: -0.7 | R29: =M29+(1.96*O29)/(L29)^0.5 -> 1.2741657 | S29: =M29-(1.96*O29)/(L29)^0.5 -> 0.46783435
A30: 17 | B30: 30 | C30: 171.887 | D30: 171.15 | E30: 6.468 | F30: 185.9 | G30: 160.9 | H30: =C30+(1.96*E30)/(B30)^0.5 -> 174.20154 | I30: =C30-(1.96*E30)/(B30)^0.5 -> 169.57246 | K30: 17 | L30: 30 | M30: 1.147 | N30: 0.9 | O30: 1.267 | P30: 4.1 | Q30: -1.1 | R30: =M30+(1.96*O30)/(L30)^0.5 -> 1.6003901 | S30: =M30-(1.96*O30)/(L30)^0.5 -> 0.69360987
A31: 18 | B31: 21 | C31: 173.943 | D31: 174.4 | E31: 5.623 | F31: 187.9 | G31: 161.6 | H31: =C31+(1.96*E31)/(B31)^0.5 -> 176.348 | I31: =C31-(1.96*E31)/(B31)^0.5 -> 171.538 | K31: 18 | L31: 21 | M31: 1.043 | N31: 0.9 | O31: 1.121 | P31: 3.3 | Q31: -1.1 | R31: =M31+(1.96*O31)/(L31)^0.5 -> 1.5224596 | S31: =M31-(1.96*O31)/(L31)^0.5 -> 0.56354038
A32: 19 | B32: 7 | C32: 171.943 | D32: 172.9 | E32: 5.977 | F32: 182.5 | G32: 163 | H32: =C32+(1.96*E32)/(B32)^0.5 -> 176.37082 | I32: =C32-(1.96*E32)/(B32)^0.5 -> 167.51518 | K32: 19 | L32: 7 | M32: 1.9 | N32: 1.3 | O32: 1.768 | P32: 5 | Q32: 0 | R32: =M32+(1.96*O32)/(L32)^0.5 -> 3.2097527 | S32: =M32-(1.96*O32)/(L32)^0.5 -> 0.59024727
A35: TALLA SENTADO (cm) | K35: PUNTUACIÓN Z PHANTOM RESIDUAL
A36: Edad | B36: n | C36: Media | D36: Mediana | E36: Desv. Est. | F36: Máximo | G36: Mínimo | H36: IC95%sup | I36: IC95%inf | K36: Edad | L36: n | M36: Media | N36: Mediana | O36: Desv. Est. | P36: Máximo | Q36: Mínimo | R36: IC95%sup | S36: IC95%inf
A37: 7 | B37: 14 | C37: 69.729 | D37: 69.2 | E37: 3.05 | F37: 75.5 | G37: 64.2 | H37: =C37+(1.96*E37)/(B37)^0.5 -> 71.326688 | I37: =C37-(1.96*E37)/(B37)^0.5 -> 68.131312 | K37: 7 | L37: 14 | M37: 0.821 | N37: 0.8 | O37: 0.625 | P37: 2.3 | Q37: 0 | R37: =M37+(1.96*O37)/(L37)^0.5 -> 1.148395 | S37: =M37-(1.96*O37)/(L37)^0.5 -> 0.49360498
A38: 8 | B38: 39 | C38: 70.61 | D38: 70.1 | E38: 3.036 | F38: 76.9 | G38: 64.4 | H38: =C38+(1.96*E38)/(B38)^0.5 -> 71.562852 | I38: =C38-(1.96*E38)/(B38)^0.5 -> 69.657148 | K38: 8 | L38: 39 | M38: 0.995 | N38: 0.7 | O38: 1.075 | P38: 4.5 | Q38: -0.3 | R38: =M38+(1.96*O38)/(L38)^0.5 -> 1.33239 | S38: =M38-(1.96*O38)/(L38)^0.5 -> 0.65760998
A39: 9 | B39: 57 | C39: 71.993 | D39: 71.7 | E39: 2.852 | F39: 81.3 | G39: 65.5 | H39: =C39+(1.96*E39)/(B39)^0.5 -> 72.733403 | I39: =C39-(1.96*E39)/(B39)^0.5 -> 71.252597 | K39: 9 | L39: 57 | M39: 0.74 | N39: 0.7 | O39: 0.935 | P39: 4.3 | Q39: -0.9 | R39: =M39+(1.96*O39)/(L39)^0.5 -> 0.9827338 | S39: =M39-(1.96*O39)/(L39)^0.5 -> 0.4972662
A40: 10 | B40: 66 | C40: 73.539 | D40: 73.35 | E40: 3.285 | F40: 80.7 | G40: 67.5 | H40: =C40+(1.96*E40)/(B40)^0.5 -> 74.331537 | I40: =C40-(1.96*E40)/(B40)^0.5 -> 72.746463 | K40: 10 | L40: 66 | M40: 0.855 | N40: 0.8 | O40: 1.032 | P40: 4 | Q40: -0.9 | R40: =M40+(1.96*O40)/(L40)^0.5 -> 1.1039796 | S40: =M40-(1.96*O40)/(L40)^0.5 -> 0.60602038
A41: 11 | B41: 55 | C41: 76.489 | D41: 76.6 | E41: 4.468 | F41: 89 | G41: 67 | H41: =C41+(1.96*E41)/(B41)^0.5 -> 77.669831 | I41: =C41-(1.96*E41)/(B41)^0.5 -> 75.308169 | K41: 11 | L41: 55 | M41: 0.836 | N41: 0.8 | O41: 1.062 | P41: 5.2 | Q41: -1.2 | R41: =M41+(1.96*O41)/(L41)^0.5 -> 1.1166721 | S41: =M41-(1.96*O41)/(L41)^0.5 -> 0.5553279
A42: 12 | B42: 35 | C42: 79.486 | D42: 78.8 | E42: 4.003 | F42: 89.5 | G42: 73 | H42: =C42+(1.96*E42)/(B42)^0.5 -> 80.812196 | I42: =C42-(1.96*E42)/(B42)^0.5 -> 78.159804 | K42: 12 | L42: 35 | M42: 0.546 | N42: 0.4 | O42: 1.043 | P42: 4.1 | Q42: -1.4 | R42: =M42+(1.96*O42)/(L42)^0.5 -> 0.89154639 | S42: =M42-(1.96*O42)/(L42)^0.5 -> 0.20045361
A43: 13 | B43: 64 | C43: 84.125 | D43: 84.2 | E43: 4.8 | F43: 96.9 | G43: 74 | H43: =C43+(1.96*E43)/(B43)^0.5 -> 85.301 | I43: =C43-(1.96*E43)/(B43)^0.5 -> 82.949 | K43: 13 | L43: 64 | M43: 0.481 | N43: 0.3 | O43: 0.857 | P43: 3.1 | Q43: -1.3 | R43: =M43+(1.96*O43)/(L43)^0.5 -> 0.690965 | S43: =M43-(1.96*O43)/(L43)^0.5 -> 0.271035
A44: 14 | B44: 87 | C44: 87.043 | D44: 87.5 | E44: 4.771 | F44: 97.1 | G44: 72.5 | H44: =C44+(1.96*E44)/(B44)^0.5 -> 88.04555 | I44: =C44-(1.96*E44)/(B44)^0.5 -> 86.04045 | K44: 14 | L44: 87 | M44: 0.734 | N44: 0.7 | O44: 1.083 | P44: 5.1 | Q44: -1.9 | R44: =M44+(1.96*O44)/(L44)^0.5 -> 0.96157518 | S44: =M44-(1.96*O44)/(L44)^0.5 -> 0.50642482
...

Sheet Predicción de Talla
A1: Predicción de la Talla Adulta utilizando la Madurez a través de las Curvas de Velocidad de Talla Acumulativas
A2: Autores: Lauren B. Sherar, Robert L. Mirwald, Adam D. G. Baxter-Jones y Martine Thoms
A4: Pasos a seguir para realizar el cálculo de la Predicción de la Talla Adulta:
A6: 1) Se deben tener los siguientes datos del niño o adolescente a evaluar:
A7: Ejemplo: | B7: Edad Decimal | C7: =HISTORIA!C7 -> 23.673973
B8: Talla Actual (Cm) | C8: ='ANTROPOMETRÍA DEPORTISTAS'!C9 -> 0
B9: Peso Actual (Kg) | C9: ='ANTROPOMETRÍA DEPORTISTAS'!C7 -> 0
B10: Longitud de la Pierna | C10: =C8-C11 -> #REF! | E10: Recuerdes restarle a la talla sentado el tamaño del Vanco si usaron uno.
B11: Talla Sentada | C11: ='ANTROPOMETRÍA DEPORTISTAS'!#REF! -> #REF!
B12: Interacción entre la Longitud de la Pierna y la Talla Sentada (Multiplicación de ambos valores) | C12: =(C10*C11) -> #REF!
B13: Interacción entre la Edad y la Longitud de la Pierna (Multiplicación de ambos valores) | C13: =(C7*C10) -> #REF!
B14: Interacción entre la Edad y la Talla Sentada (Multiplicación de ambos valores) | C14: =(C7*C11) -> #REF!
B15: Proporción entre la Talla y el Peso | C15: =(C9/C8)*100 -> #DIV/0!
A18: 2) Se debe calcular la Compensación de la Madurez (Maturity Offset) a través de la siguiente fórmula:
B20: Compensación de la Madurez: (Años para alcanzar el Pico de Velocidad de Crecimiento (PHV)) | C20: =-9.236+(0.0002708*C12)+(-0.001663*C13)+(0.007216*C14)+(0.02292*C15) -> #REF! | E20: Este numero ubicalo en la Tabla 2 según el estado de maduracion del chico
A22: 3) Seguidamente, se calcula la edad que el niño o adolescente tendrá cuando llegue al Pico de velocidad de Crecimiento.
B23: Edad en el PHV: | C23: =C7-(C20) -> #REF! | E23: Esto indica la edad a la que se dara ( o dío) el mayor crecimiento
B25: Importante: | D25: Masculino | E25: Femenino
C26: Madurador Promedio | D26: 13 a 15 | E26: 11 a 13
C27: Madurador Temprano | D27: <13 | E27: <11
C28: Madurador Tardío | D28: >15 | E28: >13
A29: 4) Finalmente, se obtiene la Talla Adulta Prevista. (Ver Tabla 1)
B30: Predicción de la Talla Adulta: | C30: 19.88 | E30: Aquí colocas el valor que te da la tabla 2 al hacer el paso 2
C31: =C8+C30 -> 19.88 | E31: ESTA ES LA PROYECCION DE TALLA . TOMA EN CUENTA EL LIMITE INFERIOR Y SUPERIOR.
B32: This method can predict adult height within ±5.35 cm 95% of the time in boys and ±6.81 cm 95% of the time in girls.

Sheet PHV
A1: Tabla 1: Distancia (cm) restante para el crecimiento en maduradores tempranos, promedio y tardíos en hombres y mujeres en diferentes edades biológicas (años para alcanzar el Pico de Velocidad de Crecimiento (PHV)).
C3: Crecimiento en Cm que Faltaría Antes de que la Estatura Adulta sea Alcanzada
C4: Masculino | F4: Femenino
B5: Años para alcanzar el PHV | C5: Temprano | D5: Promedio | E5: Tardío | F5: Temprano | G5: Promedio | H5: Tardío
B6: -4 | C6: 45.29 | D6: 40.09 | E6: 34.73 | F6: 42.61 | G6: 38.81 | H6: 34.35
B7: -3.8 | C7: 44.21 | D7: 39.08 | E7: 33.83 | F7: 41.49 | G7: 37.67 | H7: 33.27
B8: -3.6 | C8: 43.11 | D8: 38.07 | E8: 32.94 | F8: 40.39 | G8: 36.55 | H8: 32.2
B9: -3.4 | C9: 41.99 | D9: 37.06 | E9: 32.05 | F9: 39.3 | G9: 35.44 | H9: 31.14
B10: -3.2 | C10: 40.85 | D10: 36.05 | E10: 31.16 | F10: 38.21 | G10: 34.34 | H10: 30.09
B11: -3 | C11: 39.69 | D11: 35.04 | E11: 30.27 | F11: 37.13 | G11: 33.25 | H11: 29.04
B12: -2.8 | C12: 38.52 | D12: 34.04 | E12: 29.38 | F12: 36.04 | G12: 32.16 | H12: 27.99
B13: -2.6 | C13: 37.33 | D13: 33.05 | E13: 28.49 | F13: 34.94 | G13: 31.04 | H13: 26.93
B14: -2.4 | C14: 36.15 | D14: 32.06 | E14: 27.6 | F14: 33.82 | G14: 29.91 | H14: 25.87
B15: -2.2 | C15: 34.97 | D15: 31.07 | E15: 26.7 | F15: 32.68 | G15: 28.76 | H15: 24.79
B16: -2 | C16: 33.8 | D16: 30.06 | E16: 25.77 | F16: 31.53 | G16: 27.58 | H16: 23.71
B17: -1.8 | C17: 32.62 | D17: 29.03 | E17: 24.79 | F17: 30.44 | G17: 26.39 | H17: 22.63
... B46: 4 | C46: 0 | D46: 0 | E46: 0 | F46: 0 | G46: 0 | H46: 0

Sheet REQUERIMIENTOS
A1: REQUERIMIENTOS Y LISTA DE INTERCAMBIO
A3: Peso actual | B3: ='ANTROPOMETRÍA DEPORTISTAS'!B7 -> 90.05 | C3: Peso usual | D3: ='ANTROPOMETRÍA DEPORTISTAS'!B6 -> 45994 | E3: Peso mínimo | G3: Peso máximo | H3: ='ANTROPOMETRÍA DEPORTISTAS'!B7 -> 90.05 | I3: Peso a utilizar | J3: =B3 -> 90.05 | O3: LBM | P3: LBM
A4: Talla | B4: ='ANTROPOMETRÍA DEPORTISTAS'!B9 -> 186 | I4: Peso Magro | J4: ='ANTROPOMETRÍA DEPORTISTAS'!C58 -> 0 | K4: % de cambio de peso
K5: Tiempo | L5: Significativo | M5: Severo
A6: PESO TEÓRICO | E6: PESO TEÓRICO | I6: Porcentaje de cambio de peso | K6: 1 semana | L6: 1 – 2 % | M6: > 2 %
A7: WEST | C7: Derivada del IMC | E7: Hamwi | I7: =((D3-B3)/D3)*100 -> 99.804214 | K7: 1 mes | L7: 3 – 5 % | M7: > 5 %
A8: Hombres | B8: =22.1*(POWER(B4/100,2)) -> 76.45716 | C8: Hombres | D8: =23*(POWER(B3/100,2)) -> 18.650706 | E8: Hombres | F8: =(B4-152)*1.08+48.5 -> 85.22 | G8: Hombres | H8: =23*(POWER(F4/100,2)) -> 0 | I8: Peso ajustado (Obesidad) | K8: 3 meses | L8: 6 – 8 % | M8: > 8 %
A9: Mujeres | B9: =20.6*(POWER(B4/100,2)) -> 71.26776 | C9: Mujeres | D9: =21.5*(POWER(B3/100,2)) -> 17.434355 | E9: Mujeres | F9: =(B4-152)*0.88+45.5 -> 75.42 | G9: Mujeres | H9: =21.5*(POWER(F4/100,2)) -> 0 | I9: =(B3-F8)*0.25+F8 -> 86.4275 | K9: 6 meses | L9: 9 – 10% | M9: > 10 %
A12: METODO TRADICIONAL | E12: MÉTODO DIRECTO | J12: HARRIS Y BENEDICT | N12: HARRIS Y BENEDICT (ROZA) | S12: CUNNINGHAM (1980) | X12: 1.2 - Sedentary:
A13: Peso Utilizar | C13: =J3 -> 90.05 | E13: Hipocalórica | G13: =(J3*F13) -> 0 | H13: < 25 kcal/kg Peso | J13: RCB (Masculino) | L13: =(66.47+(13.75*J3)+(5*B4)-(6.75*HISTORIA!C7)) -> 2074.8582 | N13: RCB (Masculino) | P13: =88.362+(13.397*J3)+(4.799*B4)-(5.677*HISTORIA!C7) -> 2052.9787 | S13: RCB (Masculino) | U13: =(500+(22*O4)) -> 500 | X13: You work a desk job and don’t exercise
A14: RCB (Masculino) | C14: =(J3*24*1) -> 2161.2 | E14: Normocalórica | G14: =F14*J3 -> 0 | H14: 25-30 kcal/kg Peso | J14: RCB (Femenino) | L14: =(655.1+(9.56*J3)+(1.85*B4)-(4.7*HISTORIA!C7)) -> 1748.8103 | N14: RCB (Femenino) | P14: =447.593+(9.247*J3)+(3.098*B4)-(4.33*HISTORIA!C7) -> 1754.005 | S14: RCB (Femenino) | U14: =(500+(22*P4)) -> 500 | X14: 1.375 - Light Activity:
A15: RCB (Femenino) | C15: =(J3*24*0.98) -> 2117.976 | E15: Hipercalórica | G15: =F15*J3 -> 0 | H15: > 30 kcal/kg Peso | J15: Factor de Actividad | L15: 1.725 | N15: Factor de Actividad | P15: =L15 -> 1.725 | S15: Factor de Actividad | U15: =Q15 -> 0 | X15: You work a desk job but do a bit of regular exercise. Or you don’t exercise but you work at a
A16: ETA (Masculino) | C16: =C14/10 -> 216.12 | J16: Factor de estrés | L16: 1 | N16: RCT (Masculino) | P16: =P13*P15 -> 3541.3883 | S16: RCT (Masculino) | U16: =U13*U15 -> 0 | X16: job that’s pretty active (a nurse, teacher, etc.) where you’re on your for feet most of the day.
A17: ETA (Femenino) | C17: =(C15)/10 -> 211.7976 | E17: MÉTODO HOLLIDAY | J17: RCT (Masculino) | L17: =L13*L15*L16 -> 3579.1304 | N17: RCT (Femenino) | P17: =P14*P15 -> 3025.6587 | S17: RCT (Femenino) | U17: =U14*U15 -> 0 | X17: 1.55 - Moderate Activity:
A18: Actividad Física | C18: 1.5 | E18: 0-10 Kg | F18: 100 Kcal/Kg/día | J18: RCT (Femenino) | L18: =L14*L15*L16 -> 3016.6978 | X18: Most of you will probably fall into this category. Maybe you work a sedentary job, but you
A19: RCT (Masculino) | C19: =(C14*C18)+C16 -> 3457.92 | E19: 10,1-20 Kg | F19: 1000 Kcal + 50 Kcal por cada Kg por encima | X19: train like a madman. Or maybe you train moderately, but you also have a job where you
A20: RCT (Femenino) | C20: =(C15*C18)+C17 -> 3388.7616 | E20: >20 Kg | F20: 1000 Kcal + 20 Kcal por cada Kg por encima de 20 Kg | J20: FACTOR DE ACTIVIDAD FÍSICA | N20: MULLER EQUATION | S20: MIFFLIN - ST.JEOR | X20: stand on your feet all the time. Someone who doesn’t train but works a hard labor job
E21: RCB: | H21: =(J3-20) *20 + 1000 -> 2401 | J21: Sedentary | L21: 1.2 | N21: RCB (Masculino) | P21: =((13.587*'ANTROPOMETRÍA DEPORTISTAS'!B58)+(9.613*'ANTROPOMETRÍA DEPORTISTAS'!B59)+(198*1)-(3.351*HISTORIA!C7)+674) -> 1977.7787 | S21: RCB (Masculino) | U21: =(9.99*J3)+(6.25*B4)-(4.92*HISTORIA!C7)+5 -> 1950.6236 | X21: would also fall into this category.
E22: ENERGÍA DE ACTIVIDAD: | H22: =HISTORIA!K41 -> 0 | J22: Light Activity | L22: 1375 | N22: RCB (Femenino) | P22: =((13.587*'ANTROPOMETRÍA DEPORTISTAS'!B58)+(9.613*'ANTROPOMETRÍA DEPORTISTAS'!B59)+(198*0)-(3.351*HISTORIA!C7)+674) -> 1779.7787 | S22: RCB (Femenino) | U22: =(9.99*J3)+(6.25*B4)-(4.92*HISTORIA!C7)-161 -> 1784.6236 | X22: 1.725 - Very Active:
A23: ACTIVIDAD FÍSICA (AF) | E23: ETA: 10% | G23: =SUM(H21:H22) -> 2401 | H23: =G23*0.1 -> 240.1 | J23: Moderate Activity | L23: 1.55 | N23: Factor de Actividad | P23: =L15 -> 1.725 | S23: Factor de Actividad | U23: 1.375 | X23: You train hard most days of the week, and you also work a job where you’re on your feet
A24: Sedentario | C24: 1 | E24: REQUERIMIENTO CALÓRICO TOTAL | H24: =G23+H23 -> 2641.1 | J24: Very Active | L24: 1.725 | N24: RCT (Masculino) | P24: =P21*P23 -> 3411.6683 | S24: RCT (Masculino) | U24: =U21*U23 -> 2682.1074 | X24: quite a bit. Overall, you’re active most of the day.
A25: Muy Leve | C25: 1.25 | J25: Extra Active | L25: 1.9 | N25: RCT (Femenino) | P25: =P22*P23 -> 3070.1183 | S25: RCT (Femenino) | U25: =U22*U23 -> 2453.8574 | X25: 1.9 - Extra Active:
A26: Leve | C26: 1.5 | X26: You train hard and work a job that is physically intense in nature. As an example, you’re a
A27: Moderada | C27: 1.75 | X27: roofer who also goes to the gym five days a week.
A28: Intensa | C28: 2 | T28: Restricción | V28: Valor (Kcal)
T29: 0.1 | V29: =0.1*P24 -> 341.16683
G30: FORMÚLA DIETÉTICA | M30: Suplementos | T30: 0.12 | V30: 0.12
I31: RCT a Utilizar | J31: =U24-100 -> 2582.1074 | T31: 0.15 | V31: 0.15
G32: MACROS | I32: % | J32: kcal | K32: g | L32: g/kg Peso | M32: Aporte de Macros | T32: 0.2 | V32: 0.2
G33: Proteínas | I33: 29 | J33: =(I33/100)*J31 -> 748.81114 | K33: =J33/4 -> 187.20279 | L33: =(K33+M33)/J3 -> 2.078876 | T33: 0.25 | V33: 0.25
G34: Grasas | I34: 42 | J34: =(I34*J31)/100 -> 1084.4851 | K34: =J34/9 -> 120.49834 | L34: =K34/J3 -> 1.3381271 | T34: 0.3 | V34: 0.3
G35: CHO complejos | I35: =100-I33-I34 -> 29 | J35: =(I35*J31)/100 -> 748.81114 | K35: =J35/4 -> 187.20279 | L35: =K35/J3 -> 2.078876
G36: Colesterol
G37: Fibra | I37: =(L37*J31)/1000 -> 0 | M37: =SUM(J33:J35) -> 2582.1074
G38: Sodio
G39: Agua | I39: =L39*C13 -> 3151.75 | L39: 35
C41: Intervalos de edad.
A42: Rangos óptimos de proteína: | C42: 0-30 | D42: 31-40 | E42: 41-50 | F42: 51-60 | G42: 61-70
A43: No caloric Deficit | C43: 1,8-2,0 | D43: 2,0-2,3 | E43: 2,3-2,6 | F43: 2,6-2,9 | G43: 2,9-3,2 | H43: Kg de masa magra
A44: Deficit Calorico | C44: 2,2-2,4 | D44: 2,4-2,8 | E44: 2,8-3,1 | F44: 3,1-3,5 | G44: 3,5-3,8 | H44: Kg de masa magra
...

Sheet RESUMEN ANTROPOMETRICO
D1: RESUMEN DE INDICADORES ANTROPOMETRICOS
D4: Evaluación | F4: 1 | G4: 2 | H4: 3 | I4: 4 | J4: 5 | K4: 6 | L4: 7 | M4: 8 | N4: 9 | O4: 10
D5: Fecha | F5: ='ANTROPOMETRÍA DEPORTISTAS'!B6 -> 45994 | G5: ='ANTROPOMETRÍA DEPORTISTAS'!C6 -> 0 | H5: ='ANTROPOMETRÍA DEPORTISTAS'!D6 -> 0 | I5: ='ANTROPOMETRÍA DEPORTISTAS'!E6 -> 0 | J5: ='ANTROPOMETRÍA DEPORTISTAS'!F6 -> 0 | K5: ='ANTROPOMETRÍA DEPORTISTAS'!G6 -> 0 | L5: ='ANTROPOMETRÍA DEPORTISTAS'!H6 -> 0 | M5: ='ANTROPOMETRÍA DEPORTISTAS'!I6 -> 0 | ... O5: ='ANTROPOMETRÍA DEPORTISTAS'!K6 -> 0
D6: Peso (Kg) | F6: ='ANTROPOMETRÍA DEPORTISTAS'!B7 -> 90.05 | G6: ='ANTROPOMETRÍA DEPORTISTAS'!C7 -> 0 | H6: ='ANTROPOMETRÍA DEPORTISTAS'!D7 -> 0 | I6: ='ANTROPOMETRÍA DEPORTISTAS'!E7 -> 0 | J6: ='ANTROPOMETRÍA DEPORTISTAS'!F7 -> 0 | K6: ='ANTROPOMETRÍA DEPORTISTAS'!G7 -> 0 | L6: ='ANTROPOMETRÍA DEPORTISTAS'!H7 -> 0 | M6: ='ANTROPOMETRÍA DEPORTISTAS'!I7 -> 0 | ... O6: ='ANTROPOMETRÍA DEPORTISTAS'!K7 -> 0
D7: Talla parada (cm) | F7: ='ANTROPOMETRÍA DEPORTISTAS'!B9 -> 186 | G7: ='ANTROPOMETRÍA DEPORTISTAS'!C9 -> 0 | H7: ='ANTROPOMETRÍA DEPORTISTAS'!D9 -> 0 | I7: ='ANTROPOMETRÍA DEPORTISTAS'!E9 -> 0 | J7: ='ANTROPOMETRÍA DEPORTISTAS'!F9 -> 0 | K7: ='ANTROPOMETRÍA DEPORTISTAS'!G9 -> 0 | L7: ='ANTROPOMETRÍA DEPORTISTAS'!H9 -> 0 | M7: ='ANTROPOMETRÍA DEPORTISTAS'!I9 -> 0 | ... O7: ='ANTROPOMETRÍA DEPORTISTAS'!K9 -> 0
D8: ='ANTROPOMETRÍA DEPORTISTAS'!A52 -> % Grasa (Carter 1986) | F8: ='ANTROPOMETRÍA DEPORTISTAS'!B52 -> 10.73025 | G8: ='ANTROPOMETRÍA DEPORTISTAS'!C52 -> 2.585 | H8: ='ANTROPOMETRÍA DEPORTISTAS'!D52 -> 2.585 | I8: ='ANTROPOMETRÍA DEPORTISTAS'!E52 -> 2.585 | J8: ='ANTROPOMETRÍA DEPORTISTAS'!F52 -> 2.585 | K8: ='ANTROPOMETRÍA DEPORTISTAS'!G52 -> 2.585 | L8: ='ANTROPOMETRÍA DEPORTISTAS'!H52 -> 2.585 | M8: ='ANTROPOMETRÍA DEPORTISTAS'!I52 -> 2.585 | ... O8: ='ANTROPOMETRÍA DEPORTISTAS'!K52 -> 2.585
D9: ='ANTROPOMETRÍA DEPORTISTAS'!A53 -> % Grasa (Durnin y W. 1974) | F9: ='ANTROPOMETRÍA DEPORTISTAS'!B53 -> 15.230089 | G9: ='ANTROPOMETRÍA DEPORTISTAS'!C53 -> #NUM! | H9: ='ANTROPOMETRÍA DEPORTISTAS'!D53 -> #NUM! | I9: ='ANTROPOMETRÍA DEPORTISTAS'!E53 -> #NUM! | J9: ='ANTROPOMETRÍA DEPORTISTAS'!F53 -> #N/A | K9: ='ANTROPOMETRÍA DEPORTISTAS'!G53 -> -2.18 | L9: ='ANTROPOMETRÍA DEPORTISTAS'!H53 -> -2.18 | M9: ='ANTROPOMETRÍA DEPORTISTAS'!I53 -> -2.18 | ... O9: ='ANTROPOMETRÍA DEPORTISTAS'!K53 -> -2.18
D10: Interpretación | F10: =IF('ANTROPOMETRÍA DEPORTISTAS'!B53<10, "Atleta", IF('ANTROPOMETRÍA DEPORTISTAS'!B53<=20, "Saludable", IF('ANTROPOMETRÍA DEPORTISTAS'!B53<=25, "Sobrepeso", "Obesidad"))) -> Saludable | G10: =IF('ANTROPOMETRÍA DEPORTISTAS'!C53<10, "Atleta", IF('ANTROPOMETRÍA DEPORTISTAS'!C53<=20, "Saludable", IF('ANTROPOMETRÍA DEPORTISTAS'!C53<=25, "Sobrepeso", "Obesidad"))) -> #NUM!
D11: Kg de Masa Magra | F11: ='ANTROPOMETRÍA DEPORTISTAS'!B58 -> 80.38741 | G11: ='ANTROPOMETRÍA DEPORTISTAS'!C58 -> 0 | H11: ='ANTROPOMETRÍA DEPORTISTAS'!D58 -> 0 | I11: ='ANTROPOMETRÍA DEPORTISTAS'!E58 -> 0 | J11: ='ANTROPOMETRÍA DEPORTISTAS'!F58 -> 0 | K11: ='ANTROPOMETRÍA DEPORTISTAS'!G58 -> 0 | L11: ='ANTROPOMETRÍA DEPORTISTAS'!H58 -> 0 | M11: ='ANTROPOMETRÍA DEPORTISTAS'!I58 -> 0 | ... O11: ='ANTROPOMETRÍA DEPORTISTAS'!K58 -> 0
D12: Kg de Grasa | F12: ='ANTROPOMETRÍA DEPORTISTAS'!B59 -> 9.6625901 | G12: ='ANTROPOMETRÍA DEPORTISTAS'!C59 -> 0 | H12: ='ANTROPOMETRÍA DEPORTISTAS'!D59 -> 0 | I12: ='ANTROPOMETRÍA DEPORTISTAS'!E59 -> 0 | J12: ='ANTROPOMETRÍA DEPORTISTAS'!F59 -> 0 | K12: ='ANTROPOMETRÍA DEPORTISTAS'!G59 -> 0 | L12: ='ANTROPOMETRÍA DEPORTISTAS'!H59 -> 0 | M12: ='ANTROPOMETRÍA DEPORTISTAS'!I59 -> 0 | ... O12: ='ANTROPOMETRÍA DEPORTISTAS'!K59 -> 0
D13: Masa Muscular (Kg) | F13: ='ANTROPOMETRÍA DEPORTISTAS'!B64 -> 51.016377 | G13: ='ANTROPOMETRÍA DEPORTISTAS'!C64 -> #DIV/0! | H13: ='ANTROPOMETRÍA DEPORTISTAS'!D64 -> #DIV/0! | I13: ='ANTROPOMETRÍA DEPORTISTAS'!E64 -> #DIV/0! | J13: ='ANTROPOMETRÍA DEPORTISTAS'!F64 -> #DIV/0! | K13: ='ANTROPOMETRÍA DEPORTISTAS'!G64 -> #DIV/0! | L13: ='ANTROPOMETRÍA DEPORTISTAS'!H64 -> #DIV/0! | M13: ='ANTROPOMETRÍA DEPORTISTAS'!I64 -> #DIV/0! | ... O13: ='ANTROPOMETRÍA DEPORTISTAS'!K64 -> #DIV/0!
D14: Masa Adiposa (Kg) | F14: ='ANTROPOMETRÍA DEPORTISTAS'!B63 -> 23.434141 | G14: ='ANTROPOMETRÍA DEPORTISTAS'!C63 -> #DIV/0! | H14: ='ANTROPOMETRÍA DEPORTISTAS'!D63 -> #DIV/0! | I14: ='ANTROPOMETRÍA DEPORTISTAS'!E63 -> #DIV/0! | J14: ='ANTROPOMETRÍA DEPORTISTAS'!F63 -> #DIV/0! | K14: ='ANTROPOMETRÍA DEPORTISTAS'!G63 -> #DIV/0! | L14: ='ANTROPOMETRÍA DEPORTISTAS'!H63 -> #DIV/0! | M14: ='ANTROPOMETRÍA DEPORTISTAS'!I63 -> #DIV/0! | ... O14: ='ANTROPOMETRÍA DEPORTISTAS'!K63 -> #DIV/0!
D15: Sumatoria de 6 pliegues | F15: ='ANTROPOMETRÍA DEPORTISTAS'!B54 -> 77.5 | G15: ='ANTROPOMETRÍA DEPORTISTAS'!C54 -> 0 | H15: ='ANTROPOMETRÍA DEPORTISTAS'!D54 -> 0 | I15: ='ANTROPOMETRÍA DEPORTISTAS'!E54 -> 0 | J15: ='ANTROPOMETRÍA DEPORTISTAS'!F54 -> 0 | K15: ='ANTROPOMETRÍA DEPORTISTAS'!G54 -> 0 | L15: ='ANTROPOMETRÍA DEPORTISTAS'!H54 -> 0 | M15: ='ANTROPOMETRÍA DEPORTISTAS'!I54 -> 0 | ... O15: ='ANTROPOMETRÍA DEPORTISTAS'!K54 -> 0
D16: Somatotipo | F16: =IF(AND('ANTROPOMETRÍA DEPORTISTAS'!B68>'ANTROPOMETRÍA DEPORTISTAS'!B67, 'ANTROPOMETRÍA DEPORTISTAS'!B68>'ANTROPOMETRÍA DEPORTISTAS'!B66), "Endomorfo", IF(AND('ANTROPOMETRÍA DEPORTISTAS'!B67>'ANTROPOMETRÍA DEPORTISTAS'!B68, 'ANTROPOMETRÍA DEPORTISTAS'!B67>'ANTROPOMETRÍA DEPORTISTAS'!B66), "Mesomorfo", IF(AND('ANTROPOMETRÍA DEPORTISTAS'!B66>'ANTROPOMETRÍA DEPORTISTAS'!B68, 'ANTROPOMETRÍA DEPORTISTAS'!B66>'ANTROPOMETRÍA DEPORTISTAS'!B67), "Ectomorfo", "Somatotipo Balanceado"))) -> Mesomorfo
D18: Evaluación | F18: 1 | G18: 2 | H18: 3 | I18: 4 | J18: 5 | K18: 6 | L18: 7 | M18: 8 | N18: 9 | O18: 10 | P18: 11
D19: Fecha | F19: ='5 COMPONENTES'!C2 -> 0 | G19: ='5 COMPONENTES'!D2 -> 0 | H19: ='5 COMPONENTES'!E2 -> 0 | I19: ='5 COMPONENTES'!F2 -> 0 | J19: ='5 COMPONENTES'!G2 -> 0 | K19: ='5 COMPONENTES'!H2 -> 0 | L19: ='5 COMPONENTES'!I2 -> 0 | M19: ='5 COMPONENTES'!J2 -> 0 | ... P19: ='5 COMPONENTES'!M2 -> 0
D20: Peso (Kg) | F20: ='5 COMPONENTES'!C5 -> 0 | G20: ='5 COMPONENTES'!D5 -> 0 | H20: ='5 COMPONENTES'!E5 -> 0 | I20: ='5 COMPONENTES'!F5 -> 0 | J20: ='5 COMPONENTES'!G5 -> 0 | K20: ='5 COMPONENTES'!H5 -> 0 | L20: ='5 COMPONENTES'!I5 -> 0 | M20: ='5 COMPONENTES'!J5 -> 0 | ... P20: ='5 COMPONENTES'!M5 -> 0
D21: Talla parada (cm) | F21: ='5 COMPONENTES'!C6 -> 185 | G21: ='5 COMPONENTES'!D6 -> 185 | H21: ='5 COMPONENTES'!E6 -> 185 | I21: ='5 COMPONENTES'!F6 -> 185 | J21: ='5 COMPONENTES'!G6 -> 185 | K21: ='5 COMPONENTES'!H6 -> 185 | L21: ='5 COMPONENTES'!I6 -> 185 | M21: ='5 COMPONENTES'!J6 -> 185 | ... P21: ='5 COMPONENTES'!M6 -> 0
D22: % Grasa (Carter 1986) | F22: ='5 COMPONENTES'!C80 -> 2.585 | G22: ='5 COMPONENTES'!D80 -> 2.585 | H22: ='5 COMPONENTES'!E80 -> 2.585 | I22: ='5 COMPONENTES'!F80 -> 2.585 | J22: ='5 COMPONENTES'!G80 -> 2.585 | K22: ='5 COMPONENTES'!H80 -> 2.585 | L22: ='5 COMPONENTES'!I80 -> 2.585 | M22: ='5 COMPONENTES'!J80 -> 2.585 | ... P22: ='5 COMPONENTES'!M80 -> 0
D23: Kg de Masa Magra | F23: ='5 COMPONENTES'!C82 -> 0 | G23: ='5 COMPONENTES'!D82 -> 0 | H23: ='5 COMPONENTES'!E82 -> 0 | I23: ='5 COMPONENTES'!F82 -> 0 | J23: ='5 COMPONENTES'!G82 -> 0 | K23: ='5 COMPONENTES'!H82 -> 0 | L23: ='5 COMPONENTES'!I82 -> 0 | M23: ='5 COMPONENTES'!J82 -> 0 | ... P23: ='5 COMPONENTES'!M82 -> 0
D24: Kg de Grasa | F24: ='5 COMPONENTES'!C83 -> 0 | G24: ='5 COMPONENTES'!D83 -> 0 | H24: ='5 COMPONENTES'!E83 -> 0 | I24: ='5 COMPONENTES'!F83 -> 0 | J24: ='5 COMPONENTES'!G83 -> 0 | K24: ='5 COMPONENTES'!H83 -> 0 | L24: ='5 COMPONENTES'!I83 -> 0 | M24: ='5 COMPONENTES'!J83 -> 0 | ... P24: ='5 COMPONENTES'!M83 -> 0
D25: Masa muscular total (Kg) | F25: ='5 COMPONENTES'!C66 -> 0 | G25: ='5 COMPONENTES'!D66 -> 0 | H25: ='5 COMPONENTES'!E66 -> 0 | I25: ='5 COMPONENTES'!F66 -> 0 | J25: ='5 COMPONENTES'!G66 -> 0 | K25: ='5 COMPONENTES'!H66 -> 0 | L25: ='5 COMPONENTES'!I66 -> 0 | M25: ='5 COMPONENTES'!J66 -> 0 | ... P25: ='5 COMPONENTES'!M66 -> 0
D26: Masa ósea total (Kg) | F26: ='5 COMPONENTES'!C64 -> 0 | G26: ='5 COMPONENTES'!D64 -> 0 | H26: ='5 COMPONENTES'!E64 -> 0 | I26: ='5 COMPONENTES'!F64 -> 0 | J26: ='5 COMPONENTES'!G64 -> 0 | K26: ='5 COMPONENTES'!H64 -> 0 | L26: ='5 COMPONENTES'!I64 -> 0 | M26: ='5 COMPONENTES'!J64 -> 0 | ... P26: ='5 COMPONENTES'!M64 -> 0
D27: Masa residual (Kg) | F27: ='5 COMPONENTES'!C67 -> 0 | G27: ='5 COMPONENTES'!D67 -> 0 | H27: ='5 COMPONENTES'!E67 -> 0 | I27: ='5 COMPONENTES'!F67 -> 0 | J27: ='5 COMPONENTES'!G67 -> 0 | K27: ='5 COMPONENTES'!H67 -> 0 | L27: ='5 COMPONENTES'!I67 -> 0 | M27: ='5 COMPONENTES'!J67 -> 0 | ... P27: ='5 COMPONENTES'!M67 -> 0
D28: ='5 COMPONENTES'!B63 -> Masa de la piel (Kg) | F28: ='5 COMPONENTES'!C63 -> 0 | G28: ='5 COMPONENTES'!D63 -> 0 | H28: ='5 COMPONENTES'!E63 -> 0 | I28: ='5 COMPONENTES'!F63 -> 0 | J28: ='5 COMPONENTES'!G63 -> 0 | K28: ='5 COMPONENTES'!H63 -> 0 | L28: ='5 COMPONENTES'!I63 -> 0 | M28: ='5 COMPONENTES'!J63 -> 0 | ... P28: ='5 COMPONENTES'!M63 -> 0
D29: Masa Adiposa (Kg) | F29: ='5 COMPONENTES'!C65 -> 0 | G29: ='5 COMPONENTES'!D65 -> 0 | H29: ='5 COMPONENTES'!E65 -> 0 | I29: ='5 COMPONENTES'!F65 -> 0 | J29: ='5 COMPONENTES'!G65 -> 0 | K29: ='5 COMPONENTES'!H65 -> 0 | L29: ='5 COMPONENTES'!I65 -> 0 | M29: ='5 COMPONENTES'!J65 -> 0 | ... P29: ='5 COMPONENTES'!M65 -> 0
D30: Sumatoria de 6 pliegues | F30: ='5 COMPONENTES'!C70 -> 0 | G30: ='5 COMPONENTES'!D70 -> 0 | H30: ='5 COMPONENTES'!E70 -> 0 | I30: ='5 COMPONENTES'!F70 -> 0 | J30: ='5 COMPONENTES'!G70 -> 0 | K30: ='5 COMPONENTES'!H70 -> 0 | L30: ='5 COMPONENTES'!I70 -> 0 | M30: ='5 COMPONENTES'!J70 -> 0 | ... P30: ='5 COMPONENTES'!M70 -> 0
D31: Somatotipo | F31: Mesomorfo | G31: Mesomorfo | H31: Mesomorfo | I31: Mesomorfo | J31: Mesomorfo | K31: Mesomorfo | L31: Mesomorfo | M31: Mesomorfo | N31: Mesomorfo | O31: Mesomorfo | P31: Mesomorfo
D32: Cociente muscular/óseo | F32: ='5 COMPONENTES'!C71 -> 2.4024574 | G32: ='5 COMPONENTES'!D71 -> 2.4024574 | H32: ='5 COMPONENTES'!E71 -> 2.4024574 | I32: ='5 COMPONENTES'!F71 -> 2.4024574 | J32: ='5 COMPONENTES'!G71 -> 2.4024574 | K32: ='5 COMPONENTES'!H71 -> 2.4024574 | L32: ='5 COMPONENTES'!I71 -> 2.4024574 | M32: ='5 COMPONENTES'!J71 -> 2.4024574 | ... P32: ='5 COMPONENTES'!M71 -> 0
D34: DATOS DEL INFORME
E36: ='ANTROPOMETRÍA DEPORTISTAS'!A6 -> Fecha de evaluación | F36: ='ANTROPOMETRÍA DEPORTISTAS'!B6 -> 45994 | G36: ='ANTROPOMETRÍA DEPORTISTAS'!C6 -> 0 | H36: ='ANTROPOMETRÍA DEPORTISTAS'!D6 -> 0 | I36: ='ANTROPOMETRÍA DEPORTISTAS'!E6 -> 0 | J36: ='ANTROPOMETRÍA DEPORTISTAS'!F6 -> 0 | K36: ='ANTROPOMETRÍA DEPORTISTAS'!G6 -> 0
E37: ='ANTROPOMETRÍA DEPORTISTAS'!A7 -> Peso actual (kg) | F37: ='ANTROPOMETRÍA DEPORTISTAS'!B7 -> 90.05 | G37: ='ANTROPOMETRÍA DEPORTISTAS'!C7 -> 0 | H37: ='ANTROPOMETRÍA DEPORTISTAS'!D7 -> 0 | I37: ='ANTROPOMETRÍA DEPORTISTAS'!E7 -> 0 | J37: ='ANTROPOMETRÍA DEPORTISTAS'!F7 -> 0 | K37: ='ANTROPOMETRÍA DEPORTISTAS'!G7 -> 0
E38: ='ANTROPOMETRÍA DEPORTISTAS'!A8 -> Talla (m) | F38: ='ANTROPOMETRÍA DEPORTISTAS'!B8 -> 1.86 | G38: ='ANTROPOMETRÍA DEPORTISTAS'!C8 -> 0 | H38: ='ANTROPOMETRÍA DEPORTISTAS'!D8 -> 0 | I38: ='ANTROPOMETRÍA DEPORTISTAS'!E8 -> 0 | J38: ='ANTROPOMETRÍA DEPORTISTAS'!F8 -> 0 | K38: ='ANTROPOMETRÍA DEPORTISTAS'!G8 -> 0
E39: ='ANTROPOMETRÍA DEPORTISTAS'!A9 -> Talla (cm) | F39: ='ANTROPOMETRÍA DEPORTISTAS'!B9 -> 186 | G39: ='ANTROPOMETRÍA DEPORTISTAS'!C9 -> 0 | H39: ='ANTROPOMETRÍA DEPORTISTAS'!D9 -> 0 | I39: ='ANTROPOMETRÍA DEPORTISTAS'!E9 -> 0 | J39: ='ANTROPOMETRÍA DEPORTISTAS'!F9 -> 0 | K39: ='ANTROPOMETRÍA DEPORTISTAS'!G9 -> 0
E40: ='ANTROPOMETRÍA DEPORTISTAS'!A11 -> Circunferencias(cm)
E41: ='ANTROPOMETRÍA DEPORTISTAS'!A12 -> Brazo relajado (cm) | F41: ='ANTROPOMETRÍA DEPORTISTAS'!B12 -> 39.1 | G41: ='ANTROPOMETRÍA DEPORTISTAS'!C12 -> 0 | H41: ='ANTROPOMETRÍA DEPORTISTAS'!D12 -> 0 | I41: ='ANTROPOMETRÍA DEPORTISTAS'!E12 -> 0 | J41: ='ANTROPOMETRÍA DEPORTISTAS'!F12 -> 0 | K41: ='ANTROPOMETRÍA DEPORTISTAS'!G12 -> 0
E42: ='ANTROPOMETRÍA DEPORTISTAS'!A13 -> Brazo Flexionado en Tensión (cm) | F42: ='ANTROPOMETRÍA DEPORTISTAS'!B13 -> 41.5 | G42: ='ANTROPOMETRÍA DEPORTISTAS'!C13 -> 0 | H42: ='ANTROPOMETRÍA DEPORTISTAS'!D13 -> 0 | I42: ='ANTROPOMETRÍA DEPORTISTAS'!E13 -> 0 | J42: ='ANTROPOMETRÍA DEPORTISTAS'!F13 -> 0 | K42: ='ANTROPOMETRÍA DEPORTISTAS'!G13 -> 0
E43: ='ANTROPOMETRÍA DEPORTISTAS'!A14 -> Antebrazo máximo (cm) | F43: ='ANTROPOMETRÍA DEPORTISTAS'!B14 -> 31 | G43: ='ANTROPOMETRÍA DEPORTISTAS'!C14 -> 0 | H43: ='ANTROPOMETRÍA DEPORTISTAS'!D14 -> 0 | I43: ='ANTROPOMETRÍA DEPORTISTAS'!E14 -> 0 | J43: ='ANTROPOMETRÍA DEPORTISTAS'!F14 -> 0 | K43: ='ANTROPOMETRÍA DEPORTISTAS'!G14 -> 0
E44: ='ANTROPOMETRÍA DEPORTISTAS'!A15 -> Tórax (Mesoesternal) (cm) | F44: ='ANTROPOMETRÍA DEPORTISTAS'!B15 -> 108 | G44: ='ANTROPOMETRÍA DEPORTISTAS'!C15 -> 0 | H44: ='ANTROPOMETRÍA DEPORTISTAS'!D15 -> 0 | I44: ='ANTROPOMETRÍA DEPORTISTAS'!E15 -> 0 | J44: ='ANTROPOMETRÍA DEPORTISTAS'!F15 -> 0 | K44: ='ANTROPOMETRÍA DEPORTISTAS'!G15 -> 0
E45: ='ANTROPOMETRÍA DEPORTISTAS'!A16 -> Cintura mínimo (cm) | F45: ='ANTROPOMETRÍA DEPORTISTAS'!B16 -> 85 | G45: ='ANTROPOMETRÍA DEPORTISTAS'!C16 -> 0 | H45: ='ANTROPOMETRÍA DEPORTISTAS'!D16 -> 0 | I45: ='ANTROPOMETRÍA DEPORTISTAS'!E16 -> 0 | J45: ='ANTROPOMETRÍA DEPORTISTAS'!F16 -> 0 | K45: ='ANTROPOMETRÍA DEPORTISTAS'!G16 -> 0
...

Sheet Hoja1

Sheet DATOS ANTROPOMÉTRICOS
A14: DATOS ANTROPOMETRICOS
B16: FECHA DE EVALUACION
A17: BASICOS
A18: Peso (kg)
A19: Talla (cm)
A20: PLIEGUES CUTANEOS (mm)
A21: Tríceps
A22: Subescapular
A23: Bíceps
A24: Cresta Iliaca
A25: Supraespinal
A26: Abdominal
A27: Muslo Frontal
A28: Pantorrilla Medial
... A38: ESTIMACIÓN DE VARIABLES ANTROPOMETRICAS
A39: % Grasa Durning & W. (adultos 17 años y mas) | B39: =IF(HISTORIA!C10="masculino",(495/(1.1765-(0.0744*LOG10(B21+B22+B23+B24)))-450),(495/(1.1567-(0.0717*LOG10(B21+B22+B23+B24)))-450)) -> #NUM! | C39: =IF(HISTORIA!C10="masculino",(495/(1.1765-(0.0744*LOG10(C21+C22+C23+C24)))-450),(495/(1.1567-(0.0717*LOG10(C21+C22+C23+C24)))-450)) -> #NUM! | D39: =IF(HISTORIA!C10="masculino",(495/(1.1765-(0.0744*LOG10(D21+D22+D23+D24)))-450),(495/(1.1567-(0.0717*LOG10(D21+D22+D23+D24)))-450)) -> #NUM! | E39: =IF(HISTORIA!C10="masculino",(495/(1.1765-(0.0744*LOG10(E21+E22+E23+E24)))-450),(495/(1.1567-(0.0717*LOG10(E21+E22+E23+E24)))-450)) -> #NUM! | F39: =IF(HISTORIA!C10="masculino",(495/(1.1765-(0.0744*LOG10(F21+F22+F23+F24)))-450),(495/(1.1567-(0.0717*LOG10(F21+F22+F23+F24)))-450)) -> #NUM! | G39: =IF(HISTORIA!C10="masculino",(495/(1.1765-(0.0744*LOG10(G21+G22+G23+G24)))-450),(495/(1.1567-(0.0717*LOG10(G21+G22+G23+G24)))-450)) -> #NUM! | H39: =IF(HISTORIA!C10="masculino",(495/(1.1765-(0.0744*LOG10(H21+H22+H23+H24)))-450),(495/(1.1567-(0.0717*LOG10(H21+H22+H23+H24)))-450)) -> #NUM! | I39: =IF(HISTORIA!C10="masculino",(495/(1.1765-(0.0744*LOG10(I21+I22+I23+I24)))-450),(495/(1.1567-(0.0717*LOG10(I21+I22+I23+I24)))-450)) -> #NUM! | J39: =IF(HISTORIA!C10="masculino",(495/(1.1765-(0.0744*LOG10(J21+J22+J23+J24)))-450),(495/(1.1567-(0.0717*LOG10(J21+J22+J23+J24)))-450)) -> #NUM! | K39: =IF(HISTORIA!C10="masculino",(495/(1.1765-(0.0744*LOG10(K21+K22+K23+K24)))-450),(495/(1.1567-(0.0717*LOG10(K21+K22+K23+K24)))-450)) -> #NUM! | L39: =IF(HISTORIA!C10="masculino",(495/(1.1765-(0.0744*LOG10(L21+L22+L23+L24)))-450),(495/(1.1567-(0.0717*LOG10(L21+L22+L23+L24)))-450)) -> #NUM! | M39: =IF(HISTORIA!C10="masculino",(495/(1.1765-(0.0744*LOG10(M21+M22+M23+M24)))-450),(495/(1.1567-(0.0717*LOG10(M21+M22+M23+M24)))-450)) -> #NUM!
A40: % Grasa Carter-Yuhasz (Atletas) | B40: =IF(HISTORIA!C10="masculino",(0.1051*(B21+B22+B25+B26+B27+B28)+2.585),(0.1548*(B21+B22+B25+B26+B27+B28)+3.58)) -> 2.585 | C40: =IF(HISTORIA!C10="masculino",(0.1051*(C21+C22+C25+C26+C27+C28)+2.585),(0.1548*(C21+C22+C25+C26+C27+C28)+3.58)) -> 2.585 | D40: =IF(HISTORIA!C10="masculino",(0.1051*(D21+D22+D25+D26+D27+D28)+2.585),(0.1548*(D21+D22+D25+D26+D27+D28)+3.58)) -> 2.585 | E40: =IF(HISTORIA!C10="masculino",(0.1051*(E21+E22+E25+E26+E27+E28)+2.585),(0.1548*(E21+E22+E25+E26+E27+E28)+3.58)) -> 2.585 | F40: =IF(HISTORIA!C10="masculino",(0.1051*(F21+F22+F25+F26+F27+F28)+2.585),(0.1548*(F21+F22+F25+F26+F27+F28)+3.58)) -> 2.585 | G40: =IF(HISTORIA!C10="masculino",(0.1051*(G21+G22+G25+G26+G27+G28)+2.585),(0.1548*(G21+G22+G25+G26+G27+G28)+3.58)) -> 2.585 | H40: =IF(HISTORIA!C10="masculino",(0.1051*(H21+H22+H25+H26+H27+H28)+2.585),(0.1548*(H21+H22+H25+H26+H27+H28)+3.58)) -> 2.585 | I40: =IF(HISTORIA!C10="masculino",(0.1051*(I21+I22+I25+I26+I27+I28)+2.585),(0.1548*(I21+I22+I25+I26+I27+I28)+3.58)) -> 2.585 | J40: =IF(HISTORIA!C10="masculino",(0.1051*(J21+J22+J25+J26+J27+J28)+2.585),(0.1548*(J21+J22+J25+J26+J27+J28)+3.58)) -> 2.585 | K40: =IF(HISTORIA!C10="masculino",(0.1051*(K21+K22+K25+K26+K27+K28)+2.585),(0.1548*(K21+K22+K25+K26+K27+K28)+3.58)) -> 2.585 | L40: =IF(HISTORIA!C10="masculino",(0.1051*(L21+L22+L25+L26+L27+L28)+2.585),(0.1548*(L21+L22+L25+L26+L27+L28)+3.58)) -> 2.585 | M40: =IF(HISTORIA!C10="masculino",(0.1051*(M21+M22+M25+M26+M27+M28)+2.585),(0.1548*(M21+M22+M25+M26+M27+M28)+3.58)) -> 2.585
A41: % Grasa Durnin ADULTOS | B41: =(((0.2467)*(B21+B22++B23+B24))+((0.12*B32)))+4.98 -> 4.98 | C41: =(((0.2467)*(C21+C22++C23+C24))+((0.12*C32)))+4.98 -> 4.98 | D41: =(((0.2467)*(D21+D22++D23+D24))+((0.12*D32)))+4.98 -> 4.98 | E41: =(((0.2467)*(E21+E22++E23+E24))+((0.12*E32)))+4.98 -> 4.98 | F41: =(((0.2467)*(F21+F22++F23+F24))+((0.12*F32)))+4.98 -> 4.98 | G41: =(((0.2467)*(G21+G22++G23+G24))+((0.12*G32)))+4.98 -> 4.98 | H41: =(((0.2467)*(H21+H22++H23+H24))+((0.12*H32)))+4.98 -> 4.98 | I41: =(((0.2467)*(I21+I22++I23+I24))+((0.12*I32)))+4.98 -> 4.98 | ... M41: =(((0.2467)*(M21+M22++M23+M24))+((0.12*M32)))+4.98 -> 4.98
A42: % Grasa Brook (1-11 años) | B42: =IF(HISTORIA!C10="masculino",(530/(1.169-(0.078*LOG10(B21+B22+B23+B25)))-489),(530/(1.2063-(0.0999*LOG10(B21+B22+B23+B25)))-489)) -> #NUM! | C42: =IF(HISTORIA!C10="masculino",(530/(1.169-(0.078*LOG10(C21+C22+C23+C25)))-489),(530/(1.2063-(0.0999*LOG10(C21+C22+C23+C25)))-489)) -> #NUM! | D42: =IF(HISTORIA!C10="masculino",(530/(1.169-(0.078*LOG10(D21+D22+D23+D25)))-489),(530/(1.2063-(0.0999*LOG10(D21+D22+D23+D25)))-489)) -> #NUM! | E42: =IF(HISTORIA!C10="masculino",(530/(1.169-(0.078*LOG10(E21+E22+E23+E25)))-489),(530/(1.2063-(0.0999*LOG10(E21+E22+E23+E25)))-489)) -> #NUM! | F42: =IF(HISTORIA!C10="masculino",(530/(1.169-(0.078*LOG10(F21+F22+F23+F25)))-489),(530/(1.2063-(0.0999*LOG10(F21+F22+F23+F25)))-489)) -> #NUM! | G42: =IF(HISTORIA!C10="masculino",(530/(1.169-(0.078*LOG10(G21+G22+G23+G25)))-489),(530/(1.2063-(0.0999*LOG10(G21+G22+G23+G25)))-489)) -> #NUM! | H42: =IF(HISTORIA!C10="masculino",(530/(1.169-(0.078*LOG10(H21+H22+H23+H25)))-489),(530/(1.2063-(0.0999*LOG10(H21+H22+H23+H25)))-489)) -> #NUM! | I42: =IF(HISTORIA!C10="masculino",(530/(1.169-(0.078*LOG10(I21+I22+I23+I25)))-489),(530/(1.2063-(0.0999*LOG10(I21+I22+I23+I25)))-489)) -> #NUM! | J42: =IF(HISTORIA!C10="masculino",(530/(1.169-(0.078*LOG10(J21+J22+J23+J25)))-489),(530/(1.2063-(0.0999*LOG10(J21+J22+J23+J25)))-489)) -> #NUM! | K42: =IF(HISTORIA!C10="masculino",(530/(1.169-(0.078*LOG10(K21+K22+K23+K25)))-489),(530/(1.2063-(0.0999*LOG10(K21+K22+K23+K25)))-489)) -> #NUM! | L42: =IF(HISTORIA!C10="masculino",(530/(1.169-(0.078*LOG10(L21+L22+L23+L25)))-489),(530/(1.2063-(0.0999*LOG10(L21+L22+L23+L25)))-489)) -> #NUM! | M42: =IF(HISTORIA!C10="masculino",(530/(1.169-(0.078*LOG10(M21+M22+M23+M25)))-489),(530/(1.2063-(0.0999*LOG10(M21+M22+M23+M25)))-489)) -> #NUM!
A43: % Grasa Durnin (12-16 años) | B43: =IF(HISTORIA!C10="masculino",(530/(1.1533-(0.0643*LOG10(B21+B22+B23+B25)))-489),(530/(1.1369-(0.0598*LOG10(B21+B22+B23+B25)))-489)) -> #NUM! | C43: =IF(HISTORIA!C10="masculino",(530/(1.1533-(0.0643*LOG10(C21+C22+C23+C25)))-489),(530/(1.1369-(0.0598*LOG10(C21+C22+C23+C25)))-489)) -> #NUM! | D43: =IF(HISTORIA!C10="masculino",(530/(1.1533-(0.0643*LOG10(D21+D22+D23+D25)))-489),(530/(1.1369-(0.0598*LOG10(D21+D22+D23+D25)))-489)) -> #NUM! | E43: =IF(HISTORIA!C10="masculino",(530/(1.1533-(0.0643*LOG10(E21+E22+E23+E25)))-489),(530/(1.1369-(0.0598*LOG10(E21+E22+E23+E25)))-489)) -> #NUM! | F43: =IF(HISTORIA!C10="masculino",(530/(1.1533-(0.0643*LOG10(F21+F22+F23+F25)))-489),(530/(1.1369-(0.0598*LOG10(F21+F22+F23+F25)))-489)) -> #NUM! | G43: =IF(HISTORIA!C10="masculino",(530/(1.1533-(0.0643*LOG10(G21+G22+G23+G25)))-489),(530/(1.1369-(0.0598*LOG10(G21+G22+G23+G25)))-489)) -> #NUM! | H43: =IF(HISTORIA!C10="masculino",(530/(1.1533-(0.0643*LOG10(H21+H22+H23+H25)))-489),(530/(1.1369-(0.0598*LOG10(H21+H22+H23+H25)))-489)) -> #NUM! | I43: =IF(HISTORIA!C10="masculino",(530/(1.1533-(0.0643*LOG10(I21+I22+I23+I25)))-489),(530/(1.1369-(0.0598*LOG10(I21+I22+I23+I25)))-489)) -> #NUM! | J43: =IF(HISTORIA!C10="masculino",(530/(1.1533-(0.0643*LOG10(J21+J22+J23+J25)))-489),(530/(1.1369-(0.0598*LOG10(J21+J22+J23+J25)))-489)) -> #NUM! | K43: =IF(HISTORIA!C10="masculino",(530/(1.1533-(0.0643*LOG10(K21+K22+K23+K25)))-489),(530/(1.1369-(0.0598*LOG10(K21+K22+K23+K25)))-489)) -> #NUM! | L43: =IF(HISTORIA!C10="masculino",(530/(1.1533-(0.0643*LOG10(L21+L22+L23+L25)))-489),(530/(1.1369-(0.0598*LOG10(L21+L22+L23+L25)))-489)) -> #NUM! | M43: =IF(HISTORIA!C10="masculino",(530/(1.1533-(0.0643*LOG10(M21+M22+M23+M25)))-489),(530/(1.1369-(0.0598*LOG10(M21+M22+M23+M25)))-489)) -> #NUM!
A44: % Grasa Seleccionado | B44: 22.4 | C44: 31.8
A45: % Grasa Minimo Permitido | B45: 15 | C45: 15
A46: % Grasa Maximo Permitido | B46: 20 | C46: 20
A47: Peso de la Grasa (pg) | B47: =(B18*(B44/100)) -> 0 | C47: =(C18*(C44/100)) -> 0 | D47: =(D18*(D44/100)) -> 0 | E47: =(E18*(E44/100)) -> 0 | F47: =(F18*(F44/100)) -> 0 | G47: =(G18*(G44/100)) -> 0 | H47: =(H18*(H44/100)) -> 0 | I47: =(I18*(I44/100)) -> 0 | ... M47: =(M18*(M44/100)) -> 0
A48: Peso Magro (pm) | B48: =B18-B47 -> 0 | C48: =C18-C47 -> 0 | D48: =D18-D47 -> 0 | E48: =E18-E47 -> 0 | F48: =F18-F47 -> 0 | G48: =G18-G47 -> 0 | H48: =H18-H47 -> 0 | I48: =I18-I47 -> 0 | ... M48: =M18-M47 -> 0
A49: % Peso Magro (%pm) | B49: =(B48*100)/B18 -> #DIV/0! | C49: =(C48*100)/C18 -> #DIV/0! | D49: =(D48*100)/D18 -> #DIV/0! | E49: =(E48*100)/E18 -> #DIV/0! | F49: =(F48*100)/F18 -> #DIV/0! | G49: =(G48*100)/G18 -> #DIV/0! | H49: =(H48*100)/H18 -> #DIV/0! | I49: =(I48*100)/I18 -> #DIV/0! | ... M49: =(M48*100)/M18 -> #DIV/0!
A50: Indice de Masa Corporal (IMC) | B50: =B18/(POWER(B19/100,2)) -> #DIV/0! | C50: =C18/(POWER(C19/100,2)) -> #DIV/0! | D50: =D18/(POWER(D19/100,2)) -> #DIV/0! | E50: =E18/(POWER(E19/100,2)) -> #DIV/0! | F50: =F18/(POWER(F19/100,2)) -> #DIV/0! | G50: =G18/(POWER(G19/100,2)) -> #DIV/0! | H50: =H18/(POWER(H19/100,2)) -> #DIV/0! | I50: =I18/(POWER(I19/100,2)) -> #DIV/0! | ... M50: =M18/(POWER(M19/100,2)) -> #DIV/0!
A51: Relacion Cintura/Cadera (ICC) | B51: =B32/B33 -> #DIV/0! | C51: =C32/C33 -> #DIV/0! | D51: =D32/D33 -> #DIV/0! | E51: =E32/E33 -> #DIV/0! | F51: =F32/F33 -> #DIV/0! | G51: =G32/G33 -> #DIV/0! | H51: =H32/H33 -> #DIV/0! | I51: =I32/I33 -> #DIV/0! | ... M51: =M32/M33 -> #DIV/0!
A52: Adiposidad Relativa (AR) | B52: =(B21+B22+B24+B26+B27+B28)*(170.18/B19) -> #DIV/0! | C52: =(C21+C22+C24+C26+C27+C28)*(170.18/C19) -> #DIV/0! | D52: =(D21+D22+D24+D26+D27+D28)*(170.18/D19) -> #DIV/0! | E52: =(E21+E22+E24+E26+E27+E28)*(170.18/E19) -> #DIV/0! | F52: =(F21+F22+F24+F26+F27+F28)*(170.18/F19) -> #DIV/0! | G52: =(G21+G22+G24+G26+G27+G28)*(170.18/G19) -> #DIV/0! | H52: =(H21+H22+H24+H26+H27+H28)*(170.18/H19) -> #DIV/0! | I52: =(I21+I22+I24+I26+I27+I28)*(170.18/I19) -> #DIV/0! | ... M52: =(M21+M22+M24+M26+M27+M28)*(170.18/M19) -> #DIV/0!
A53: Peso Proporcional (PP) | B53: =B18*(POWER(170.18/B19,3)) -> #DIV/0! | C53: =C18*(POWER(170.18/C19,3)) -> #DIV/0! | D53: =D18*(POWER(170.18/D19,3)) -> #DIV/0! | E53: =E18*(POWER(170.18/E19,3)) -> #DIV/0! | F53: =F18*(POWER(170.18/F19,3)) -> #DIV/0! | G53: =G18*(POWER(170.18/G19,3)) -> #DIV/0! | H53: =H18*(POWER(170.18/H19,3)) -> #DIV/0! | I53: =I18*(POWER(170.18/I19,3)) -> #DIV/0! | ... M53: =M18*(POWER(170.18/M19,3)) -> #DIV/0!
A54: Sumatoria de 4 Pliegues | B54: =B21+B22+B23+B24 -> 0 | C54: =C21+C22+C23+C24 -> 0 | D54: =D21+D22+D23+D24 -> 0 | E54: =E21+E22+E23+E24 -> 0 | F54: =F21+F22+F23+F24 -> 0 | G54: =G21+G22+G23+G24 -> 0 | H54: =H21+H22+H23+H24 -> 0 | I54: =I21+I22+I23+I24 -> 0 | ... M54: =M21+M22+M23+M24 -> 0
A55: Sumatoria de 6 Pliegues | B55: =B21+B22+B25+B26+B27+B28 -> 0 | C55: =C21+C22+C25+C26+C27+C28 -> 0 | D55: =D21+D22+D25+D26+D27+D28 -> 0 | E55: =E21+E22+E25+E26+E27+E28 -> 0 | F55: =F21+F22+F25+F26+F27+F28 -> 0 | G55: =G21+G22+G25+G26+G27+G28 -> 0 | H55: =H21+H22+H25+H26+H27+H28 -> 0 | I55: =I21+I22+I25+I26+I27+I28 -> 0 | ... M55: =M21+M22+M25+M26+M27+M28 -> 0
A56: Sumatoria de 8 Pliegues | B56: =SUM(B21:B28) -> 0 | C56: =SUM(C21:C28) -> 0 | D56: =SUM(D21:D28) -> 0 | E56: =SUM(E21:E28) -> 0 | F56: =SUM(F21:F28) -> 0 | G56: =SUM(G21:G28) -> 0 | H56: =SUM(H21:H28) -> 0 | I56: =SUM(I21:I28) -> 0 | ... M56: =SUM(M21:M28) -> 0
A57: PESO
A58: Peso Minimo Permitido | B58: =(B48*100)/(100-B45) -> 0 | C58: =(C48*100)/(100-C45) -> 0 | D58: =(D48*100)/(100-D45) -> 0 | E58: =(E48*100)/(100-E45) -> 0 | F58: =(F48*100)/(100-F45) -> 0 | G58: =(G48*100)/(100-G45) -> 0 | H58: =(H48*100)/(100-H45) -> 0 | I58: =(I48*100)/(100-I45) -> 0 | ... M58: =(M48*100)/(100-M45) -> 0
A59: Peso Maximo Permitido | B59: =(B48*100)/(100-B46) -> 0 | C59: =(C48*100)/(100-C46) -> 0 | D59: =(D48*100)/(100-D46) -> 0 | E59: =(E48*100)/(100-E46) -> 0 | F59: =(F48*100)/(100-F46) -> 0 | G59: =(G48*100)/(100-G46) -> 0 | H59: =(H48*100)/(100-H46) -> 0 | I59: =(I48*100)/(100-I46) -> 0 | ... M59: =(M48*100)/(100-M46) -> 0
A60: Peso Objetivo | B60: 84 | C60: 84
A61: Kg a Subir o Bajar | B61: =B18-B60 -> -84 | C61: =C18-C60 -> -84 | D61: =D18-D60 -> 0 | E61: =E18-E60 -> 0 | F61: =F18-F60 -> 0 | G61: =G18-G60 -> 0 | H61: =H18-H60 -> 0 | I61: =I18-I60 -> 0 | ... M61: =M18-M60 -> 0
A62: SOMATOTIPO
A63: Endomorfia | B63: =(0.1451*((B21+B22+B25)*(170.18/B19)))-(0.00068* POWER(((B21+B22+B25)*(170.18/B19)),2))+(0.00000014*POWER(((B21+B22+B25)*(170.18/B19)),3))-0.7182 -> #DIV/0! | C63: =(0.1451*((C21+C22+C25)*(170.18/C19)))-(0.00068* POWER(((C21+C22+C25)*(170.18/C19)),2))+(0.00000014*POWER(((C21+C22+C25)*(170.18/C19)),3))-0.7182 -> #DIV/0! | D63: =(0.1451*((D21+D22+D25)*(170.18/D19)))-(0.00068* POWER(((D21+D22+D25)*(170.18/D19)),2))+(0.00000014*POWER(((D21+D22+D25)*(170.18/D19)),3))-0.7182 -> #DIV/0! | E63: =(0.1451*((E21+E22+E25)*(170.18/E19)))-(0.00068* POWER(((E21+E22+E25)*(170.18/E19)),2))+(0.00000014*POWER(((E21+E22+E25)*(170.18/E19)),3))-0.7182 -> #DIV/0! | F63: =(0.1451*((F21+F22+F25)*(170.18/F19)))-(0.00068* POWER(((F21+F22+F25)*(170.18/F19)),2))+(0.00000014*POWER(((F21+F22+F25)*(170.18/F19)),3))-0.7182 -> #DIV/0! | G63: =(0.1451*((G21+G22+G25)*(170.18/G19)))-(0.00068* POWER(((G21+G22+G25)*(170.18/G19)),2))+(0.00000014*POWER(((G21+G22+G25)*(170.18/G19)),3))-0.7182 -> #DIV/0! | H63: =(0.1451*((H21+H22+H25)*(170.18/H19)))-(0.00068* POWER(((H21+H22+H25)*(170.18/H19)),2))+(0.00000014*POWER(((H21+H22+H25)*(170.18/H19)),3))-0.7182 -> #DIV/0! | I63: =(0.1451*((I21+I22+I25)*(170.18/I19)))-(0.00068* POWER(((I21+I22+I25)*(170.18/I19)),2))+(0.00000014*POWER(((I21+I22+I25)*(170.18/I19)),3))-0.7182 -> #DIV/0! | ... M63: =(0.1451*((M21+M22+M25)*(170.18/M19)))-(0.00068* POWER(((M21+M22+M25)*(170.18/M19)),2))+(0.00000014*POWER(((M21+M22+M25)*(170.18/M19)),3))-0.7182 -> #DIV/0!
...

Sheet SOMATOCARTA
A14: ANÁLISIS ANTROPOMÉTRICO
B15: Fecha | C15: Endomorfia | D15: Mesomorfia | E15: Ectomorfia | F15: Coodenada X | G15: Coordanda Y
